Workbook
Name _1: #REF!
Name _1: #REF!
Name _1: #REF!
Name _10: #REF!
Name _10: #REF!
Name _10: #REF!
Name _11: #REF!
Name _11: #REF!
Name _11: #REF!
Name _12: #REF!
Name _12: #REF!
Name _12: #REF!
Name _13: #REF!
Name _13: #REF!
Name _13: #REF!
Name _14: #REF!
Name _14: #REF!
Name _14: #REF!
Name _15: #REF!
Name _15: #REF!
Name _15: #REF!
Name _16: #REF!
Name _16: #REF!
Name _16: #REF!
Name _17: #REF!
Name _17: #REF!
Name _17: #REF!
Name _18: #REF!
Name _18: #REF!
Name _18: #REF!
Name _19: #REF!
Name _19: #REF!
Name _19: #REF!
Name _1Excel_BuiltIn__FilterDatabase_10_9_1: NA()
Name _2: #REF!
Name _2: #REF!
Name _2: #REF!
Name _20: #REF!
Name _20: #REF!
Name _20: #REF!
Name _21: #REF!
Name _21: #REF!
Name _21: #REF!
Name _22: #REF!
Name _22: #REF!
Name _22: #REF!
Name _23: #REF!
Name _23: #REF!
Name _23: #REF!
Name _24: #REF!
Name _24: #REF!
Name _24: #REF!
Name _25: #REF!
Name _25: #REF!
Name _25: #REF!
Name _26: #REF!
Name _26: #REF!
Name _26: #REF!
Name _27: #REF!
Name _27: #REF!

Sheet COVER
B6: Tactical Media Plan | I6: CONFIDENCIAL
B8: CLIENT: | C8: SABESP
B9: CAMPAING | C9: ESCASSEZ HIDRICA - CRÍTICO
B10: TARGET: | C10: AS ABCDE 25+
B14: VERSION | C14: UPDATE DATE | D14: UPDATES:
B15: v1 | C15: 46038 | D15: AJUSTE NO VALOR DE RADIO E JORNAL + INCLUSÃO DE tv + INCLUSÃO DO ABCD JORNAL
B18: V5 | C18: 45677 | D18: Inclusão da veiculação de TV aberta e fechada
B19: V6 | C19: 45679 | D19: Ajuste conforme inserções de TV encaixadas
B20: V7 | C20: 46058 | D20: Atualização do plano conforme o veiculado de janeiro.
B21: V8 | C21: 46076 | D21: Atualização conforme realizado de fevereiro.

Sheet RESUMO DE MEIOS - SP1
B5: CLIENT: SABESP
B6: CAMPAING: ESCASSEZ HIDRICA - CRÍTICO
B8: RESUMO DE MEIOS - SÃO PAULO CAPITAL
B10: PRAÇA | C10: MEIO | D10: VEÍCULO | F10: JANEIRO | G10: FEVEREIRO | H10: TOTAL BRUTO | I10: VALOR DESEMBOLSO TT | J10: PART GERAL %
N12: UTILIZAÇÃO DE SALDO DE PACOTES
B13: SÃO PAULO CAPITAL | C13: TV ABERTA | D13: GLOBO | F13: ='TV ABERTA - SP1'!CC33*1.25 -> 1799646.8 | G13: ='TV ABERTA - SP1'!CE33*1.25 -> 543961 | H13: =SUM(F13:G13) -> 2343607.8 | I13: =H13*0.8 -> 1874886.2 | J13: =I13/$I$21 -> 0.58930842 | N13: SBT | O13: =I16 -> 409671.65
B14: SÃO PAULO CAPITAL | C14: TV ABERTA | D14: BANDEIRANTES | F14: ='TV ABERTA - SP1'!CC45*1.25 -> 66842.4 | G14: ='TV ABERTA - SP1'!CE45*1.25 -> 43587.6 | H14: =SUM(F14:G14) -> 110430 | I14: =H14*0.8 -> 88344 | J14: =I14/$I$21 -> 0.027768012 | N14: REDE TV | O14: =I17 -> 80635.56
B15: SÃO PAULO CAPITAL | C15: TV ABERTA | D15: RECORD | F15: ='TV ABERTA - SP1'!CC58*1.25 -> 471401.6 | G15: ='TV ABERTA - SP1'!CE58*1.25 -> 377926.6 | H15: =SUM(F15:G15) -> 849328.2 | I15: =H15*0.8 -> 679462.56 | J15: =I15/$I$21 -> 0.21356656 | N15: GLOBO | O15: =G13*0.8 -> 435168.8
B16: SÃO PAULO CAPITAL | C16: TV ABERTA | D16: SBT | F16: ='TV ABERTA - SP1'!CC83*1.25 -> 272575 | G16: ='TV ABERTA - SP1'!CE83*1.25 -> 239514.56 | H16: =SUM(F16:G16) -> 512089.56 | I16: =H16*0.8 -> 409671.65 | J16: =I16/$I$21 -> 0.12876672
B17: SÃO PAULO CAPITAL | C17: TV ABERTA | D17: REDE TV | F17: ='TV ABERTA - SP1'!CC90*1.25 -> 49699.95 | G17: ='TV ABERTA - SP1'!CE90*1.25 -> 51094.5 | H17: =SUM(F17:G17) -> 100794.45 | I17: =H17*0.8 -> 80635.56 | J17: =I17/$I$21 -> 0.025345119
B18: SÃO PAULO CAPITAL | C18: TV ABERTA | D18: CULTURA | F18: ='TV ABERTA - SP1'!CC100*1.25 -> 17112 | G18: ='TV ABERTA - SP1'!CE100*1.25 -> 15960 | H18: =SUM(F18:G18) -> 33072 | I18: =H18*0.8 -> 26457.6 | J18: =I18/$I$21 -> 0.0083160706
B19: SÃO PAULO CAPITAL | C19: TV ABERTA | D19: GAZETA | F19: ='TV ABERTA - SP1'!CC106*1.25 -> 16102.8 | G19: ='TV ABERTA - SP1'!CE106*1.25 -> 11453.4 | H19: =SUM(F19:G19) -> 27556.2 | I19: =H19*0.8 -> 22044.96 | J19: =I19/$I$21 -> 0.0069291033
B21: TT TV ABERTA | F21: =SUM(F13:F19) -> 2693380.5 | G21: =SUM(G13:G19) -> 1283497.7 | H21: =SUM(H13:H19) -> 3976878.2 | I21: =SUM(I13:I19) -> 3181502.6 | J21: =SUM(J13:J19) -> 1 | K21: =I21/I67 -> 0.57276866 | L21: =I21=SUM('TV ABERTA - SP1'!BU108) -> TRUE
B23: SÃO PAULO ESTADO | C23: TV PAGA | D23: GLOBONEWS | H23: =SUM(F23:G23) -> 0 | I23: =H23*0.8 -> 0 | J23: =IFERROR(I23/$I$28,0) -> 0
B24: SÃO PAULO ESTADO | C24: TV PAGA | D24: CNN BRASIL | H24: =SUM(F24:G24) -> 0 | I24: =H24*0.8 -> 0 | J24: =IFERROR(I24/$I$28,0) -> 0
B25: SÃO PAULO ESTADO | C25: TV PAGA | D25: RECORD NEWS | H25: =SUM(F25:G25) -> 0 | I25: =H25*0.8 -> 0 | J25: =IFERROR(I25/$I$28,0) -> 0
B26: SÃO PAULO ESTADO | C26: TV PAGA | D26: BAND NEWS | H26: =SUM(F26:G26) -> 0 | I26: =H26*0.8 -> 0 | J26: =IFERROR(I26/$I$28,0) -> 0
B28: TT TV PAGA | F28: =SUM(F23:F27) -> 0 | G28: =SUM(G23:G27) -> 0 | H28: =SUM(H23:H27) -> 0 | I28: =SUM(I23:I27) -> 0 | J28: =SUM(J23:J27) -> 0 | K28: =I28/I67 -> 0 | L28: =I28='TV PAGA - COLCHÃO REP - SP1'!BU28 -> FALSE
B30: SÃO PAULO CAPITAL | C30: JORNAL | D30: =JORNAL!C14 -> FOLHA DE SP | F30: =SUM(JORNAL!CN14:CN16)*1.25 -> 205409.91 | G30: {=SUM(JORNAL!CP14:CP16*1.25)} -> 0 | H30: =SUM(F30:G30) -> 205409.91 | I30: =H30*0.8 -> 164327.93 | J30: =I30/$I$36 -> 0.30990317
B31: SÃO PAULO CAPITAL | C31: JORNAL | D31: =JORNAL!C19 -> O ESTADO DE SP | F31: =SUM(JORNAL!CN19:CN21)*1.25 -> 232919.51 | G31: =SUM(JORNAL!CP19:CP21)*1.25 -> 0 | H31: =SUM(F31:G31) -> 232919.51 | I31: =H31*0.8 -> 186335.61 | J31: =I31/$I$36 -> 0.35140706
B32: SÃO PAULO CAPITAL | C32: JORNAL | D32: =JORNAL!C23 -> VALOR | F32: =SUM(JORNAL!CN23:CN25)*1.25 -> 138378.24 | G32: =SUM(JORNAL!CP23:CP25)*1.25 -> 0 | H32: =SUM(F32:G32) -> 138378.24 | I32: =H32*0.8 -> 110702.59 | J32: =I32/$I$36 -> 0.20877208
B33: SÃO PAULO CAPITAL | C33: JORNAL | D33: =JORNAL!C27 -> GAZETA DE SP | F33: =SUM(JORNAL!CN27:CN28)*1.25 -> 0 | G33: =SUM(JORNAL!CP27:CP29)*1.25 -> 0 | H33: =SUM(F33:G33) -> 0 | I33: =H33*0.8 -> 0 | J33: =I33/$I$36 -> 0
B34: =JORNAL!B31 -> ABC | C34: JORNAL | D34: =JORNAL!C31 -> DIÁRIO DO GRANDE ABC | F34: =SUM(JORNAL!CN31:CN34)*1.25 -> 86112 | G34: =SUM(JORNAL!CP31:CP34)*1.25 -> 0 | H34: =SUM(F34:G34) -> 86112 | I34: =H34*0.8 -> 68889.6 | J34: =I34/$I$36 -> 0.12991769
B36: TT JORNAL | F36: =SUM(F30:F34) -> 662819.66 | G36: =SUM(G30:G34) -> 0 | H36: =SUM(H30:H34) -> 662819.66 | I36: =SUM(I30:I34) -> 530255.73 | J36: =SUM(J30:J34) -> 1 | K36: =I36/I67 -> 0.095462398 | L36: =I36=JORNAL!CN39 -> TRUE
B38: SÃO PAULO CAPITAL | C38: RADIO | D38: JOVEM PAN FM | F38: =SUM(RÁDIO!CH14:CH15)*1.25 -> 94517.28 | G38: =SUM(RÁDIO!CJ14:CJ15)*1.25 -> 89266.32 | H38: =SUM(F38:G38) -> 183783.6 | I38: =H38*0.8 -> 147026.88 | J38: =I38/$I$58 -> 0.082231879
B39: SÃO PAULO CAPITAL | C39: RADIO | D39: BAND NEWS FM | F39: =SUM(RÁDIO!CH18:CH19)*1.25 -> 83832 | G39: =SUM(RÁDIO!CJ18:CJ19)*1.25 -> 55888 | H39: =SUM(F39:G39) -> 139720 | I39: =H39*0.8 -> 111776 | J39: =I39/$I$58 -> 0.062516123
B40: SÃO PAULO CAPITAL | C40: RADIO | D40: BANDEIRANTES | F40: =SUM(RÁDIO!CH22:CH23)*1.25 -> 59052 | G40: =SUM(RÁDIO!CJ22:CJ23)*1.25 -> 59052 | H40: =SUM(F40:G40) -> 118104 | I40: =H40*0.8 -> 94483.2 | J40: =I40/$I$58 -> 0.05284429
B41: SÃO PAULO CAPITAL | C41: RADIO | D41: CBN | F41: =SUM(RÁDIO!CH26:CH27)*1.25 -> 104319 | G41: =SUM(RÁDIO!CJ26:CJ27)*1.25 -> 48682.2 | H41: =SUM(F41:G41) -> 153001.2 | I41: =H41*0.8 -> 122400.96 | J41: =I41/$I$58 -> 0.068458645
B42: SÃO PAULO CAPITAL | C42: RADIO | D42: NATIVA FM | F42: =SUM(RÁDIO!CH35:CH36)*1.25 -> 60773.24 | G42: =SUM(RÁDIO!CJ35:CJ36)*1.25 -> 53867.19 | H42: =SUM(F42:G42) -> 114640.43 | I42: =H42*0.8 -> 91712.344 | J42: =I42/$I$58 -> 0.051294555
B43: SÃO PAULO CAPITAL | C43: RADIO | D43: BAND FM | F43: =SUM(RÁDIO!CH39:CH40)*1.25 -> 77714 | G43: =SUM(RÁDIO!CJ39:CJ40)*1.25 -> 77714 | H43: =SUM(F43:G43) -> 155428 | I43: =H43*0.8 -> 124342.4 | J43: =I43/$I$58 -> 0.069544489
B44: SÃO PAULO CAPITAL | C44: RADIO | D44: 89 ROCK FM | F44: =SUM(RÁDIO!CH43:CH44)*1.25 -> 72852 | G44: =SUM(RÁDIO!CJ43:CJ44)*1.25 -> 72852 | H44: =SUM(F44:G44) -> 145704 | I44: =H44*0.8 -> 116563.2 | J44: =I44/$I$58 -> 0.065193596
B45: SÃO PAULO CAPITAL | C45: RADIO | D45: ALPHA FM | F45: =SUM(RÁDIO!CH47:CH48)*1.25 -> 91929.6 | G45: =SUM(RÁDIO!CJ47:CJ48)*1.25 -> 94348.8 | H45: =SUM(F45:G45) -> 186278.4 | I45: =H45*0.8 -> 149022.72 | J45: =I45/$I$58 -> 0.083348149
B46: SÃO PAULO CAPITAL | C46: RADIO | D46: DISNEY FM | F46: =SUM(RÁDIO!CH51:CH52)*1.25 -> 60762 | G46: =SUM(RÁDIO!CJ51:CJ52)*1.25 -> 62361 | H46: =SUM(F46:G46) -> 123123 | I46: =H46*0.8 -> 98498.4 | J46: =I46/$I$58 -> 0.055089984
B47: SÃO PAULO CAPITAL | C47: RADIO | D47: ENERGIA 97 FM | F47: =SUM(RÁDIO!CH55:CH56)*1.25 -> 25766 | G47: =SUM(RÁDIO!CJ55:CJ56)*1.25 -> 25766 | H47: =SUM(F47:G47) -> 51532 | I47: =H47*0.8 -> 41225.6 | J47: =I47/$I$58 -> 0.023057407
B48: SÃO PAULO CAPITAL | C48: RADIO | D48: KISS FM | F48: =SUM(RÁDIO!CH59:CH60)*1.25 -> 0 | G48: =SUM(RÁDIO!CJ59:CJ60)*1.25 -> 0 | H48: =SUM(F48:G48) -> 0 | I48: =H48*0.8 -> 0 | J48: =I48/$I$58 -> 0
B49: SÃO PAULO CAPITAL | C49: RADIO | D49: GAZETA FM | F49: =SUM(RÁDIO!CH63:CH64)*1.25 -> 67184 | G49: =SUM(RÁDIO!CJ63:CJ64)*1.25 -> 67184 | H49: =SUM(F49:G49) -> 134368 | I49: =H49*0.8 -> 107494.4 | J49: =I49/$I$58 -> 0.060121431
B50: SÃO PAULO CAPITAL | C50: RADIO | D50: 105 FM | F50: =SUM(RÁDIO!CH67:CH68)*1.25 -> 40716 | G50: =SUM(RÁDIO!CJ67:CJ68)*1.25 -> 40716 | H50: =SUM(F50:G50) -> 81432 | I50: =H50*0.8 -> 65145.6 | J50: =I50/$I$58 -> 0.036435821
B51: SÃO PAULO CAPITAL | C51: RADIO | D51: RÁDIO MIX | F51: =SUM(RÁDIO!CH71+RÁDIO!CH72)*1.25 -> 60115 | G51: =SUM(RÁDIO!CJ71+RÁDIO!CJ72)*1.25 -> 53283.75 | H51: =SUM(F51:G51) -> 113398.75 | I51: =H51*0.8 -> 90719 | J51: =I51/$I$58 -> 0.050738979
B52: SÃO PAULO CAPITAL | C52: RADIO | D52: TRANSAMÉRICA FM | F52: =SUM(RÁDIO!CH75:CH76)*1.25 -> 53911.2 | G52: =SUM(RÁDIO!CJ75:CJ76)*1.25 -> 50060.4 | H52: =SUM(F52:G52) -> 103971.6 | I52: =H52*0.8 -> 83177.28 | J52: =I52/$I$58 -> 0.046520908
B53: SÃO PAULO CAPITAL | C53: RADIO | D53: MASSA FM | F53: =SUM(RÁDIO!CH79:CH80)*1.25 -> 30410.64 | G53: =SUM(RÁDIO!CJ79:CJ80)*1.25 -> 30410.64 | H53: =SUM(F53:G53) -> 60821.28 | I53: =H53*0.8 -> 48657.024 | J53: =I53/$I$58 -> 0.027213789
...

Sheet RESUMO DE MEIOS - SPE
B5: CLIENT: SABESP
B6: CAMPAING: ESCASSEZ HIDRICA - CRÍTICO
B8: RESUMO DE MEIOS - SÃO PAULO ESTADO
B10: PRAÇA | C10: MEIO | D10: VEÍCULO | F10: JANEIRO | G10: FEVEREIRO | H10: TOTAL BRUTO | I10: VALOR DESEMBOLSO TT | J10: PART GERAL %
N12: UTILIZAÇÃO DE SALDO DE PACOTES | P12: SALDO PACOTE | Q12: TOTAL A SER FATURADO
B13: SÃO PAULO ESTADO | C13: TV ABERTA | D13: GLOBO | F13: ='TV ABERTA - SPE'!CC32*1.25 -> 3234841.4 | G13: ='TV ABERTA - SPE'!CE32*1.25 -> 1220562 | H13: =SUM(F13:G13) -> 4455403.4 | I13: =H13*0.8 -> 3564322.8 | J13: =I13/$I$23 -> 0.45681236 | N13: SBT | O13: =I16+I21 -> 1109489.6 | P13: 567311.6 | Q13: =O13-P13 -> 542178
B14: SÃO PAULO ESTADO | C14: TV ABERTA | D14: BANDEIRANTES | F14: ='TV ABERTA - SPE'!CC44*1.25 -> 118538.85 | G14: ='TV ABERTA - SPE'!CE44*1.25 -> 77298.6 | H14: =SUM(F14:G14) -> 195837.45 | I14: =H14*0.8 -> 156669.96 | J14: =I14/$I$23 -> 0.020079207
B15: SÃO PAULO ESTADO | C15: TV ABERTA | D15: RECORD | F15: ='TV ABERTA - SPE'!CC57*1.25 -> 602332.6 | G15: ='TV ABERTA - SPE'!CE57*1.25 -> 574113.2 | H15: =SUM(F15:G15) -> 1176445.8 | I15: =H15*0.8 -> 941156.64 | J15: =I15/$I$23 -> 0.12062095
B16: SÃO PAULO ESTADO | C16: TV ABERTA | D16: SBT | F16: ='TV ABERTA - SPE'!CC70*1.25 -> 510641.5 | G16: ='TV ABERTA - SPE'!CE70*1.25 -> 573264 | H16: =SUM(F16:G16) -> 1083905.5 | I16: =H16*0.8 -> 867124.4 | J16: =I16/$I$23 -> 0.11113279
B18: SÃO PAULO ESTADO | C18: TV ABERTA | D18: GLOBO | F18: ='TV ABERTA - COLCHÃO REP - SPE'!CC17*1.25 -> 830408.4 | G18: ='TV ABERTA - COLCHÃO REP - SPE'!CE17*1.25 -> 830408.4 | H18: =SUM(F18:G18) -> 1660816.8 | I18: =H18*0.8 -> 1328653.4 | J18: =I18/$I$23 -> 0.17028349
B19: SÃO PAULO ESTADO | C19: TV ABERTA | D19: BANDEIRANTES | F19: ='TV ABERTA - COLCHÃO REP - SPE'!CC20*1.25 -> 114500.4 | G19: ='TV ABERTA - COLCHÃO REP - SPE'!CE20*1.25 -> 114500.4 | H19: =SUM(F19:G19) -> 229000.8 | I19: =H19*0.8 -> 183200.64 | J19: =I19/$I$23 -> 0.023479444
B20: SÃO PAULO ESTADO | C20: TV ABERTA | D20: RECORD | F20: ='TV ABERTA - COLCHÃO REP - SPE'!CC23*1.25 -> 324440 | G20: ='TV ABERTA - COLCHÃO REP - SPE'!CE23*1.25 -> 324440 | H20: =SUM(F20:G20) -> 648880 | I20: =H20*0.8 -> 519104 | J20: =I20/$I$23 -> 0.066529644
B21: SÃO PAULO ESTADO | C21: TV ABERTA | D21: SBT | F21: ='TV ABERTA - COLCHÃO REP - SPE'!CC25*1.25 -> 100985.5 | G21: ='TV ABERTA - COLCHÃO REP - SPE'!CE25*1.25 -> 201971 | H21: =SUM(F21:G21) -> 302956.5 | I21: =H21*0.8 -> 242365.2 | J21: =I21/$I$23 -> 0.031062119
B23: TT TV ABERTA | F23: =SUM(F13:F21) -> 5836688.7 | G23: =SUM(G13:G21) -> 3916557.6 | H23: =SUM(H13:H21) -> 9753246.3 | I23: =SUM(I13:I21) -> 7802597 | J23: =SUM(J13:J21) -> 1 | K23: =I23/I68 -> 0.75373272 | L23: =I23=SUM('TV ABERTA - SPE'!BU72,'TV ABERTA - COLCHÃO REP - SPE'!BU27) -> TRUE
B25: SÃO PAULO ESTADO | C25: TV PAGA | D25: GLOBONEWS | F25: ='TV PAGA - COLCHÃO REP - SPE'!CC37*1.25 -> 38904 | G25: ='TV PAGA - COLCHÃO REP - SPE'!CE37*1.25 -> 38904 | H25: =SUM(F25:G25) -> 77808 | I25: =H25*0.8 -> 62246.4 | J25: =I25/$I$30 -> 0.41072115
B26: SÃO PAULO ESTADO | C26: TV PAGA | D26: CNN BRASIL | F26: ='TV PAGA - COLCHÃO REP - SPE'!CC40*1.25 -> 22260 | G26: ='TV PAGA - COLCHÃO REP - SPE'!CE40*1.25 -> 22260 | H26: =SUM(F26:G26) -> 44520 | I26: =H26*0.8 -> 35616 | J26: =I26/$I$30 -> 0.23500547
B27: SÃO PAULO ESTADO | C27: TV PAGA | D27: RECORD NEWS | F27: ='TV PAGA - COLCHÃO REP - SPE'!CC43*1.25 -> 22000 | G27: ='TV PAGA - COLCHÃO REP - SPE'!CE43*1.25 -> 22000 | H27: =SUM(F27:G27) -> 44000 | I27: =H27*0.8 -> 35200 | J27: =I27/$I$30 -> 0.23226057
B28: SÃO PAULO ESTADO | C28: TV PAGA | D28: BAND NEWS | F28: ='TV PAGA - COLCHÃO REP - SPE'!CC46*1.25 -> 11557.2 | G28: ='TV PAGA - COLCHÃO REP - SPE'!CE46*1.25 -> 11557.2 | H28: =SUM(F28:G28) -> 23114.4 | I28: =H28*0.8 -> 18491.52 | J28: =I28/$I$30 -> 0.12201281
B30: TT TV PAGA | F30: =SUM(F25:F29) -> 94721.2 | G30: =SUM(G25:G29) -> 94721.2 | H30: =SUM(H25:H29) -> 189442.4 | I30: =SUM(I25:I29) -> 151553.92 | J30: =SUM(J25:J29) -> 1 | K30: =I30/I68 -> 0.014640145 | L30: =I30='TV PAGA - COLCHÃO REP - SPE'!BU48 -> TRUE
B32: SÃO PAULO | C32: JORNAL | D32: =JORNAL!C14 -> FOLHA DE SP | F32: =SUM(JORNAL!CN14:CN16)*1.25 -> 205409.91 | G32: {=SUM(JORNAL!CP14:CP16*1.25)} -> 0 | H32: =SUM(F32:G32) -> 205409.91 | I32: =H32*0.8 -> 164327.93 | J32: =I32/$I$38 -> 0.30990317
B33: SÃO PAULO | C33: JORNAL | D33: =JORNAL!C19 -> O ESTADO DE SP | F33: =SUM(JORNAL!CN19:CN21)*1.25 -> 232919.51 | G33: =SUM(JORNAL!CP19:CP21)*1.25 -> 0 | H33: =SUM(F33:G33) -> 232919.51 | I33: =H33*0.8 -> 186335.61 | J33: =I33/$I$38 -> 0.35140706
B34: SÃO PAULO | C34: JORNAL | D34: =JORNAL!C23 -> VALOR | F34: =SUM(JORNAL!CN23:CN25)*1.25 -> 138378.24 | G34: =SUM(JORNAL!CP23:CP25)*1.25 -> 0 | H34: =SUM(F34:G34) -> 138378.24 | I34: =H34*0.8 -> 110702.59 | J34: =I34/$I$38 -> 0.20877208
B35: SÃO PAULO | C35: JORNAL | D35: =JORNAL!C27 -> GAZETA DE SP | F35: =SUM(JORNAL!CN27:CN28)*1.25 -> 0 | G35: =SUM(JORNAL!CP27:CP29)*1.25 -> 0 | H35: =SUM(F35:G35) -> 0 | I35: =H35*0.8 -> 0 | J35: =I35/$I$38 -> 0
B36: =JORNAL!B31 -> ABC | C36: JORNAL | D36: =JORNAL!C31 -> DIÁRIO DO GRANDE ABC | F36: =SUM(JORNAL!CN31:CN34)*1.25 -> 86112 | G36: =SUM(JORNAL!CP31:CP34)*1.25 -> 0 | H36: =SUM(F36:G36) -> 86112 | I36: =H36*0.8 -> 68889.6 | J36: =I36/$I$38 -> 0.12991769
B38: TT JORNAL | F38: =SUM(F32:F36) -> 662819.66 | G38: =SUM(G32:G36) -> 0 | H38: =SUM(H32:H36) -> 662819.66 | I38: =SUM(I32:I36) -> 530255.73 | J38: =SUM(J32:J36) -> 1 | K38: =I38/I68 -> 0.051222829 | L38: =I38=JORNAL!CN39 -> TRUE
B40: SÃO PAULO | C40: RADIO | D40: JOVEM PAN FM | F40: =SUM(RÁDIO!CH14:CH15)*1.25 -> 94517.28 | G40: =SUM(RÁDIO!CJ14:CJ15)*1.25 -> 89266.32 | H40: =SUM(F40:G40) -> 183783.6 | I40: =H40*0.8 -> 147026.88 | J40: =I40/$I$60 -> 0.082231879
B41: SÃO PAULO | C41: RADIO | D41: BAND NEWS FM | F41: =SUM(RÁDIO!CH18:CH19)*1.25 -> 83832 | G41: =SUM(RÁDIO!CJ18:CJ19)*1.25 -> 55888 | H41: =SUM(F41:G41) -> 139720 | I41: =H41*0.8 -> 111776 | J41: =I41/$I$60 -> 0.062516123
B42: SÃO PAULO | C42: RADIO | D42: BANDEIRANTES | F42: =SUM(RÁDIO!CH22:CH23)*1.25 -> 59052 | G42: =SUM(RÁDIO!CJ22:CJ23)*1.25 -> 59052 | H42: =SUM(F42:G42) -> 118104 | I42: =H42*0.8 -> 94483.2 | J42: =I42/$I$60 -> 0.05284429
B43: SÃO PAULO | C43: RADIO | D43: CBN | F43: =SUM(RÁDIO!CH26:CH27)*1.25 -> 104319 | G43: =SUM(RÁDIO!CJ26:CJ27)*1.25 -> 48682.2 | H43: =SUM(F43:G43) -> 153001.2 | I43: =H43*0.8 -> 122400.96 | J43: =I43/$I$60 -> 0.068458645
B44: SÃO PAULO | C44: RADIO | D44: NATIVA FM | F44: =SUM(RÁDIO!CH35:CH36)*1.25 -> 60773.24 | G44: =SUM(RÁDIO!CJ35:CJ36)*1.25 -> 53867.19 | H44: =SUM(F44:G44) -> 114640.43 | I44: =H44*0.8 -> 91712.344 | J44: =I44/$I$60 -> 0.051294555
B45: SÃO PAULO | C45: RADIO | D45: BAND FM | F45: =SUM(RÁDIO!CH39:CH40)*1.25 -> 77714 | G45: =SUM(RÁDIO!CJ39:CJ40)*1.25 -> 77714 | H45: =SUM(F45:G45) -> 155428 | I45: =H45*0.8 -> 124342.4 | J45: =I45/$I$60 -> 0.069544489
B46: SÃO PAULO | C46: RADIO | D46: 89 ROCK FM | F46: =SUM(RÁDIO!CH43:CH44)*1.25 -> 72852 | G46: =SUM(RÁDIO!CJ43:CJ44)*1.25 -> 72852 | H46: =SUM(F46:G46) -> 145704 | I46: =H46*0.8 -> 116563.2 | J46: =I46/$I$60 -> 0.065193596
B47: SÃO PAULO | C47: RADIO | D47: ALPHA FM | F47: =SUM(RÁDIO!CH47:CH48)*1.25 -> 91929.6 | G47: =SUM(RÁDIO!CJ47:CJ48)*1.25 -> 94348.8 | H47: =SUM(F47:G47) -> 186278.4 | I47: =H47*0.8 -> 149022.72 | J47: =I47/$I$60 -> 0.083348149
B48: SÃO PAULO | C48: RADIO | D48: DISNEY FM | F48: =SUM(RÁDIO!CH51:CH52)*1.25 -> 60762 | G48: =SUM(RÁDIO!CJ51:CJ52)*1.25 -> 62361 | H48: =SUM(F48:G48) -> 123123 | I48: =H48*0.8 -> 98498.4 | J48: =I48/$I$60 -> 0.055089984
B49: SÃO PAULO | C49: RADIO | D49: ENERGIA 97 FM | F49: =SUM(RÁDIO!CH55:CH56)*1.25 -> 25766 | G49: =SUM(RÁDIO!CJ55:CJ56)*1.25 -> 25766 | H49: =SUM(F49:G49) -> 51532 | I49: =H49*0.8 -> 41225.6 | J49: =I49/$I$60 -> 0.023057407
B50: SÃO PAULO | C50: RADIO | D50: KISS FM | F50: =SUM(RÁDIO!CH59:CH60)*1.25 -> 0 | G50: =SUM(RÁDIO!CJ59:CJ60)*1.25 -> 0 | H50: =SUM(F50:G50) -> 0 | I50: =H50*0.8 -> 0 | J50: =I50/$I$60 -> 0
B51: SÃO PAULO | C51: RADIO | D51: GAZETA FM | F51: =SUM(RÁDIO!CH63:CH64)*1.25 -> 67184 | G51: =SUM(RÁDIO!CJ63:CJ64)*1.25 -> 67184 | H51: =SUM(F51:G51) -> 134368 | I51: =H51*0.8 -> 107494.4 | J51: =I51/$I$60 -> 0.060121431
B52: SÃO PAULO | C52: RADIO | D52: 105 FM | F52: =SUM(RÁDIO!CH67:CH68)*1.25 -> 40716 | G52: =SUM(RÁDIO!CJ67:CJ68)*1.25 -> 40716 | H52: =SUM(F52:G52) -> 81432 | I52: =H52*0.8 -> 65145.6 | J52: =I52/$I$60 -> 0.036435821
B53: SÃO PAULO | C53: RADIO | D53: RÁDIO MIX | F53: =SUM(RÁDIO!CH71+RÁDIO!CH72)*1.25 -> 60115 | G53: =SUM(RÁDIO!CJ71+RÁDIO!CJ72)*1.25 -> 53283.75 | H53: =SUM(F53:G53) -> 113398.75 | I53: =H53*0.8 -> 90719 | J53: =I53/$I$60 -> 0.050738979
B54: SÃO PAULO | C54: RADIO | D54: TRANSAMÉRICA FM | F54: =SUM(RÁDIO!CH75:CH76)*1.25 -> 53911.2 | G54: =SUM(RÁDIO!CJ75:CJ76)*1.25 -> 50060.4 | H54: =SUM(F54:G54) -> 103971.6 | I54: =H54*0.8 -> 83177.28 | J54: =I54/$I$60 -> 0.046520908
...

Sheet TV ABERTA - SP1
B5: CLIENT: SABESP
B6: CAMPAING: ESCASSEZ HIDRICA - CRÍTICO
BW7: PLANNED
B8: MARKET | C8: CHANNEL | D8: PROGRAMM | E8: DAY | F8: START TIME | G8: END TIME | H8: SEC | I8: JANEIRO | AN8: FEVEREIRO | BP8: INS. | BQ8: CUSTO TABELA UNITÁRIO (BRUTO) | BR8: DESC. % | BS8: CUSTO NEGOCIADO UNITÁRIO (BRUTO) | BT8: CUSTO TOTAL NEGOCIADO (BRUTO) | BU8: CUSTO TOTAL DESEMBOLSO SABESP | BW8: AUD. AS ABCDE 25+ | BX8: TRP | BY8: CPP | CA8: RESUMO
I9: T | J9: F | K9: S | L9: S | M9: M | N9: T | O9: W | P9: T | Q9: F | R9: S | S9: S | T9: M | U9: T | V9: W | W9: T | X9: F | Y9: S | Z9: S | AA9: M | AB9: T | AC9: W | AD9: T | AE9: F | AF9: S | AG9: S | AH9: M | AI9: T | AJ9: W | AK9: T | AL9: F | AM9: S | AN9: S | AO9: M | AP9: T | AQ9: W | AR9: T | AS9: F | AT9: S | AU9: S | AV9: M | AW9: T | AX9: W | AY9: T | AZ9: F | BA9: S | BB9: S | BC9: M | BD9: T | BE9: W | BF9: T | BG9: F | BH9: S | BI9: S | BJ9: M | BK9: T | BL9: W | BM9: T | BN9: F | BO9: S
I10: 1 | J10: 2 | K10: 3 | L10: 4 | M10: 5 | N10: 6 | O10: 7 | P10: 8 | Q10: 9 | R10: 10 | S10: 11 | T10: 12 | U10: 13 | V10: 14 | W10: 15 | X10: 16 | Y10: 17 | Z10: =Y10+1 -> 18 | AA10: =Z10+1 -> 19 | AB10: =AA10+1 -> 20 | AC10: =AB10+1 -> 21 | AD10: =AC10+1 -> 22 | AE10: =AD10+1 -> 23 | AF10: =AE10+1 -> 24 | AG10: =AF10+1 -> 25 | ... AM10: =AL10+1 -> 31 | AN10: 1 | AO10: 2 | AP10: 3 | AQ10: 4 | AR10: 5 | AS10: 6 | AT10: 7 | AU10: 8 | AV10: 9 | AW10: 10 | AX10: 11 | AY10: 12 | AZ10: 13 | BA10: 14 | BB10: 15 | BC10: 16 | BD10: 17 | BE10: =BD10+1 -> 18 | BF10: =BE10+1 -> 19 | BG10: =BF10+1 -> 20 | BH10: =BG10+1 -> 21 | BI10: =BH10+1 -> 22 | BJ10: =BI10+1 -> 23 | BK10: =BJ10+1 -> 24 | BL10: =BK10+1 -> 25 | ... BO10: =BN10+1 -> 28 | CA10: CHANNEL | CB10: JANEIRO | CD10: FEVEREIRO
CB12: INS | CC12: INVESTIMENTO $ | CD12: INS | CE12: INVESTIMENTO $
B13: SÃO PAULO CAPITAL | C13: TV GLOBO | D13: NOVELA II | E13: SEG-SEX | F13: 0.81944444 | G13: 0.85416667 | H13: 30 | AJ13: 1 | BP13: =SUM(I13:BO13) -> 1 | BQ13: 131844 | BR13: 1 | BS13: =BQ13*(1-BR13) -> 0 | BT13: =BS13*BP13 -> 0 | BU13: =BT13*0.8 -> 0 | BW13: 12.33 | BX13: =BW13*BP13 -> 12.33 | BY13: =IFERROR(BU13/BX13,0) -> 0 | CA13: TV GLOBO | CB13: =COUNTA(I13:AM13) -> 1 | CC13: =CB13*BS13*0.8 -> 0 | CD13: =COUNTA(AN13:BO13) -> 0 | CE13: =CD13*BS13*0.8 -> 0 | CF13: =SUM(CC13,CE13)=BU13 -> TRUE
D14: NOVELA III | E14: SEG-SEX | F14: 0.88888889 | G14: 0.93402778 | H14: 30 | AH14: 1 | AK14: 1 | BP14: =SUM(I14:BO14) -> 2 | BQ14: 182594 | BR14: 0 | BS14: =BQ14*(1-BR14) -> 182594 | BT14: =BS14*BP14 -> 365188 | BU14: =BT14*0.8 -> 292150.4 | BW14: 13.35 | BX14: =BW14*BP14 -> 26.7 | BY14: =IFERROR(BU14/BX14,0) -> 10941.963 | CA14: TV GLOBO | CB14: =COUNTA(I14:AM14) -> 2 | CC14: =CB14*BS14*0.8 -> 292150.4 | CD14: =COUNTA(AN14:BO14) -> 0 | CE14: =CD14*BS14*0.8 -> 0 | CF14: =SUM(CC14,CE14)=BU14 -> TRUE
D16: JORNAL HOJE | E16: SEG-SEX | F16: 0.55902778 | G16: 0.61458333 | H16: 30 | AO16: 1 | AR16: 1 | AW16: 1 | BP16: =SUM(I16:BO16) -> 3 | BQ16: 41050 | BR16: 0.30844153 | BS16: =BQ16*(1-BR16) -> 28388.475 | BT16: =BS16*BP16 -> 85165.426 | BU16: =BT16*0.8 -> 68132.341 | BW16: 5.92 | BX16: =BW16*BP16 -> 17.76 | BY16: =IFERROR(BU16/BX16,0) -> 3836.2804 | CA16: TV GLOBO | CB16: =COUNTA(I16:AM16) -> 0 | CC16: =CB16*BS16*0.8 -> 0 | CD16: =COUNTA(AN16:BO16) -> 3 | CE16: =CD16*BS16*0.8 -> 68132.341 | CF16: =SUM(CC16,CE16)=BU16 -> TRUE
D17: BOM DIA BRASIL | E17: SEG-SEX | F17: 0.33333333 | G17: 0.39583333 | H17: 30 | AQ17: 1 | AV17: 1 | AY17: 1 | AZ17: 1 | BP17: =SUM(I17:BO17) -> 4 | BQ17: 25643 | BR17: 0.30844153 | BS17: =BQ17*(1-BR17) -> 17733.634 | BT17: =BS17*BP17 -> 70934.536 | BU17: =BT17*0.8 -> 56747.628 | BW17: 4.94 | BX17: =BW17*BP17 -> 19.76 | BY17: =IFERROR(BU17/BX17,0) -> 2871.8435 | CA17: TV GLOBO | CB17: =COUNTA(I17:AM17) -> 0 | CC17: =CB17*BS17*0.8 -> 0 | CD17: =COUNTA(AN17:BO17) -> 4 | CE17: =CD17*BS17*0.8 -> 56747.628 | CF17: =SUM(CC17,CE17)=BU17 -> TRUE
D18: BOM DIA PRACA | E18: SEG-SEX | F18: 0.25 | G18: 0.35416667 | H18: 30 | AP18: 1 | AR18: 1 | AS18: 1 | AW18: 1 | AX18: 1 | BP18: =SUM(I18:BO18) -> 5 | BQ18: 18183 | BR18: 0.30844153 | BS18: =BQ18*(1-BR18) -> 12574.608 | BT18: =BS18*BP18 -> 62873.039 | BU18: =BT18*0.8 -> 50298.431 | BW18: 4.41 | BX18: =BW18*BP18 -> 22.05 | BY18: =IFERROR(BU18/BX18,0) -> 2281.108 | CA18: TV GLOBO | CB18: =COUNTA(I18:AM18) -> 0 | CC18: =CB18*BS18*0.8 -> 0 | CD18: =COUNTA(AN18:BO18) -> 5 | CE18: =CD18*BS18*0.8 -> 50298.431 | CF18: =SUM(CC18,CE18)=BU18 -> TRUE
D20: JORNAL NACIONAL | E20: SEG-SEX | F20: 0.85416667 | G20: 0.88888889 | H20: 30 | AV20: 1 | BP20: =SUM(I20:BO20) -> 1 | BQ20: 180006 | BR20: 0 | BS20: =BQ20*(1-BR20) -> 180006 | BT20: =BS20*BP20 -> 180006 | BU20: =BT20*0.8 -> 144004.8 | BW20: 13.07 | BX20: =BW20*BP20 -> 13.07 | BY20: =IFERROR(BU20/BX20,0) -> 11017.965 | CA20: TV GLOBO | CB20: =COUNTA(I20:AM20) -> 0 | CC20: =CB20*BS20*0.8 -> 0 | CD20: =COUNTA(AN20:BO20) -> 1 | CE20: =CD20*BS20*0.8 -> 144004.8 | CF20: =SUM(CC20,CE20)=BU20 -> TRUE
D21: FANTASTICO | E21: DOM | F21: 0.85416667 | G21: 0.96527778 | H21: 30 | AU21: 1 | BP21: =SUM(I21:BO21) -> 1 | BQ21: 144982 | BR21: 0 | BS21: =BQ21*(1-BR21) -> 144982 | BT21: =BS21*BP21 -> 144982 | BU21: =BT21*0.8 -> 115985.6 | BW21: 8.8 | BX21: =BW21*BP21 -> 8.8 | BY21: =IFERROR(BU21/BX21,0) -> 13180.182 | CA21: TV GLOBO | CB21: =COUNTA(I21:AM21) -> 0 | CC21: =CB21*BS21*0.8 -> 0 | CD21: =COUNTA(AN21:BO21) -> 1 | CE21: =CD21*BS21*0.8 -> 115985.6 | CF21: =SUM(CC21,CE21)=BU21 -> TRUE
D22: JORNAL DA GLOBO | E22: SEG-SEX | F22: 0.041666667 | G22: 0.076388889 | H22: 30 | AO22: 1 | AQ22: 1 | AW22: 1 | AY22: 1 | BP22: =SUM(I22:BO22) -> 4 | BQ22: 28729 | BR22: 1 | BS22: =BQ22*(1-BR22) -> 0 | BT22: =BS22*BP22 -> 0 | BU22: =BT22*0.8 -> 0 | BW22: 3.7 | BX22: =BW22*BP22 -> 14.8 | BY22: =IFERROR(BU22/BX22,0) -> 0 | CA22: TV GLOBO | CB22: =COUNTA(I22:AM22) -> 0 | CC22: =CB22*BS22*0.8 -> 0 | CD22: =COUNTA(AN22:BO22) -> 4 | CE22: =CD22*BS22*0.8 -> 0 | CF22: =SUM(CC22,CE22)=BU22 -> TRUE
D24: NOVELA I | E24: SEG-SEX | F24: 0.76736111 | G24: 0.79861111 | H24: 30 | AH24: 1 | AK24: 1 | BP24: =SUM(I24:BO24) -> 2 | BQ24: 98392 | BR24: 0 | BS24: =BQ24*(1-BR24) -> 98392 | BT24: =BS24*BP24 -> 196784 | BU24: =BT24*0.8 -> 157427.2 | BW24: 8.51 | BX24: =BW24*BP24 -> 17.02 | BY24: =IFERROR(BU24/BX24,0) -> 9249.5417 | CA24: TV GLOBO | CB24: =COUNTA(I24:AM24) -> 2 | CC24: =CB24*BS24*0.8 -> 157427.2 | CD24: =COUNTA(AN24:BO24) -> 0 | CE24: =CD24*BS24*0.8 -> 0 | CF24: =SUM(CC24,CE24)=BU24 -> TRUE
D25: NOVELA II | E25: SEG-SEX | F25: 0.81944444 | G25: 0.85416667 | H25: 30 | AI25: 1 | AL25: 1 | BP25: =SUM(I25:BO25) -> 2 | BQ25: 131844 | BR25: 0 | BS25: =BQ25*(1-BR25) -> 131844 | BT25: =BS25*BP25 -> 263688 | BU25: =BT25*0.8 -> 210950.4 | BW25: 12.33 | BX25: =BW25*BP25 -> 24.66 | BY25: =IFERROR(BU25/BX25,0) -> 8554.3552 | CA25: TV GLOBO | CB25: =COUNTA(I25:AM25) -> 2 | CC25: =CB25*BS25*0.8 -> 210950.4 | CD25: =COUNTA(AN25:BO25) -> 0 | CE25: =CD25*BS25*0.8 -> 0 | CF25: =SUM(CC25,CE25)=BU25 -> TRUE
D26: NOVELA I | E26: SÁB | F26: 0.77777778 | G26: 0.80902778 | H26: 30 | AJ26: 1 | BP26: =SUM(I26:BO26) -> 1 | BQ26: 98392 | BR26: 1 | BS26: =BQ26*(1-BR26) -> 0 | BT26: =BS26*BP26 -> 0 | BU26: =BT26*0.8 -> 0 | BW26: 11.08 | BX26: =BW26*BP26 -> 11.08 | BY26: =IFERROR(BU26/BX26,0) -> 0 | CA26: TV GLOBO | CB26: =COUNTA(I26:AM26) -> 1 | CC26: =CB26*BS26*0.8 -> 0 | CD26: =COUNTA(AN26:BO26) -> 0 | CE26: =CD26*BS26*0.8 -> 0 | CF26: =SUM(CC26,CE26)=BU26 -> TRUE
D28: JORNAL NACIONAL | E28: SEG-SEX | F28: 0.88888889 | G28: 0.93402778 | H28: 60 | AE28: 1 | BP28: =SUM(I28:BO28) -> 1 | BQ28: =180006*2 -> 360012 | BR28: 0 | BS28: =BQ28*(1-BR28) -> 360012 | BT28: =BS28*BP28 -> 360012 | BU28: =BT28*0.8 -> 288009.6 | BW28: 13.07 | BX28: =BW28*BP28 -> 13.07 | BY28: =IFERROR(BU28/BX28,0) -> 22035.93 | CA28: TV GLOBO | CB28: =COUNTA(I28:AM28) -> 1 | CC28: =CB28*BS28*0.8 -> 288009.6 | CD28: =COUNTA(AN28:BO28) -> 0 | CE28: =CD28*BS28*0.8 -> 0 | CF28: =SUM(CC28,CE28)=BU28 -> TRUE
D29: FANTASTICO | E29: DOM | F29: 0.85416667 | G29: 0.96527778 | H29: 60 | AG29: 1 | BP29: =SUM(I29:BO29) -> 1 | BQ29: =144982*2 -> 289964 | BR29: 0 | BS29: =BQ29*(1-BR29) -> 289964 | BT29: =BS29*BP29 -> 289964 | BU29: =BT29*0.8 -> 231971.2 | BW29: 8.8 | BX29: =BW29*BP29 -> 8.8 | BY29: =IFERROR(BU29/BX29,0) -> 26360.364 | CA29: TV GLOBO | CB29: =COUNTA(I29:AM29) -> 1 | CC29: =CB29*BS29*0.8 -> 231971.2 | CD29: =COUNTA(AN29:BO29) -> 0 | CE29: =CD29*BS29*0.8 -> 0 | CF29: =SUM(CC29,CE29)=BU29 -> TRUE
D30: PRACA TV 2 ED SAB | E30: SÁB | F30: 0.80902778 | G30: 0.82291667 | H30: 60 | AF30: 1 | BP30: =SUM(I30:BO30) -> 1 | BQ30: =112324*2 -> 224648 | BR30: 1 | BS30: =BQ30*(1-BR30) -> 0 | BT30: =BS30*BP30 -> 0 | BU30: =BT30*0.8 -> 0 | BW30: 12.39 | BX30: =BW30*BP30 -> 12.39 | BY30: =IFERROR(BU30/BX30,0) -> 0 | CA30: TV GLOBO | CB30: =COUNTA(I30:AM30) -> 1 | CC30: =CB30*BS30*0.8 -> 0 | CD30: =COUNTA(AN30:BO30) -> 0 | CE30: =CD30*BS30*0.8 -> 0 | CF30: =SUM(CC30,CE30)=BU30 -> TRUE
D32: JORNAL NACIONAL | E32: SEG-SEX | F32: 0.85416667 | G32: 0.88888889 | H32: 60 | AD32: 1 | BP32: =SUM(I32:BO32) -> 1 | BQ32: =(180006*2) -> 360012 | BR32: 0.1 | BS32: =BQ32*(1-BR32) -> 324010.8 | BT32: =BS32*BP32 -> 324010.8 | BU32: =BT32*0.8 -> 259208.64 | BW32: 13.07 | BX32: =BW32*BP32 -> 13.07 | BY32: =IFERROR(BU32/BX32,0) -> 19832.337 | CA32: TV GLOBO | CB32: =COUNTA(I32:AM32) -> 1 | CC32: =CB32*BS32*0.8 -> 259208.64 | CD32: =COUNTA(AN32:BO32) -> 0 | CE32: =CD32*BS32*0.8 -> 0 | CF32: =SUM(CC32,CE32)=BU32 -> TRUE
CA33: TT | CB33: =SUM(CB13:CB32) -> 12 | CC33: =SUM(CC13:CC32) -> 1439717.4 | CD33: =SUM(CD13:CD32) -> 18 | CE33: =SUM(CE13:CE32) -> 435168.8
C34: BANDEIRANTES | D34: BORA BRASIL | E34: SEG-SEX | F34: 0.375 | G34: 11:00 | H34: 30 | AK34: 1 | AR34: 1 | AY34: 1 | BP34: =SUM(I34:BO34) -> 3 | BQ34: 10649 | BR34: 0.85 | BS34: =BQ34*(1-BR34) -> 1597.35 | BT34: =BS34*BP34 -> 4792.05 | BU34: =BT34*0.8 -> 3833.64 | BW34: 0.24 | BX34: =BW34*BP34 -> 0.72 | BY34: =IFERROR(BU34/BX34,0) -> 5324.5 | CA34: BANDEIRANTES | CB34: =COUNTA(I34:AM34) -> 1 | CC34: =CB34*BS34*0.8 -> 1277.88 | CD34: =COUNTA(AN34:BO34) -> 2 | CE34: =CD34*BS34*0.8 -> 2555.76 | CF34: =SUM(CC34,CE34)=BU34 -> TRUE
D35: BORA BRASIL | E35: SEG-SEX | F35: 0.375 | G35: 11:00 | H35: 60 | AE35: 1 | BP35: =SUM(I35:BO35) -> 1 | BQ35: 21298 | BR35: 0.85 | BS35: =BQ35*(1-BR35) -> 3194.7 | BT35: =BS35*BP35 -> 3194.7 | BU35: =BT35*0.8 -> 2555.76 | BW35: 0.24 | BX35: =BW35*BP35 -> 0.24 | BY35: =IFERROR(BU35/BX35,0) -> 10649 | CA35: BANDEIRANTES | CB35: =COUNTA(I35:AM35) -> 1 | CC35: =CB35*BS35*0.8 -> 2555.76 | CD35: =COUNTA(AN35:BO35) -> 0 | CE35: =CD35*BS35*0.8 -> 0 | CF35: =SUM(CC35,CE35)=BU35 -> TRUE
D36: BRASIL URGENTE | E36: SEG-SÁB | F36: 0.66666667 | G36: 17:30 | H36: 30 | AL36: 1 | AS36: 1 | AZ36: 1 | BP36: =SUM(I36:BO36) -> 3 | BQ36: 37711 | BR36: 0.85 | BS36: =BQ36*(1-BR36) -> 5656.65 | BT36: =BS36*BP36 -> 16969.95 | BU36: =BT36*0.8 -> 13575.96 | BW36: 1.43 | BX36: =BW36*BP36 -> 4.29 | BY36: =IFERROR(BU36/BX36,0) -> 3164.5594 | CA36: BANDEIRANTES | CB36: =COUNTA(I36:AM36) -> 1 | CC36: =CB36*BS36*0.8 -> 4525.32 | CD36: =COUNTA(AN36:BO36) -> 2 | CE36: =CD36*BS36*0.8 -> 9050.64 | CF36: =SUM(CC36,CE36)=BU36 -> TRUE
D37: BRASIL URGENTE | E37: SEG-SÁB | F37: 0.66666667 | G37: 17:30 | H37: 60 | AE37: 1 | BP37: =SUM(I37:BO37) -> 1 | BQ37: 75422 | BR37: 0.85 | BS37: =BQ37*(1-BR37) -> 11313.3 | BT37: =BS37*BP37 -> 11313.3 | BU37: =BT37*0.8 -> 9050.64 | BW37: 1.43 | BX37: =BW37*BP37 -> 1.43 | BY37: =IFERROR(BU37/BX37,0) -> 6329.1189 | CA37: BANDEIRANTES | CB37: =COUNTA(I37:AM37) -> 1 | CC37: =CB37*BS37*0.8 -> 9050.64 | CD37: =COUNTA(AN37:BO37) -> 0 | CE37: =CD37*BS37*0.8 -> 0 | CF37: =SUM(CC37,CE37)=BU37 -> TRUE
D38: CANAL LIVRE | E38: DOM | F38: 0.95833333 | G38: 00:00 | H38: 30 | AU38: 1 | BP38: =SUM(I38:BO38) -> 1 | BQ38: 19480 | BR38: 0.85 | BS38: =BQ38*(1-BR38) -> 2922 | BT38: =BS38*BP38 -> 2922 | BU38: =BT38*0.8 -> 2337.6 | BW38: 0.21 | BX38: =BW38*BP38 -> 0.21 | BY38: =IFERROR(BU38/BX38,0) -> 11131.429 | CA38: BANDEIRANTES | CB38: =COUNTA(I38:AM38) -> 0 | CC38: =CB38*BS38*0.8 -> 0 | CD38: =COUNTA(AN38:BO38) -> 1 | CE38: =CD38*BS38*0.8 -> 2337.6 | CF38: =SUM(CC38,CE38)=BU38 -> TRUE
D39: CANAL LIVRE | E39: DOM | F39: 0.95833333 | G39: 00:00 | H39: 60 | AG39: 1 | BP39: =SUM(I39:BO39) -> 1 | BQ39: 38960 | BR39: 0.85 | BS39: =BQ39*(1-BR39) -> 5844 | BT39: =BS39*BP39 -> 5844 | BU39: =BT39*0.8 -> 4675.2 | BW39: 0.21 | BX39: =BW39*BP39 -> 0.21 | BY39: =IFERROR(BU39/BX39,0) -> 22262.857 | CA39: BANDEIRANTES | CB39: =COUNTA(I39:AM39) -> 1 | CC39: =CB39*BS39*0.8 -> 4675.2 | CD39: =COUNTA(AN39:BO39) -> 0 | CE39: =CD39*BS39*0.8 -> 0 | CF39: =SUM(CC39,CE39)=BU39 -> TRUE
D40: JORNAL DA NOITE | E40: SEG-SEX | F40: 0.010416667 | G40: 01:15 | H40: 30 | AJ40: 1 | AQ40: 1 | AX40: 1 | BP40: =SUM(I40:BO40) -> 3 | BQ40: 20453 | BR40: 0.85 | BS40: =BQ40*(1-BR40) -> 3067.95 | BT40: =BS40*BP40 -> 9203.85 | BU40: =BT40*0.8 -> 7363.08 | BW40: 0.34 | BX40: =BW40*BP40 -> 1.02 | BY40: =IFERROR(BU40/BX40,0) -> 7218.7059 | CA40: BANDEIRANTES | CB40: =COUNTA(I40:AM40) -> 1 | CC40: =CB40*BS40*0.8 -> 2454.36 | CD40: =COUNTA(AN40:BO40) -> 2 | CE40: =CD40*BS40*0.8 -> 4908.72 | CF40: =SUM(CC40,CE40)=BU40 -> TRUE
D41: JORNAL DA NOITE | E41: SEG-SEX | F41: 0.010416667 | G41: 01:15 | H41: 60 | AE41: 1 | BP41: =SUM(I41:BO41) -> 1 | BQ41: 40906 | BR41: 0.85 | BS41: =BQ41*(1-BR41) -> 6135.9 | BT41: =BS41*BP41 -> 6135.9 | BU41: =BT41*0.8 -> 4908.72 | BW41: 0.34 | BX41: =BW41*BP41 -> 0.34 | BY41: =IFERROR(BU41/BX41,0) -> 14437.412 | CA41: BANDEIRANTES | CB41: =COUNTA(I41:AM41) -> 1 | CC41: =CB41*BS41*0.8 -> 4908.72 | CD41: =COUNTA(AN41:BO41) -> 0 | CE41: =CD41*BS41*0.8 -> 0 | CF41: =SUM(CC41,CE41)=BU41 -> TRUE
D42: NOVELA I | E42: SEG-SEX | F42: 0.29166667 | G42: 08:00 | H42: 30 | BP42: =SUM(I42:BO42) -> 0 | BQ42: 10649 | BR42: 0.85 | BS42: =BQ42*(1-BR42) -> 1597.35 | BT42: =BS42*BP42 -> 0 | BU42: =BT42*0.8 -> 0 | BW42: 0.1 | BX42: =BW42*BP42 -> 0 | BY42: =IFERROR(BU42/BX42,0) -> 0 | CA42: BANDEIRANTES | CB42: =COUNTA(I42:AM42) -> 0 | CC42: =CB42*BS42*0.8 -> 0 | CD42: =COUNTA(AN42:BO42) -> 0 | CE42: =CD42*BS42*0.8 -> 0 | CF42: =SUM(CC42,CE42)=BU42 -> TRUE
D43: NOVELA II | E43: SEG-SEX | F43: 0.85416667 | G43: 21:25 | H43: 30 | AH43: 1 | AO43: 1 | AV43: 1 | BP43: =SUM(I43:BO43) -> 3 | BQ43: 66739 | BR43: 0.85 | BS43: =BQ43*(1-BR43) -> 10010.85 | BT43: =BS43*BP43 -> 30032.55 | BU43: =BT43*0.8 -> 24026.04 | BW43: 0.71 | BX43: =BW43*BP43 -> 2.13 | BY43: =IFERROR(BU43/BX43,0) -> 11279.831 | CA43: BANDEIRANTES | CB43: =COUNTA(I43:AM43) -> 1 | CC43: =CB43*BS43*0.8 -> 8008.68 | CD43: =COUNTA(AN43:BO43) -> 2 | CE43: =CD43*BS43*0.8 -> 16017.36 | CF43: =SUM(CC43,CE43)=BU43 -> TRUE
D44: NOVELA II | E44: SEG-SEX | F44: 0.85416667 | G44: 21:25 | H44: 60 | AE44: 1 | BP44: =SUM(I44:BO44) -> 1 | BQ44: 133478 | BR44: 0.85 | BS44: =BQ44*(1-BR44) -> 20021.7 | BT44: =BS44*BP44 -> 20021.7 | BU44: =BT44*0.8 -> 16017.36 | BW44: 0.71 | BX44: =BW44*BP44 -> 0.71 | BY44: =IFERROR(BU44/BX44,0) -> 22559.662 | CA44: BANDEIRANTES | CB44: =COUNTA(I44:AM44) -> 1 | CC44: =CB44*BS44*0.8 -> 16017.36 | CD44: =COUNTA(AN44:BO44) -> 0 | CE44: =CD44*BS44*0.8 -> 0 | CF44: =SUM(CC44,CE44)=BU44 -> TRUE
CA45: TT | CB45: =SUM(CB34:CB44) -> 9 | CC45: =SUM(CC34:CC44) -> 53473.92 | CD45: =SUM(CD34:CD44) -> 9 | CE45: =SUM(CE34:CE44) -> 34870.08
C46: RECORD | D46: CIDADE ALERTA ED SAB | E46: SÁB | F46: 0.70833333 | G46: 0.82291667 | H46: 30 | AM46: 1 | AT46: 1 | BP46: =SUM(I46:BO46) -> 2 | BQ46: 51691 | BR46: 0.8 | BS46: =BQ46*(1-BR46) -> 10338.2 | BT46: =BS46*BP46 -> 20676.4 | BU46: =BT46*0.8 -> 16541.12 | BW46: 2.19 | BX46: =BW46*BP46 -> 4.38 | BY46: =IFERROR(BU46/BX46,0) -> 3776.5114 | CA46: RECORD | CB46: =COUNTA(I46:AM46) -> 1 | CC46: =CB46*BS46*0.8 -> 8270.56 | CD46: =COUNTA(AN46:BO46) -> 1 | CE46: =CD46*BS46*0.8 -> 8270.56 | CF46: =SUM(CC46,CE46)=BU46 -> TRUE
D47: CIDADE ALERTA 2 SAB | E47: SÁB | F47: 0.875 | G47: 22:30 | H47: 60 | AF47: 1 | BP47: =SUM(I47:BO47) -> 1 | BQ47: 103382 | BR47: 0.8 | BS47: =BQ47*(1-BR47) -> 20676.4 | BT47: =BS47*BP47 -> 20676.4 | BU47: =BT47*0.8 -> 16541.12 | BW47: 2.19 | BX47: =BW47*BP47 -> 2.19 | BY47: =IFERROR(BU47/BX47,0) -> 7553.0228 | CA47: RECORD | CB47: =COUNTA(I47:AM47) -> 1 | CC47: =CB47*BS47*0.8 -> 16541.12 | CD47: =COUNTA(AN47:BO47) -> 0 | CE47: =CD47*BS47*0.8 -> 0 | CF47: =SUM(CC47,CE47)=BU47 -> TRUE
D48: DOMINGO ESPETACULAR | E48: DOM | F48: 0.75 | G48: 20:00 | H48: 30 | AN48: 1 | AU48: 1 | BP48: =SUM(I48:BO48) -> 2 | BQ48: 326000 | BR48: 0.8 | BS48: =BQ48*(1-BR48) -> 65200 | BT48: =BS48*BP48 -> 130400 | BU48: =BT48*0.8 -> 104320 | BW48: 3.05 | BX48: =BW48*BP48 -> 6.1 | BY48: =IFERROR(BU48/BX48,0) -> 17101.639 | CA48: RECORD | CB48: =COUNTA(I48:AM48) -> 0 | CC48: =CB48*BS48*0.8 -> 0 | CD48: =COUNTA(AN48:BO48) -> 2 | CE48: =CD48*BS48*0.8 -> 104320 | CF48: =SUM(CC48,CE48)=BU48 -> TRUE
D49: DOMINGO ESPETACULAR | E49: DOM | F49: 0.75 | G49: 20:00 | H49: 60 | AG49: 1 | BP49: =SUM(I49:BO49) -> 1 | BQ49: 652000 | BR49: 0.8 | BS49: =BQ49*(1-BR49) -> 130400 | BT49: =BS49*BP49 -> 130400 | BU49: =BT49*0.8 -> 104320 | BW49: 3.05 | BX49: =BW49*BP49 -> 3.05 | BY49: =IFERROR(BU49/BX49,0) -> 34203.279 | CA49: RECORD | CB49: =COUNTA(I49:AM49) -> 1 | CC49: =CB49*BS49*0.8 -> 104320 | CD49: =COUNTA(AN49:BO49) -> 0 | CE49: =CD49*BS49*0.8 -> 0 | CF49: =SUM(CC49,CE49)=BU49 -> TRUE
D50: FALA BRASIL | E50: SEG-SEX | F50: 0.35416667 | G50: 09:35 | H50: 30 | AJ50: 1 | AQ50: 1 | AX50: 1 | BP50: =SUM(I50:BO50) -> 3 | BQ50: 69921 | BR50: 0.8 | BS50: =BQ50*(1-BR50) -> 13984.2 | BT50: =BS50*BP50 -> 41952.6 | BU50: =BT50*0.8 -> 33562.08 | BW50: 1.95 | BX50: =BW50*BP50 -> 5.85 | BY50: =IFERROR(BU50/BX50,0) -> 5737.1077 | CA50: RECORD | CB50: =COUNTA(I50:AM50) -> 1 | CC50: =CB50*BS50*0.8 -> 11187.36 | CD50: =COUNTA(AN50:BO50) -> 2 | CE50: =CD50*BS50*0.8 -> 22374.72 | CF50: =SUM(CC50,CE50)=BU50 -> TRUE
...

Sheet TV ABERTA - SPE
B5: CLIENT: SABESP
B6: CAMPAING: ESCASSEZ HIDRICA - CRÍTICO
BW7: PLANNED
B8: MARKET | C8: CHANNEL | D8: PROGRAMM | E8: DAY | F8: START TIME | G8: END TIME | H8: SEC | I8: JANEIRO | BP8: INS. | BQ8: CUSTO TABELA UNITÁRIO (BRUTO) | BR8: DESC. % | BS8: CUSTO NEGOCIADO UNITÁRIO (BRUTO) | BT8: CUSTO TOTAL NEGOCIADO (BRUTO) | BU8: CUSTO TOTAL DESEMBOLSO SABESP | BW8: AUD. AS ABCDE 25+ | BX8: TRP | BY8: CPP | CA8: RESUMO
I9: T | J9: F | K9: S | L9: S | M9: M | N9: T | O9: W | P9: T | Q9: F | R9: S | S9: S | T9: M | U9: T | V9: W | W9: T | X9: F | Y9: S | Z9: S | AA9: M | AB9: T | AC9: W | AD9: T | AE9: F | AF9: S | AG9: S | AH9: M | AI9: T | AJ9: W | AK9: T | AL9: F | AM9: S | AN9: S | AO9: M | AP9: T | AQ9: W | AR9: T | AS9: F | AT9: S | AU9: S | AV9: M | AW9: T | AX9: W | AY9: T | AZ9: F | BA9: S | BB9: S | BC9: M | BD9: T | BE9: W | BF9: T | BG9: F | BH9: S | BI9: S | BJ9: M | BK9: T | BL9: W | BM9: T | BN9: F | BO9: S
I10: 1 | J10: 2 | K10: 3 | L10: 4 | M10: 5 | N10: 6 | O10: 7 | P10: 8 | Q10: 9 | R10: 10 | S10: 11 | T10: 12 | U10: 13 | V10: 14 | W10: 15 | X10: 16 | Y10: 17 | Z10: =Y10+1 -> 18 | AA10: =Z10+1 -> 19 | AB10: =AA10+1 -> 20 | AC10: =AB10+1 -> 21 | AD10: =AC10+1 -> 22 | AE10: =AD10+1 -> 23 | AF10: =AE10+1 -> 24 | AG10: =AF10+1 -> 25 | ... AM10: =AL10+1 -> 31 | AN10: 1 | AO10: 2 | AP10: 3 | AQ10: 4 | AR10: 5 | AS10: 6 | AT10: 7 | AU10: 8 | AV10: 9 | AW10: 10 | AX10: 11 | AY10: 12 | AZ10: 13 | BA10: 14 | BB10: 15 | BC10: 16 | BD10: 17 | BE10: =BD10+1 -> 18 | BF10: =BE10+1 -> 19 | BG10: =BF10+1 -> 20 | BH10: =BG10+1 -> 21 | BI10: =BH10+1 -> 22 | BJ10: =BI10+1 -> 23 | BK10: =BJ10+1 -> 24 | BL10: =BK10+1 -> 25 | ... BO10: =BN10+1 -> 28 | CA10: CHANNEL | CB10: JANEIRO | CD10: FEVEREIRO
CB12: INS | CC12: INVESTIMENTO $ | CD12: INS | CE12: INVESTIMENTO $
B13: SÃO PAULO ESTADO | C13: TV GLOBO | D13: NOVELA II | E13: SEG-SEX | F13: 0.81944444 | G13: 0.85416667 | H13: 30 | AJ13: 1 | BP13: =SUM(I13:BO13) -> 1 | BQ13: 217403 | BR13: 1 | BS13: =BQ13*(1-BR13) -> 0 | BT13: =BS13*BP13 -> 0 | BU13: =BT13*0.8 -> 0 | BW13: 12.33 | BX13: =BW13*BP13 -> 12.33 | BY13: =IFERROR(BU13/BX13,0) -> 0 | CA13: TV GLOBO | CB13: =COUNTA(I13:AM13) -> 1 | CC13: =CB13*BS13*0.8 -> 0 | CD13: =COUNTA(AN13:BO13) -> 0 | CE13: =CD13*BS13*0.8 -> 0 | CF13: =SUM(CC13,CE13)=BU13 -> TRUE
D14: NOVELA III | E14: SEG-SEX | F14: 0.88888889 | G14: 0.93402778 | H14: 30 | AH14: 1 | AK14: 1 | BP14: =SUM(I14:BO14) -> 2 | BQ14: 318624 | BR14: 0 | BS14: =BQ14*(1-BR14) -> 318624 | BT14: =BS14*BP14 -> 637248 | BU14: =BT14*0.8 -> 509798.4 | BW14: 13.35 | BX14: =BW14*BP14 -> 26.7 | BY14: =IFERROR(BU14/BX14,0) -> 19093.573 | CA14: TV GLOBO | CB14: =COUNTA(I14:AM14) -> 2 | CC14: =CB14*BS14*0.8 -> 509798.4 | CD14: =COUNTA(AN14:BO14) -> 0 | CE14: =CD14*BS14*0.8 -> 0 | CF14: =SUM(CC14,CE14)=BU14 -> TRUE
D16: NOVELA II | E16: SEG-SEX | F16: 0.81944444 | G16: 0.85416667 | H16: 30 | AO16: 1 | AR16: 1 | AW16: 1 | BP16: =SUM(I16:BO16) -> 3 | BQ16: 217403 | BR16: 0 | BS16: =BQ16*(1-BR16) -> 217403 | BT16: =BS16*BP16 -> 652209 | BU16: =BT16*0.8 -> 521767.2 | BW16: 12.33 | BX16: =BW16*BP16 -> 36.99 | BY16: =IFERROR(BU16/BX16,0) -> 14105.629 | CA16: TV GLOBO | CB16: =COUNTA(I16:AM16) -> 0 | CC16: =CB16*BS16*0.8 -> 0 | CD16: =COUNTA(AN16:BO16) -> 3 | CE16: =CD16*BS16*0.8 -> 521767.2 | CF16: =SUM(CC16,CE16)=BU16 -> TRUE
D17: NOVELA I | E17: SEG-SEX | F17: 0.76736111 | G17: 0.79861111 | H17: 30 | AS17: 1 | BP17: =SUM(I17:BO17) -> 1 | BQ17: 163381 | BR17: 1 | BS17: =BQ17*(1-BR17) -> 0 | BT17: =BS17*BP17 -> 0 | BU17: =BT17*0.8 -> 0 | BW17: 8.51 | BX17: =BW17*BP17 -> 8.51 | BY17: =IFERROR(BU17/BX17,0) -> 0 | CA17: TV GLOBO | CB17: =COUNTA(I17:AM17) -> 0 | CC17: =CB17*BS17*0.8 -> 0 | CD17: =COUNTA(AN17:BO17) -> 1 | CE17: =CD17*BS17*0.8 -> 0 | CF17: =SUM(CC17,CE17)=BU17 -> TRUE
D19: JORNAL NACIONAL | E19: SEG-SEX | F19: 0.85416667 | G19: 0.88888889 | H19: 30 | AV19: 1 | BP19: =SUM(I19:BO19) -> 1 | BQ19: 316309 | BR19: 0 | BS19: =BQ19*(1-BR19) -> 316309 | BT19: =BS19*BP19 -> 316309 | BU19: =BT19*0.8 -> 253047.2 | BW19: 13.07 | BX19: =BW19*BP19 -> 13.07 | BY19: =IFERROR(BU19/BX19,0) -> 19360.918 | CA19: TV GLOBO | CB19: =COUNTA(I19:AM19) -> 0 | CC19: =CB19*BS19*0.8 -> 0 | CD19: =COUNTA(AN19:BO19) -> 1 | CE19: =CD19*BS19*0.8 -> 253047.2 | CF19: =SUM(CC19,CE19)=BU19 -> TRUE
D20: FANTASTICO | E20: DOM | F20: 0.85416667 | G20: 0.96527778 | H20: 30 | AU20: 1 | BP20: =SUM(I20:BO20) -> 1 | BQ20: 252044 | BR20: 0 | BS20: =BQ20*(1-BR20) -> 252044 | BT20: =BS20*BP20 -> 252044 | BU20: =BT20*0.8 -> 201635.2 | BW20: 8.8 | BX20: =BW20*BP20 -> 8.8 | BY20: =IFERROR(BU20/BX20,0) -> 22913.091 | CA20: TV GLOBO | CB20: =COUNTA(I20:AM20) -> 0 | CC20: =CB20*BS20*0.8 -> 0 | CD20: =COUNTA(AN20:BO20) -> 1 | CE20: =CD20*BS20*0.8 -> 201635.2 | CF20: =SUM(CC20,CE20)=BU20 -> TRUE
D21: JORNAL DA GLOBO | E21: SEG-SEX | F21: 0.041666667 | G21: 0.076388889 | H21: 30 | AO21: 1 | AQ21: 1 | AW21: 1 | AY21: 1 | BP21: =SUM(I21:BO21) -> 4 | BQ21: 43682 | BR21: 1 | BS21: =BQ21*(1-BR21) -> 0 | BT21: =BS21*BP21 -> 0 | BU21: =BT21*0.8 -> 0 | BW21: 3.7 | BX21: =BW21*BP21 -> 14.8 | BY21: =IFERROR(BU21/BX21,0) -> 0 | CA21: TV GLOBO | CB21: =COUNTA(I21:AM21) -> 0 | CC21: =CB21*BS21*0.8 -> 0 | CD21: =COUNTA(AN21:BO21) -> 4 | CE21: =CD21*BS21*0.8 -> 0 | CF21: =SUM(CC21,CE21)=BU21 -> TRUE
D23: NOVELA I | E23: SEG-SEX | F23: 0.76736111 | G23: 0.79861111 | H23: 30 | AH23: 1 | AK23: 1 | BP23: =SUM(I23:BO23) -> 2 | BQ23: 163381 | BR23: 0 | BS23: =BQ23*(1-BR23) -> 163381 | BT23: =BS23*BP23 -> 326762 | BU23: =BT23*0.8 -> 261409.6 | BW23: 8.51 | BX23: =BW23*BP23 -> 17.02 | BY23: =IFERROR(BU23/BX23,0) -> 15358.966 | CA23: TV GLOBO | CB23: =COUNTA(I23:AM23) -> 2 | CC23: =CB23*BS23*0.8 -> 261409.6 | CD23: =COUNTA(AN23:BO23) -> 0 | CE23: =CD23*BS23*0.8 -> 0 | CF23: =SUM(CC23,CE23)=BU23 -> TRUE
D24: NOVELA II | E24: SEG-SEX | F24: 0.81944444 | G24: 0.85416667 | H24: 30 | AI24: 1 | AL24: 1 | BP24: =SUM(I24:BO24) -> 2 | BQ24: 217403 | BR24: 0 | BS24: =BQ24*(1-BR24) -> 217403 | BT24: =BS24*BP24 -> 434806 | BU24: =BT24*0.8 -> 347844.8 | BW24: 12.33 | BX24: =BW24*BP24 -> 24.66 | BY24: =IFERROR(BU24/BX24,0) -> 14105.629 | CA24: TV GLOBO | CB24: =COUNTA(I24:AM24) -> 2 | CC24: =CB24*BS24*0.8 -> 347844.8 | CD24: =COUNTA(AN24:BO24) -> 0 | CE24: =CD24*BS24*0.8 -> 0 | CF24: =SUM(CC24,CE24)=BU24 -> TRUE
D25: NOVELA I SAB | E25: SÁB | F25: 0.77777778 | G25: 0.80902778 | H25: 30 | AM25: 1 | AT25: 1 | BP25: =SUM(I25:BO25) -> 2 | BQ25: 172884 | BR25: 1 | BS25: =BQ25*(1-BR25) -> 0 | BT25: =BS25*BP25 -> 0 | BU25: =BT25*0.8 -> 0 | BW25: 11.08 | BX25: =BW25*BP25 -> 22.16 | BY25: =IFERROR(BU25/BX25,0) -> 0 | CA25: TV GLOBO | CB25: =COUNTA(I25:AM25) -> 1 | CC25: =CB25*BS25*0.8 -> 0 | CD25: =COUNTA(AN25:BO25) -> 1 | CE25: =CD25*BS25*0.8 -> 0 | CF25: =SUM(CC25,CE25)=BU25 -> TRUE
D27: NOVELA III | E27: SEG-SEX | F27: 0.88888889 | G27: 0.93402778 | H27: 60 | AD27: 1 | BP27: =SUM(I27:BO27) -> 1 | BQ27: =318624*2 -> 637248 | BR27: 0 | BS27: =BQ27*(1-BR27) -> 637248 | BT27: =BS27*BP27 -> 637248 | BU27: =BT27*0.8 -> 509798.4 | BW27: 13.35 | BX27: =BW27*BP27 -> 13.35 | BY27: =IFERROR(BU27/BX27,0) -> 38187.146 | CA27: TV GLOBO | CB27: =COUNTA(I27:AM27) -> 1 | CC27: =CB27*BS27*0.8 -> 509798.4 | CD27: =COUNTA(AN27:BO27) -> 0 | CE27: =CD27*BS27*0.8 -> 0 | CF27: =SUM(CC27,CE27)=BU27 -> TRUE
D28: NOVELA III SAB | E28: SÁB | F28: 0.88888889 | G28: 0.93402778 | H28: 60 | AF28: 1 | BP28: =SUM(I28:BO28) -> 1 | BQ28: =257775*2 -> 515550 | BR28: 0 | BS28: =BQ28*(1-BR28) -> 515550 | BT28: =BS28*BP28 -> 515550 | BU28: =BT28*0.8 -> 412440 | BW28: 11.18 | BX28: =BW28*BP28 -> 11.18 | BY28: =IFERROR(BU28/BX28,0) -> 36890.877 | CA28: TV GLOBO | CB28: =COUNTA(I28:AM28) -> 1 | CC28: =CB28*BS28*0.8 -> 412440 | CD28: =COUNTA(AN28:BO28) -> 0 | CE28: =CD28*BS28*0.8 -> 0 | CF28: =SUM(CC28,CE28)=BU28 -> TRUE
D29: NOVELA II | E29: SEG-SEX | F29: 0.81944444 | G29: 0.85416667 | H29: 60 | AE29: 1 | BP29: =SUM(I29:BO29) -> 1 | BQ29: =217403*2 -> 434806 | BR29: 1 | BS29: =BQ29*(1-BR29) -> 0 | BT29: =BS29*BP29 -> 0 | BU29: =BT29*0.8 -> 0 | BW29: 12.33 | BX29: =BW29*BP29 -> 12.33 | BY29: =IFERROR(BU29/BX29,0) -> 0 | CA29: TV GLOBO | CB29: =COUNTA(I29:AM29) -> 1 | CC29: =CB29*BS29*0.8 -> 0 | CD29: =COUNTA(AN29:BO29) -> 0 | CE29: =CD29*BS29*0.8 -> 0 | CF29: =SUM(CC29,CE29)=BU29 -> TRUE
D31: JORNAL NACIONAL - PRIMEIRISSIMA | E31: SEG-SEX | F31: 0.85416667 | G31: 0.88888889 | H31: 60 | AC31: 1 | BP31: =SUM(I31:BO31) -> 1 | BQ31: =(316309*2)*1.2 -> 759141.6 | BR31: 0.1 | BS31: =BQ31*(1-BR31) -> 683227.44 | BT31: =BS31*BP31 -> 683227.44 | BU31: =BT31*0.8 -> 546581.95 | BW31: 13.07 | BX31: =BW31*BP31 -> 13.07 | BY31: =IFERROR(BU31/BX31,0) -> 41819.583 | CA31: TV GLOBO | CB31: =COUNTA(I31:AM31) -> 1 | CC31: =CB31*BS31*0.8 -> 546581.95 | CD31: =COUNTA(AN31:BO31) -> 0 | CE31: =CD31*BS31*0.8 -> 0 | CF31: =SUM(CC31,CE31)=BU31 -> TRUE
CA32: TT | CB32: =SUM(CB13:CB31) -> 12 | CC32: =SUM(CC13:CC31) -> 2587873.2 | CD32: =SUM(CD13:CD31) -> 11 | CE32: =SUM(CE13:CE31) -> 976449.6
C33: BANDEIRANTES | D33: BORA BRASIL | E33: SEG-SEX | F33: 0.375 | G33: 11:00 | H33: 30 | AK33: 1 | AR33: 1 | AY33: 1 | BP33: =SUM(I33:BO33) -> 3 | BQ33: 18884 | BR33: 0.85 | BS33: =BQ33*(1-BR33) -> 2832.6 | BT33: =BS33*BP33 -> 8497.8 | BU33: =BT33*0.8 -> 6798.24 | BW33: 0.24 | BX33: =BW33*BP33 -> 0.72 | BY33: =IFERROR(BU33/BX33,0) -> 9442 | CA33: BANDEIRANTES | CB33: =COUNTA(I33:AM33) -> 1 | CC33: =CB33*BS33*0.8 -> 2266.08 | CD33: =COUNTA(AN33:BO33) -> 2 | CE33: =CD33*BS33*0.8 -> 4532.16 | CF33: =SUM(CC33,CE33)=BU33 -> TRUE
D34: BORA BRASIL | E34: SEG-SEX | F34: 0.375 | G34: 11:00 | H34: 60 | AD34: 1 | BP34: =SUM(I34:BO34) -> 1 | BQ34: 37768 | BR34: 0.85 | BS34: =BQ34*(1-BR34) -> 5665.2 | BT34: =BS34*BP34 -> 5665.2 | BU34: =BT34*0.8 -> 4532.16 | BW34: 0.24 | BX34: =BW34*BP34 -> 0.24 | BY34: =IFERROR(BU34/BX34,0) -> 18884 | CA34: BANDEIRANTES | CB34: =COUNTA(I34:AM34) -> 1 | CC34: =CB34*BS34*0.8 -> 4532.16 | CD34: =COUNTA(AN34:BO34) -> 0 | CE34: =CD34*BS34*0.8 -> 0 | CF34: =SUM(CC34,CE34)=BU34 -> TRUE
D35: BRASIL URGENTE | E35: SEG-SÁB | F35: 0.66666667 | G35: 17:30 | H35: 30 | AL35: 1 | AS35: 1 | AZ35: 1 | BP35: =SUM(I35:BO35) -> 3 | BQ35: 66878 | BR35: 0.85 | BS35: =BQ35*(1-BR35) -> 10031.7 | BT35: =BS35*BP35 -> 30095.1 | BU35: =BT35*0.8 -> 24076.08 | BW35: 1.43 | BX35: =BW35*BP35 -> 4.29 | BY35: =IFERROR(BU35/BX35,0) -> 5612.1399 | CA35: BANDEIRANTES | CB35: =COUNTA(I35:AM35) -> 1 | CC35: =CB35*BS35*0.8 -> 8025.36 | CD35: =COUNTA(AN35:BO35) -> 2 | CE35: =CD35*BS35*0.8 -> 16050.72 | CF35: =SUM(CC35,CE35)=BU35 -> TRUE
D36: BRASIL URGENTE | E36: SEG-SÁB | F36: 0.66666667 | G36: 17:30 | H36: 60 | AE36: 1 | BP36: =SUM(I36:BO36) -> 1 | BQ36: 133756 | BR36: 0.85 | BS36: =BQ36*(1-BR36) -> 20063.4 | BT36: =BS36*BP36 -> 20063.4 | BU36: =BT36*0.8 -> 16050.72 | BW36: 1.43 | BX36: =BW36*BP36 -> 1.43 | BY36: =IFERROR(BU36/BX36,0) -> 11224.28 | CA36: BANDEIRANTES | CB36: =COUNTA(I36:AM36) -> 1 | CC36: =CB36*BS36*0.8 -> 16050.72 | CD36: =COUNTA(AN36:BO36) -> 0 | CE36: =CD36*BS36*0.8 -> 0 | CF36: =SUM(CC36,CE36)=BU36 -> TRUE
D37: CANAL LIVRE | E37: DOM | F37: 0.95833333 | G37: 00:00 | H37: 30 | AU37: 1 | BP37: =SUM(I37:BO37) -> 1 | BQ37: 34546 | BR37: 0.85 | BS37: =BQ37*(1-BR37) -> 5181.9 | BT37: =BS37*BP37 -> 5181.9 | BU37: =BT37*0.8 -> 4145.52 | BW37: 0.21 | BX37: =BW37*BP37 -> 0.21 | BY37: =IFERROR(BU37/BX37,0) -> 19740.571 | CA37: BANDEIRANTES | CB37: =COUNTA(I37:AM37) -> 0 | CC37: =CB37*BS37*0.8 -> 0 | CD37: =COUNTA(AN37:BO37) -> 1 | CE37: =CD37*BS37*0.8 -> 4145.52 | CF37: =SUM(CC37,CE37)=BU37 -> TRUE
D38: CANAL LIVRE | E38: DOM | F38: 0.95833333 | G38: 00:00 | H38: 60 | AG38: 1 | BP38: =SUM(I38:BO38) -> 1 | BQ38: 69092 | BR38: 0.85 | BS38: =BQ38*(1-BR38) -> 10363.8 | BT38: =BS38*BP38 -> 10363.8 | BU38: =BT38*0.8 -> 8291.04 | BW38: 0.21 | BX38: =BW38*BP38 -> 0.21 | BY38: =IFERROR(BU38/BX38,0) -> 39481.143 | CA38: BANDEIRANTES | CB38: =COUNTA(I38:AM38) -> 1 | CC38: =CB38*BS38*0.8 -> 8291.04 | CD38: =COUNTA(AN38:BO38) -> 0 | CE38: =CD38*BS38*0.8 -> 0 | CF38: =SUM(CC38,CE38)=BU38 -> TRUE
D39: JORNAL DA NOITE | E39: SEG-SEX | F39: 0.010416667 | G39: 01:15 | H39: 30 | AJ39: 1 | AQ39: 1 | AX39: 1 | BP39: =SUM(I39:BO39) -> 3 | BQ39: 36271 | BR39: 0.85 | BS39: =BQ39*(1-BR39) -> 5440.65 | BT39: =BS39*BP39 -> 16321.95 | BU39: =BT39*0.8 -> 13057.56 | BW39: 0.34 | BX39: =BW39*BP39 -> 1.02 | BY39: =IFERROR(BU39/BX39,0) -> 12801.529 | CA39: BANDEIRANTES | CB39: =COUNTA(I39:AM39) -> 1 | CC39: =CB39*BS39*0.8 -> 4352.52 | CD39: =COUNTA(AN39:BO39) -> 2 | CE39: =CD39*BS39*0.8 -> 8705.04 | CF39: =SUM(CC39,CE39)=BU39 -> TRUE
D40: JORNAL DA NOITE | E40: SEG-SEX | F40: 0.010416667 | G40: 01:15 | H40: 60 | AD40: 1 | BP40: =SUM(I40:BO40) -> 1 | BQ40: 72542 | BR40: 0.85 | BS40: =BQ40*(1-BR40) -> 10881.3 | BT40: =BS40*BP40 -> 10881.3 | BU40: =BT40*0.8 -> 8705.04 | BW40: 0.34 | BX40: =BW40*BP40 -> 0.34 | BY40: =IFERROR(BU40/BX40,0) -> 25603.059 | CA40: BANDEIRANTES | CB40: =COUNTA(I40:AM40) -> 1 | CC40: =CB40*BS40*0.8 -> 8705.04 | CD40: =COUNTA(AN40:BO40) -> 0 | CE40: =CD40*BS40*0.8 -> 0 | CF40: =SUM(CC40,CE40)=BU40 -> TRUE
D41: NOVELA I | E41: SEG-SEX | F41: 0.29166667 | G41: 08:00 | H41: 30 | BP41: =SUM(I41:BO41) -> 0 | BQ41: 16564 | BR41: 0.85 | BS41: =BQ41*(1-BR41) -> 2484.6 | BT41: =BS41*BP41 -> 0 | BU41: =BT41*0.8 -> 0 | BW41: 0.1 | BX41: =BW41*BP41 -> 0 | BY41: =IFERROR(BU41/BX41,0) -> 0 | CA41: BANDEIRANTES | CB41: =COUNTA(I41:AM41) -> 0 | CC41: =CB41*BS41*0.8 -> 0 | CD41: =COUNTA(AN41:BO41) -> 0 | CE41: =CD41*BS41*0.8 -> 0 | CF41: =SUM(CC41,CE41)=BU41 -> TRUE
D42: NOVELA II | E42: SEG-SEX | F42: 0.85416667 | G42: 21:25 | H42: 30 | AH42: 1 | AO42: 1 | AV42: 1 | BP42: =SUM(I42:BO42) -> 3 | BQ42: 118356 | BR42: 0.85 | BS42: =BQ42*(1-BR42) -> 17753.4 | BT42: =BS42*BP42 -> 53260.2 | BU42: =BT42*0.8 -> 42608.16 | BW42: 0.71 | BX42: =BW42*BP42 -> 2.13 | BY42: =IFERROR(BU42/BX42,0) -> 20003.831 | CA42: BANDEIRANTES | CB42: =COUNTA(I42:AM42) -> 1 | CC42: =CB42*BS42*0.8 -> 14202.72 | CD42: =COUNTA(AN42:BO42) -> 2 | CE42: =CD42*BS42*0.8 -> 28405.44 | CF42: =SUM(CC42,CE42)=BU42 -> TRUE
D43: NOVELA II | E43: SEG-SEX | F43: 0.85416667 | G43: 21:25 | H43: 60 | AE43: 1 | BP43: =SUM(I43:BO43) -> 1 | BQ43: 236712 | BR43: 0.85 | BS43: =BQ43*(1-BR43) -> 35506.8 | BT43: =BS43*BP43 -> 35506.8 | BU43: =BT43*0.8 -> 28405.44 | BW43: 0.71 | BX43: =BW43*BP43 -> 0.71 | BY43: =IFERROR(BU43/BX43,0) -> 40007.662 | CA43: BANDEIRANTES | CB43: =COUNTA(I43:AM43) -> 1 | CC43: =CB43*BS43*0.8 -> 28405.44 | CD43: =COUNTA(AN43:BO43) -> 0 | CE43: =CD43*BS43*0.8 -> 0 | CF43: =SUM(CC43,CE43)=BU43 -> TRUE
CA44: TT | CB44: =SUM(CB33:CB43) -> 9 | CC44: =SUM(CC33:CC43) -> 94831.08 | CD44: =SUM(CD33:CD43) -> 9 | CE44: =SUM(CE33:CE43) -> 61838.88
C45: RECORD | D45: CIDADE ALERTA 2 SAB | E45: SÁB | F45: 0.875 | G45: 22:30 | H45: 30 | AM45: 1 | AT45: 1 | BA45: 1 | BP45: =SUM(I45:BO45) -> 3 | BQ45: 68258 | BR45: 0.8 | BS45: =BQ45*(1-BR45) -> 13651.6 | BT45: =BS45*BP45 -> 40954.8 | BU45: =BT45*0.8 -> 32763.84 | BW45: 2.19 | BX45: =BW45*BP45 -> 6.57 | BY45: =IFERROR(BU45/BX45,0) -> 4986.8858 | CA45: RECORD | CB45: =COUNTA(I45:AM45) -> 1 | CC45: =CB45*BS45*0.8 -> 10921.28 | CD45: =COUNTA(AN45:BO45) -> 2 | CE45: =CD45*BS45*0.8 -> 21842.56 | CF45: =SUM(CC45,CE45)=BU45 -> TRUE
D46: CIDADE ALERTA 2 SAB | E46: SÁB | F46: 0.875 | G46: 22:30 | H46: 60 | AF46: 1 | BP46: =SUM(I46:BO46) -> 1 | BQ46: 136516 | BR46: 0.8 | BS46: =BQ46*(1-BR46) -> 27303.2 | BT46: =BS46*BP46 -> 27303.2 | BU46: =BT46*0.8 -> 21842.56 | BW46: 2.19 | BX46: =BW46*BP46 -> 2.19 | BY46: =IFERROR(BU46/BX46,0) -> 9973.7717 | CA46: RECORD | CB46: =COUNTA(I46:AM46) -> 1 | CC46: =CB46*BS46*0.8 -> 21842.56 | CD46: =COUNTA(AN46:BO46) -> 0 | CE46: =CD46*BS46*0.8 -> 0 | CF46: =SUM(CC46,CE46)=BU46 -> TRUE
D47: DOMINGO ESPETACULAR | E47: DOM | F47: 0.75 | G47: 20:00 | H47: 30 | AN47: 1 | AU47: 1 | BB47: 1 | BP47: =SUM(I47:BO47) -> 3 | BQ47: 393224 | BR47: 0.8 | BS47: =BQ47*(1-BR47) -> 78644.8 | BT47: =BS47*BP47 -> 235934.4 | BU47: =BT47*0.8 -> 188747.52 | BW47: 3.05 | BX47: =BW47*BP47 -> 9.15 | BY47: =IFERROR(BU47/BX47,0) -> 20628.144 | CA47: RECORD | CB47: =COUNTA(I47:AM47) -> 0 | CC47: =CB47*BS47*0.8 -> 0 | CD47: =COUNTA(AN47:BO47) -> 3 | CE47: =CD47*BS47*0.8 -> 188747.52 | CF47: =SUM(CC47,CE47)=BU47 -> TRUE
D48: DOMINGO ESPETACULAR | E48: DOM | F48: 0.75 | G48: 20:00 | H48: 60 | AG48: 1 | BP48: =SUM(I48:BO48) -> 1 | BQ48: 786448 | BR48: 0.8 | BS48: =BQ48*(1-BR48) -> 157289.6 | BT48: =BS48*BP48 -> 157289.6 | BU48: =BT48*0.8 -> 125831.68 | BW48: 3.05 | BX48: =BW48*BP48 -> 3.05 | BY48: =IFERROR(BU48/BX48,0) -> 41256.289 | CA48: RECORD | CB48: =COUNTA(I48:AM48) -> 1 | CC48: =CB48*BS48*0.8 -> 125831.68 | CD48: =COUNTA(AN48:BO48) -> 0 | CE48: =CD48*BS48*0.8 -> 0 | CF48: =SUM(CC48,CE48)=BU48 -> TRUE
D49: FALA BRASIL | E49: SEG-SEX | F49: 0.35416667 | G49: 09:35 | H49: 30 | AJ49: 1 | AQ49: 1 | AX49: 1 | BP49: =SUM(I49:BO49) -> 3 | BQ49: 88342 | BR49: 0.8 | BS49: =BQ49*(1-BR49) -> 17668.4 | BT49: =BS49*BP49 -> 53005.2 | BU49: =BT49*0.8 -> 42404.16 | BW49: 1.95 | BX49: =BW49*BP49 -> 5.85 | BY49: =IFERROR(BU49/BX49,0) -> 7248.5744 | CA49: RECORD | CB49: =COUNTA(I49:AM49) -> 1 | CC49: =CB49*BS49*0.8 -> 14134.72 | CD49: =COUNTA(AN49:BO49) -> 2 | CE49: =CD49*BS49*0.8 -> 28269.44 | CF49: =SUM(CC49,CE49)=BU49 -> TRUE
D50: FALA BRASIL | E50: SEG-SEX | F50: 0.35416667 | G50: 09:35 | H50: 60 | AE50: 1 | BP50: =SUM(I50:BO50) -> 1 | BQ50: 176684 | BR50: 0.8 | BS50: =BQ50*(1-BR50) -> 35336.8 | BT50: =BS50*BP50 -> 35336.8 | BU50: =BT50*0.8 -> 28269.44 | BW50: 1.95 | BX50: =BW50*BP50 -> 1.95 | BY50: =IFERROR(BU50/BX50,0) -> 14497.149 | CA50: RECORD | CB50: =COUNTA(I50:AM50) -> 1 | CC50: =CB50*BS50*0.8 -> 28269.44 | CD50: =COUNTA(AN50:BO50) -> 0 | CE50: =CD50*BS50*0.8 -> 0 | CF50: =SUM(CC50,CE50)=BU50 -> TRUE
...

Sheet TV ABERTA - COLCHÃO REP - SP1
B5: CLIENT: SABESP
B6: CAMPAING: ESCASSEZ HIDRICA - CRÍTICO
BW7: PLANNED
B8: MARKET | C8: CHANNEL | D8: PROGRAMM | E8: DAY | F8: START TIME | G8: END TIME | H8: SEC | I8: JANEIRO | BP8: INS. | BQ8: CUSTO TABELA UNITÁRIO (BRUTO) | BR8: DESC. % | BS8: CUSTO NEGOCIADO UNITÁRIO (BRUTO) | BT8: CUSTO TOTAL NEGOCIADO (BRUTO) | BU8: CUSTO TOTAL DESEMBOLSO SABESP | BW8: AUD. AS ABCDE 25+ | BX8: TRP | BY8: CPP | CA8: RESUMO
I9: T | J9: F | K9: S | L9: S | M9: M | N9: T | O9: W | P9: T | Q9: F | R9: S | S9: S | T9: M | U9: T | V9: W | W9: T | X9: F | Y9: S | Z9: S | AA9: M | AB9: T | AC9: W | AD9: T | AE9: F | AF9: S | AG9: S | AH9: M | AI9: T | AJ9: W | AK9: T | AL9: F | AM9: S | AN9: S | AO9: M | AP9: T | AQ9: W | AR9: T | AS9: F | AT9: S | AU9: S | AV9: M | AW9: T | AX9: W | AY9: T | AZ9: F | BA9: S | BB9: S | BC9: M | BD9: T | BE9: W | BF9: T | BG9: F | BH9: S | BI9: S | BJ9: M | BK9: T | BL9: W | BM9: T | BN9: F | BO9: S
I10: 1 | J10: 2 | K10: 3 | L10: 4 | M10: 5 | N10: 6 | O10: 7 | P10: 8 | Q10: 9 | R10: 10 | S10: 11 | T10: 12 | U10: 13 | V10: 14 | W10: 15 | X10: 16 | Y10: 17 | Z10: =Y10+1 -> 18 | AA10: =Z10+1 -> 19 | AB10: =AA10+1 -> 20 | AC10: =AB10+1 -> 21 | AD10: =AC10+1 -> 22 | AE10: =AD10+1 -> 23 | AF10: =AE10+1 -> 24 | AG10: =AF10+1 -> 25 | ... AM10: =AL10+1 -> 31 | AN10: 1 | AO10: 2 | AP10: 3 | AQ10: 4 | AR10: 5 | AS10: 6 | AT10: 7 | AU10: 8 | AV10: 9 | AW10: 10 | AX10: 11 | AY10: 12 | AZ10: 13 | BA10: 14 | BB10: 15 | BC10: 16 | BD10: 17 | BE10: =BD10+1 -> 18 | BF10: =BE10+1 -> 19 | BG10: =BF10+1 -> 20 | BH10: =BG10+1 -> 21 | BI10: =BH10+1 -> 22 | BJ10: =BI10+1 -> 23 | BK10: =BJ10+1 -> 24 | BL10: =BK10+1 -> 25 | ... BO10: =BN10+1 -> 28 | CA10: CHANNEL | CB10: JANEIRO | CD10: FEVEREIRO
CB12: INS | CC12: INVESTIMENTO $ | CD12: INS | CE12: INVESTIMENTO $
B13: SÃO PAULO CAPITAL | C13: TV GLOBO | D13: PRACA TV 1 EDICAO | E13: SEG-SEX | F13: 0.48958333 | G13: 13:00 | H13: 30 | AH13: 1 | AJ13: 1 | AL13: 1 | AP13: 1 | AR13: 1 | AV13: 1 | AX13: 1 | AZ13: 1 | BP13: =SUM(I13:BO13) -> 8 | BQ13: 27572 | BR13: 0.1 | BS13: =BQ13*(1-BR13) -> 24814.8 | BT13: =BS13*BP13 -> 198518.4 | BU13: =BT13*0.8 -> 158814.72 | BW13: 5.24 | BX13: =BW13*BP13 -> 41.92 | BY13: =IFERROR(BU13/BX13,0) -> 3788.5191 | CA13: TV GLOBO | CB13: =COUNTA(I13:AM13) -> 3 | CC13: =CB13*BS13*0.8 -> 59555.52 | CD13: =COUNTA(AN13:BO13) -> 5 | CE13: =CD13*BS13*0.8 -> 99259.2 | CF13: =SUM(CC13,CE13)=BU13 -> TRUE
E14: SEG-SEX | F14: 0.48958333 | G14: 13:00 | H14: 60 | AE14: 1 | BP14: =SUM(I14:BO14) -> 1 | BQ14: 55144 | BR14: 0.1 | BS14: =BQ14*(1-BR14) -> 49629.6 | BT14: =BS14*BP14 -> 49629.6 | BU14: =BT14*0.8 -> 39703.68 | BW14: 5.24 | BX14: =BW14*BP14 -> 5.24 | BY14: =IFERROR(BU14/BX14,0) -> 7577.0382 | CA14: TV GLOBO | CB14: =COUNTA(I14:AM14) -> 1 | CC14: =CB14*BS14*0.8 -> 39703.68 | CD14: =COUNTA(AN14:BO14) -> 0 | CE14: =CD14*BS14*0.8 -> 0 | CF14: =SUM(CC14,CE14)=BU14 -> TRUE
D15: PRACA TV 2 EDICAO | E15: SEG-SEX | F15: 0.79861111 | G15: 19:40 | H15: 30 | AK15: 1 | AO15: 1 | AS15: 1 | AY15: 1 | BP15: =SUM(I15:BO15) -> 4 | BQ15: 112324 | BR15: 0.1 | BS15: =BQ15*(1-BR15) -> 101091.6 | BT15: =BS15*BP15 -> 404366.4 | BU15: =BT15*0.8 -> 323493.12 | BW15: 12.39 | BX15: =BW15*BP15 -> 49.56 | BY15: =IFERROR(BU15/BX15,0) -> 6527.3027 | CA15: TV GLOBO | CB15: =COUNTA(I15:AM15) -> 1 | CC15: =CB15*BS15*0.8 -> 80873.28 | CD15: =COUNTA(AN15:BO15) -> 3 | CE15: =CD15*BS15*0.8 -> 242619.84 | CF15: =SUM(CC15,CE15)=BU15 -> TRUE
E16: SEG-SEX | F16: 0.79861111 | G16: 19:40 | H16: 60 | AD16: 1 | BP16: =SUM(I16:BO16) -> 1 | BQ16: 224648 | BR16: 0.1 | BS16: =BQ16*(1-BR16) -> 202183.2 | BT16: =BS16*BP16 -> 202183.2 | BU16: =BT16*0.8 -> 161746.56 | BW16: 12.39 | BX16: =BW16*BP16 -> 12.39 | BY16: =IFERROR(BU16/BX16,0) -> 13054.605 | CA16: TV GLOBO | CB16: =COUNTA(I16:AM16) -> 1 | CC16: =CB16*BS16*0.8 -> 161746.56 | CD16: =COUNTA(AN16:BO16) -> 0 | CE16: =CD16*BS16*0.8 -> 0 | CF16: =SUM(CC16,CE16)=BU16 -> TRUE
CA17: TT | CB17: =SUM(CB13:CB16) -> 6 | CC17: =SUM(CC13:CC16) -> 341879.04 | CD17: =SUM(CD13:CD16) -> 8 | CE17: =SUM(CE13:CE16) -> 341879.04
C18: BANDEIRANTES | D18: JORNAL DA BAND | E18: SEG-SEX | F18: 0.80555556 | G18: 20:30 | H18: 30 | AI18: 1 | AK18: 1 | AP18: 1 | AR18: 1 | AW18: 1 | AY18: 1 | BP18: =SUM(I18:BO18) -> 6 | BQ18: 107608 | BR18: 0.85 | BS18: =BQ18*(1-BR18) -> 16141.2 | BT18: =BS18*BP18 -> 96847.2 | BU18: =BT18*0.8 -> 77477.76 | BW18: 1.59 | BX18: =BW18*BP18 -> 9.54 | BY18: =IFERROR(BU18/BX18,0) -> 8121.3585 | CA18: BANDEIRANTES | CB18: =COUNTA(I18:AM18) -> 2 | CC18: =CB18*BS18*0.8 -> 25825.92 | CD18: =COUNTA(AN18:BO18) -> 4 | CE18: =CD18*BS18*0.8 -> 51651.84 | CF18: =SUM(CC18,CE18)=BU18 -> TRUE
E19: SEG-SEX | F19: 0.80555556 | G19: 20:30 | H19: 60 | AD19: 1 | BP19: =SUM(I19:BO19) -> 1 | BQ19: 215216 | BR19: 0.85 | BS19: =BQ19*(1-BR19) -> 32282.4 | BT19: =BS19*BP19 -> 32282.4 | BU19: =BT19*0.8 -> 25825.92 | BW19: 1.59 | BX19: =BW19*BP19 -> 1.59 | BY19: =IFERROR(BU19/BX19,0) -> 16242.717 | CA19: BANDEIRANTES | CB19: =COUNTA(I19:AM19) -> 1 | CC19: =CB19*BS19*0.8 -> 25825.92 | CD19: =COUNTA(AN19:BO19) -> 0 | CE19: =CD19*BS19*0.8 -> 0 | CF19: =SUM(CC19,CE19)=BU19 -> TRUE
CA20: TT | CB20: =SUM(CB18:CB19) -> 3 | CC20: =SUM(CC18:CC19) -> 51651.84 | CD20: =SUM(CD18:CD19) -> 4 | CE20: =SUM(CE18:CE19) -> 51651.84
