Workbook
Name _1: #REF!
Name _10: #REF!
Name _11: #REF!
Name _12: #REF!
Name _13: #REF!
Name _14: #REF!
Name _15: #REF!
Name _16: #REF!
Name _17: #REF!
Name _18: #REF!
Name _19: #REF!
Name _1Excel_BuiltIn__FilterDatabase_10_9_1: NA()
Name _2: #REF!
Name _20: #REF!
Name _21: #REF!
Name _22: #REF!
Name _23: #REF!
Name _24: #REF!
Name _25: #REF!
Name _26: #REF!
Name _27: #REF!
Name _28: #REF!
Name _29: #REF!
Name _3: #REF!
Name _30: #REF!
Name _31: #REF!
Name _4: #REF!
Name _5: #REF!
Name _6: #REF!
Name _7: #REF!
Name _8: #REF!
Name _9: #REF!
Name _M: #REF!
Name _O: #REF!
Name C_: #REF!
Name CACHE: '[4]Conversão-Mercha'!$A$57:$I$112
Name CACHE: '[5]Conversão-Mercha'!$A$57:$I$112
Name CACHESEL1: '[4]Conversão-Mercha'!$M$59:$M$72
Name CACHESEL1: '[5]Conversão-Mercha'!$M$59:$M$72
Name CACHESEL10: '[4]Conversão-Mercha'!$V$59:$V$72
Name CACHESEL10: '[5]Conversão-Mercha'!$V$59:$V$72
Name CACHESEL2: '[4]Conversão-Mercha'!$N$59:$N$72
Name CACHESEL2: '[5]Conversão-Mercha'!$N$59:$N$72
Name CACHESEL3: '[4]Conversão-Mercha'!$O$59:$O$72
Name CACHESEL3: '[5]Conversão-Mercha'!$O$59:$O$72
Name CACHESEL4: '[4]Conversão-Mercha'!$P$59:$P$72
Name CACHESEL4: '[5]Conversão-Mercha'!$P$59:$P$72
Name CACHESEL5: '[4]Conversão-Mercha'!$Q$59:$Q$72
Name CACHESEL5: '[5]Conversão-Mercha'!$Q$59:$Q$72
Name CACHESEL6: '[4]Conversão-Mercha'!$R$59:$R$72
Name CACHESEL6: '[5]Conversão-Mercha'!$R$59:$R$72
Name CACHESEL7: '[4]Conversão-Mercha'!$S$59:$S$72
Name CACHESEL7: '[5]Conversão-Mercha'!$S$59:$S$72
Name CACHESEL8: '[4]Conversão-Mercha'!$T$59:$T$72
Name CACHESEL8: '[5]Conversão-Mercha'!$T$59:$T$72
Name CACHESEL9: '[4]Conversão-Mercha'!$U$59:$U$72
Name CACHESEL9: '[5]Conversão-Mercha'!$U$59:$U$72
Name CALENDARIO: '[4]Conversão-Mercha'!$B$119:$B$132
Name CALENDARIO: '[5]Conversão-Mercha'!$B$119:$B$132
Name CAMP: #REF!

Sheet COVER
B6: Tactical Media Plan | I6: CONFIDENCIAL
B8: CLIENT: | C8: SABESP
B9: CAMPAING | C9: ABC - RIO GRANDE DA SERRA
B10: TARGET: | C10: AS ABCDE 25+
B14: VERSION | C14: UPDATE DATE | D14: UPDATES:
B15: REV01 | C15: 46071 | D15: Inclusão das propostas de alguns veiculos que ainda não tinham enviado
B16: REV02 | C16: 46072 | D16: Inclusão das ultimas propostas que faltavam
B17: REV03 | C17: 46073 | D17: Ajuste no custo do ABCD Jornal.
B18: REV04 | C18: 46073 | D18: Alteração na data de veiculação dos veiculos com exceção do Diario do Grande ABC
B19: REV05 | C19: 46086 | D19: Aletração nas datas de veiculação dos veículos e inclusão do Viva ABC
B20: REV06 | C20: 46087 | D20: Inclusão do Repórter Diário e o Canal ABC
B21: REV07 | C21: 46091 | D21: Ajuste da data de inicio do Canal ABC e secundagem do filme para 60''.
B22: REV08 | C22: 46094 | D22: Ajuste das datas de ínício de Jornal Divulgação Exata, Nova Gente e Viva ABC

Sheet RESUMO DE MEIOS
B5: CLIENT: SABESP
B6: CAMPAING: ABC - RIO GRANDE DA SERRA
B8: RESUMO DE MEIOS
B10: PRAÇA | C10: MEIO | D10: VEÍCULO | F10: FEVEREIRO | G10: MARÇO | H10: ABRIL | I10: MAIO | J10: TOTAL BRUTO | K10: VALOR DESEMBOLSO TT | L10: PART GERAL %
B13: ABC | C13: JORNAL | D13: DIARIO DO GRANDE ABC | F13: =SUM('JORNAL '!BV14:BV15)*1.25 -> 64584 | G13: =SUM('JORNAL '!BX14:BX16)*1.25 -> 0 | H13: 0 | I13: 0 | J13: =SUM(F13:I13) -> 64584 | K13: =J13*0.8 -> 51667.2 | L13: =K13/$K$28 -> 0.23455549
B14: ABC | C14: JORNAL | D14: ABC REPORTER | F14: =SUM('JORNAL '!BV19:BV21)*1.25 -> 32414.08 | G14: =SUM('JORNAL '!BX19:BX21)*1.25 -> 0 | H14: 0 | I14: 0 | J14: =SUM(F14:I14) -> 32414.08 | K14: =J14*0.8 -> 25931.264 | L14: =K14/$K$28 -> 0.11772111
B15: ABC | C15: JORNAL | D15: O GRANDE ABC | F15: =SUM('JORNAL '!BV23,'JORNAL '!BV24,'JORNAL '!BV25) *1.25 -> 6199.998 | G15: =SUM('JORNAL '!BX23:BX25)*1.25 -> 0 | H15: 0 | I15: 0 | J15: =SUM(F15:I15) -> 6199.998 | K15: =J15*0.8 -> 4959.9984 | L15: =K15/$K$28 -> 0.022517087
B16: ABC | C16: JORNAL | D16: ABC EM OFF | F16: =SUM('JORNAL '!BV27:BV28)*1.25 -> 24849.978 | G16: =SUM('JORNAL '!BX27:BX28)*1.25 -> 0 | H16: 0 | I16: 0 | J16: =SUM(F16:I16) -> 24849.978 | K16: =J16*0.8 -> 19879.982 | L16: =K16/$K$28 -> 0.090249885
B17: ABC | C17: JORNAL | D17: DIARIO RP | F17: =SUM('JORNAL '!BV31:BV32)*1.25 -> 0 | G17: =SUM('JORNAL '!BX31:BX32)*1.25 -> 3825 | H17: 0 | I17: 0 | J17: =SUM(F17:I17) -> 3825 | K17: =J17*0.8 -> 3060 | L17: =K17/$K$28 -> 0.013891594
B18: ABC | C18: JORNAL | D18: ABC AGORA | F18: =SUM('JORNAL '!BV34:BV35)*1.25 -> 7650 | G18: =SUM('JORNAL '!BX34:BX35)*1.25 -> 0 | H18: 0 | I18: 0 | J18: =SUM(F18:I18) -> 7650 | K18: =J18*0.8 -> 6120 | L18: =K18/$K$28 -> 0.027783189
B19: ABC | C19: JORNAL | D19: JORNAL IMPRENSA ABC | F19: =SUM('JORNAL '!BV36:BV39)*1.25 -> 34088.306 | G19: =SUM('JORNAL '!BX37:BX39)*1.25 -> 0 | H19: 0 | I19: 0 | J19: =SUM(F19:I19) -> 34088.306 | K19: =J19*0.8 -> 27270.645 | L19: =K19/$K$28 -> 0.12380155
B20: ABC | C20: JORNAL | D20: O ABCD JORNAL | F20: ='JORNAL '!BV42*1.25 -> 18750 | G20: =SUM('JORNAL '!BX42)*1.25 -> 0 | H20: 0 | I20: 0 | J20: =SUM(F20:I20) -> 18750 | K20: =J20*0.8 -> 15000 | L20: =K20/$K$28 -> 0.068096051
B21: ABC | C21: JORNAL | D21: ABC NEWS | F21: ='JORNAL '!BV44*1.25 -> 12600 | G21: =SUM('JORNAL '!BX44)*1.25 -> 0 | H21: 0 | I21: 0 | J21: =SUM(F21:I21) -> 12600 | K21: =J21*0.8 -> 10080 | L21: =K21/$K$28 -> 0.045760546
B22: ABC | C22: JORNAL | D22: FOLHA DE RIBEIRÃO PIRES | F22: ='JORNAL '!BV47*1.25 -> 15000 | G22: =SUM('JORNAL '!BX47)*1.25 -> 0 | H22: 0 | I22: 0 | J22: =SUM(F22:I22) -> 15000 | K22: =J22*0.8 -> 12000 | L22: =K22/$K$28 -> 0.054476841
B23: ABC | C23: JORNAL | D23: NOVA GENTE | F23: ='JORNAL '!BV51*1.25 -> 0 | G23: =SUM('JORNAL '!BX51)*1.25 -> 17500 | H23: 0 | I23: 0 | J23: =SUM(F23:I23) -> 17500 | K23: =J23*0.8 -> 14000 | L23: =K23/$K$28 -> 0.063556315
B24: ABC | C24: JORNAL | D24: JORNAL DIVULGAÇÃO EXATA | F24: ='JORNAL '!BV54*1.25 -> 0 | G24: =SUM('JORNAL '!BX54:BX55)*1.25 -> 27900 | H24: 0 | I24: 0 | J24: =SUM(F24:I24) -> 27900 | K24: =J24*0.8 -> 22320 | L24: =K24/$K$28 -> 0.10132692
B25: ABC | C25: JORNAL | D25: VIVA ABC | F25: {=SUM('JORNAL '!BV57:BV60*1.25)} -> 0 | G25: =SUM('JORNAL '!BX58:BX61)*1.25 -> 3125 | H25: 0 | I25: 0 | J25: =SUM(F25:I25) -> 3125 | K25: =J25*0.8 -> 2500 | L25: =K25/$K$28 -> 0.011349342
B26: ABC | C26: JORNAL | D26: REPÓRTER DIÁRIO | F26: {=SUM('JORNAL '!BV58:BV61*1.25)} -> 0 | G26: =SUM('JORNAL '!BX63)*1.25 -> 6860 | H26: 0 | I26: 0 | J26: =SUM(F26:I26) -> 6860 | K26: =J26*0.8 -> 5488 | L26: =K26/$K$28 -> 0.024914075
B28: TT JORNAL | F28: =SUM(F13:F26) -> 216136.36 | G28: =SUM(G13:G26) -> 59210 | H28: =SUM(H13:H26) -> 0 | I28: =SUM(I13:I26) -> 0 | J28: =SUM(J13:J26) -> 275346.36 | K28: =SUM(K13:K26) -> 220277.09 | L28: =SUM(L13:L26) -> 1 | M28: =K28/K34 -> 0.68058417 | N28: =K28='JORNAL '!BS66 -> TRUE
B30: ABC | C30: TV ABERTA | D30: CANAL ABC | F30: 0 | G30: ='OPEN TV'!DK17*1.25 -> 35468.8 | H30: ='OPEN TV'!DM19*1.25 -> 54581.6 | I30: ='OPEN TV'!DO19*1.25 -> 39176.8 | J30: =SUM(F30:I30) -> 129227.2 | K30: =J30*0.8 -> 103381.76 | L30: =K30/$K$32 -> 1
B32: TT JORNAL | F32: =SUM(F30:F30) -> 0 | G32: =SUM(G30:G30) -> 35468.8 | H32: =SUM(H30:H30) -> 54581.6 | I32: =SUM(I30:I30) -> 39176.8 | J32: =SUM(J30:J30) -> 129227.2 | K32: =SUM(K30:K30) -> 103381.76 | L32: =SUM(L30:L30) -> 1 | M32: =K32/K34 -> 0.31941583 | N32: =K32='OPEN TV'!DO21 -> TRUE
B34: TOTAL GERAL | F34: =SUM(,F28,F32) -> 216136.36 | G34: =SUM(,G28,G32) -> 94678.8 | H34: =SUM(,H28,H32) -> 54581.6 | I34: =SUM(,I28,I32) -> 39176.8 | J34: =SUM(,J28,J32) -> 404573.56 | K34: =SUM(,K28,K32) -> 323658.85 | M34: =SUM(M10:M32) -> 1
F35: =F34/J34 -> 0.53423254 | G35: =G34/J34 -> 0.23402122 | H35: =H34/J34 -> 0.13491144 | I35: =I34/J34 -> 0.0968348 | K35: =SUM('JORNAL '!BS66,'OPEN TV'!DA19)=K34 -> TRUE

Sheet JORNAL 
B5: CLIENT: SABESP
B6: CAMPAING: ABC - RIO GRANDE DA SERRA
B9: MARKET | C9: CHANNEL | D9: FORMATO | E9: INFORMAÇÕES | F9: CIRCULAÇÃO / IMPRESSÕES | G9: FEVEREIRO | U9: FEVREIRO | AI9: MARÇO | BN9: INS. | BO9: CUSTO TABELA UNITÁRIO (BRUTO) | BP9: DESC. % | BQ9: CUSTO NEGOCIADO UNITÁRIO (BRUTO) | BR9: CUSTO TOTAL NEGOCIADO (BRUTO) | BS9: CUSTO TOTAL DESEMBOLSO
G10: S | H10: M | I10: T | J10: W | K10: T | L10: F | M10: S | N10: S | O10: M | P10: T | Q10: W | R10: T | S10: F | T10: S | U10: S | V10: M | W10: T | X10: W | Y10: T | Z10: F | AA10: S | AB10: S | AC10: M | AD10: T | AE10: W | AF10: T | AG10: F | AH10: S | AI10: S | AJ10: M | AK10: T | AL10: W | AM10: T | AN10: F | AO10: S | AP10: S | AQ10: M | AR10: T | AS10: W | AT10: T | AU10: F | AV10: S | AW10: S | AX10: M | AY10: T | AZ10: W | BA10: T | BB10: F | BC10: S | BD10: S | BE10: M | BF10: T | BG10: W | BH10: T | BI10: F | BJ10: S | BK10: S | BL10: M | BM10: T | BU10: FEVEREIRO | BW10: MARÇO
G11: 1 | H11: 2 | I11: 3 | J11: 4 | K11: 5 | L11: 6 | M11: 7 | N11: 8 | O11: 9 | P11: 10 | Q11: 11 | R11: 12 | S11: 13 | T11: 14 | U11: 15 | V11: 16 | W11: 17 | X11: 18 | Y11: 19 | Z11: 20 | AA11: 21 | AB11: 22 | AC11: 23 | AD11: 24 | AE11: 25 | AF11: 26 | AG11: 27 | AH11: 28 | AI11: 1 | AJ11: =AI11+1 -> 2 | AK11: =AJ11+1 -> 3 | AL11: =AK11+1 -> 4 | AM11: =AL11+1 -> 5 | AN11: =AM11+1 -> 6 | AO11: =AN11+1 -> 7 | AP11: =AO11+1 -> 8 | AQ11: =AP11+1 -> 9 | ... BM11: =BL11+1 -> 31
BU12: INS. | BV12: INV. LIQUIDO | BW12: INS. | BX12: INV. LIQUIDO
B14: ABC | C14: DIÁRIO DO GRANDE ABC | D14: PÁGINA SIMPLES ANÚNCIO (DIAS ÚTEIS) - IMPRESSO | E14: DIÁRIO | F14: 10000 | AE14: 1 | BN14: =SUM(G14:BM14) -> 1 | BO14: 71760 | BP14: 0.6 | BQ14: =BO14*(1-BP14) -> 28704 | BR14: =BQ14*BN14 -> 28704 | BS14: =BR14*0.8 -> 22963.2 | BU14: =SUM(G14:AH14) -> 1 | BV14: =BU14*$BQ14*0.8 -> 22963.2 | BW14: =SUM(AI14:BM14) -> 0 | BX14: =BW14*$BQ14*0.8 -> 0
D15: PÁGINA DE PUBLI EDITORIAL (DOMINGO) - IMPRESSO | F15: 10000 | AB15: 1 | BN15: =SUM(G15:BM15) -> 1 | BO15: 143520 | BP15: 0.75 | BQ15: =BO15*(1-BP15) -> 35880 | BR15: =BQ15*BN15 -> 35880 | BS15: =BR15*0.8 -> 28704 | BU15: =SUM(G15:AH15) -> 1 | BV15: =BU15*$BQ15*0.8 -> 28704 | BW15: =SUM(AI15:BM15) -> 0 | BX15: =BW15*$BQ15*0.8 -> 0
D16: PÁGINA DE PUBLI EDITORIAL (DOMINGO) - DIGITAL | E16: PRODUÇÃO PELA AGENCIA ATÉ 1000 CARACTERES + 1 IMAGEM + TÍTULO | F16: - | AB16: 1 | BN16: =SUM(G16:BM16) -> 1 | BO16: 143520 | BP16: 1 | BQ16: =BO16*(1-BP16) -> 0 | BR16: =BQ16*BN16 -> 0 | BS16: =BR16*0.8 -> 0
D17: DIGITAL (ARROBA BANNER E SUPER BANNER) | F17: 80000 | AE17: 80000 | BN17: =SUM(G17:BM17) -> 80000 | BO17: =(87*BN17/1000)+(105*BN17/1000) -> 15360 | BP17: 1 | BQ17: 0 | BR17: =BQ17*BN17 -> 0 | BS17: =BR17*0.8 -> 0 | BU17: =SUM(G17:AH17) -> 80000 | BV17: =BU17*$BQ17*0.8 -> 0 | BW17: =SUM(AI17:BM17) -> 0 | BX17: =BW17*$BQ17*0.8 -> 0
C19: ABC REPORTER | D19: PÁGINA SIMPLES - 24,6X40CM - IMPRESSO | E19: TERÇA A SÁBADO | F19: 5000 | AG19: 1 | BN19: =SUM(G19:BM19) -> 1 | BO19: 188200 | BP19: 0.91388395 | BQ19: =BO19*(1-BP19) -> 16207.04 | BR19: =BQ19*BN19 -> 16207.04 | BS19: =BR19*0.8 -> 12965.632 | BU19: =SUM(G19:AH19) -> 1 | BV19: =BU19*$BQ19*0.8 -> 12965.632 | BW19: =SUM(AI19:BM19) -> 0 | BX19: =BW19*$BQ19*0.8 -> 0
D20: PUBLIEDITORIAL - 24,6X40CM - IMPRESSO | F20: 5000 | AE20: 1 | BN20: =SUM(G20:BM20) -> 1 | BO20: 188200 | BP20: 0.91388395 | BQ20: =BO20*(1-BP20) -> 16207.04 | BR20: =BQ20*BN20 -> 16207.04 | BS20: =BR20*0.8 -> 12965.632 | BU20: =SUM(G20:AH20) -> 1 | BV20: =BU20*$BQ20*0.8 -> 12965.632 | BW20: =SUM(AI20:BM20) -> 0 | BX20: =BW20*$BQ20*0.8 -> 0
D21: DIGITAL - BILLBOARD (1170x269) | AE21: 1 | BN21: =SUM(G21:BM21) -> 1 | BO21: 0 | BP21: 1 | BQ21: =BO21*(1-BP21) -> 0 | BR21: =BQ21*BN21 -> 0 | BS21: =BR21*0.8 -> 0 | BU21: =SUM(G21:AH21) -> 1 | BV21: =BU21*$BQ21*0.8 -> 0 | BW21: =SUM(AI21:BM21) -> 0 | BX21: =BW21*$BQ21*0.8 -> 0
C23: O GRANDE ABC | D23: BANNER CABEÇALHO - 730x175CM | E23: DIÁRIO | AE23: 1 | BN23: =SUM(G23:BM23) -> 1 | BO23: 2333.33 | BP23: 0.4 | BQ23: =BO23*(1-BP23) -> 1399.998 | BR23: =BQ23*BN23 -> 1399.998 | BS23: =BR23*0.8 -> 1119.9984 | BU23: =SUM(G23:AH23) -> 1 | BV23: =BU23*$BQ23*0.8 -> 1119.9984 | BW23: =SUM(AI23:BM23) -> 0 | BX23: =BW23*$BQ23*0.8 -> 0
D24: FEED - FACEBOOK E INSTAGRAM | AE24: 1 | BN24: =SUM(G24:BM24) -> 1 | BO24: 2000 | BP24: 0.4 | BQ24: =BO24*(1-BP24) -> 1200 | BR24: =BQ24*BN24 -> 1200 | BS24: =BR24*0.8 -> 960 | BU24: =SUM(G24:AH24) -> 1 | BV24: =BU24*$BQ24*0.8 -> 960 | BW24: =SUM(AI24:BM24) -> 0 | BX24: =BW24*$BQ24*0.8 -> 0
D25: BRANDED CONTENT - DIGITAL | E25: PRODUÇÃO PELA AGENCIA ATÉ 1000 CARACTERES + 1 IMAGEM + TÍTULO | AE25: 1 | BN25: =SUM(G25:BM25) -> 1 | BO25: 6000 | BP25: 0.4 | BQ25: =BO25*(1-BP25) -> 3600 | BR25: =BQ25*BN25 -> 3600 | BS25: =BR25*0.8 -> 2880 | BU25: =SUM(G25:AH25) -> 1 | BV25: =BU25*$BQ25*0.8 -> 2880 | BW25: =SUM(AI25:BM25) -> 0 | BX25: =BW25*$BQ25*0.8 -> 0
C27: ABC EM OFF | D27: BANNER TOPO – IAB | E27: DIÁRIO | AE27: 117187 | BN27: =SUM(G27:BM27) -> 117187 | BO27: 64 | BP27: 0.3 | BQ27: =BO27*(1-BP27) -> 44.8 | BR27: =BQ27*BN27/1000 -> 5249.9776 | BS27: =BR27*0.8 -> 4199.9821 | BU27: =SUM(G27:AH27) -> 117187 | BV27: =BU27*$BQ27/1000*0.8 -> 4199.9821 | BW27: =SUM(AI27:BM27) -> 0 | BX27: =BW27*$BQ27/1000*0.8 -> 0
D28: PUBLIEDITORIAL - DIGITAL | E28: PRODUÇÃO PELA AGENCIA ATÉ 1000 CARACTERES + 1 IMAGEM + TÍTULO | AE28: 1 | BN28: =SUM(G28:BM28) -> 1 | BO28: 28000 | BP28: 0.3 | BQ28: =BO28*(1-BP28) -> 19600 | BR28: =BQ28*BN28 -> 19600 | BS28: =BR28*0.8 -> 15680 | BU28: =SUM(G28:AH28) -> 1 | BV28: =BU28*$BQ28*0.8 -> 15680 | BW28: =SUM(AI28:BM28) -> 0 | BX28: =BW28*$BQ28*0.8 -> 0
D29: VÍDEOS PARA REDES SOCIAIS | AE29: 1 | BN29: =SUM(G29:BM29) -> 1
C31: DIÁRIO RP | D31: BRANDED CONTENT - DIGITAL | E31: DIÁRIO | AK31: 1 | BN31: =SUM(G31:BM31) -> 1 | BO31: 3000 | BP31: 0.15 | BQ31: =BO31*(1-BP31) -> 2550 | BR31: =BQ31*BN31 -> 2550 | BS31: =BR31*0.8 -> 2040 | BU31: =SUM(G31:AH31) -> 0 | BV31: =BU31*$BQ31*0.8 -> 0 | BW31: =SUM(AI31:BM31) -> 1 | BX31: =BW31*$BQ31*0.8 -> 2040
D32: VÍDEOS INSTAGRAM E FACEBOOK | E32: PRODUÇÃO PELA AGENCIA ATÉ 1000 CARACTERES + 1 IMAGEM + TÍTULO | AK32: 1 | BN32: =SUM(G32:BM32) -> 1 | BO32: 1500 | BP32: 0.15 | BQ32: =BO32*(1-BP32) -> 1275 | BR32: =BQ32*BN32 -> 1275 | BS32: =BR32*0.8 -> 1020 | BU32: =SUM(G32:AH32) -> 0 | BV32: =BU32*$BQ32*0.8 -> 0 | BW32: =SUM(AI32:BM32) -> 1 | BX32: =BW32*$BQ32*0.8 -> 1020
C34: ABC AGORA | D34: BANNER TOPO OUTDOOR - DIGITAL | E34: DIÁRIO | AE34: 1 | BN34: =SUM(G34:BM34) -> 1 | BO34: 7000 | BP34: 0.15 | BQ34: =BO34*(1-BP34) -> 5950 | BR34: =BQ34*BN34 -> 5950 | BS34: =BR34*0.8 -> 4760 | BU34: =SUM(G34:AH34) -> 1 | BV34: =BU34*$BQ34*0.8 -> 4760 | BW34: =SUM(AI34:BM34) -> 0 | BX34: =BW34*$BQ34*0.8 -> 0
D35: BRANDED CONTENT - DIGITAL | E35: PRODUÇÃO PELA AGENCIA ATÉ 600 CARACTERES + 1 IMAGEM + TÍTULO | AE35: 1 | BN35: =SUM(G35:BM35) -> 1 | BO35: 2000 | BP35: 0.15 | BQ35: =BO35*(1-BP35) -> 1700 | BR35: =BQ35*BN35 -> 1700 | BS35: =BR35*0.8 -> 1360 | BU35: =SUM(G35:AH35) -> 1 | BV35: =BU35*$BQ35*0.8 -> 1360 | BW35: =SUM(AI35:BM35) -> 0 | BX35: =BW35*$BQ35*0.8 -> 0
C37: JORNAL IMPRENSA ABC | D37: PÁGINA SIMPLES (INDETERMINADA) - IMPRESSO | E37: SÁBADO | AH37: 1 | BN37: =SUM(G37:BM37) -> 1 | BO37: 123586.32 | BP37: 0.88 | BQ37: =BO37*(1-BP37) -> 14830.358 | BR37: =BQ37*BN37 -> 14830.358 | BS37: =BR37*0.8 -> 11864.287 | BU37: =SUM(G37:AH37) -> 1 | BV37: =BU37*$BQ37*0.8 -> 11864.287 | BW37: =SUM(AI37:BM37) -> 0 | BX37: =BW37*$BQ37*0.8 -> 0
D38: BANNER QUADRO HOME - DIGITAL | E38: BRANDED CONTENT - PRODUÇÃO DO BRIEFING EM 2 DIAS ÚTEIS | AE38: 1 | BN38: =SUM(G38:BM38) -> 1 | BO38: 6000 | BP38: 0.88 | BQ38: =BO38*(1-BP38) -> 720 | BR38: =BQ38*BN38 -> 720 | BS38: =BR38*0.8 -> 576 | BU38: =SUM(G38:AH38) -> 1 | BV38: =BU38*$BQ38*0.8 -> 576 | BW38: =SUM(AI38:BM38) -> 0 | BX38: =BW38*$BQ38*0.8 -> 0
D39: BRANDED CONTENT - DIGITAL - 1 PÁGINA | AE39: 1 | BN39: =SUM(G39:BM39) -> 1 | BO39: 123586.32 | BP39: 0.85 | BQ39: =BO39*(1-BP39) -> 18537.948 | BR39: =BQ39*BN39 -> 18537.948 | BS39: =BR39*0.8 -> 14830.358 | BU39: =SUM(G39:AH39) -> 1 | BV39: =BU39*$BQ39*0.8 -> 14830.358 | BW39: =SUM(AI39:BM39) -> 0 | BX39: =BW39*$BQ39*0.8 -> 0
D40: INSTAGRAM (VÍDEO OU ESTÁTICO) | AE40: 1 | BN40: =SUM(G40:BM40) -> 1 | BO40: 0
C42: O ABCD JORNAL | D42: ROS DESKTOP - SITE - SUPER BANNER, BANNER SINGLE, SUPER BANNER 1 | E42: DIÁRIO | AE42: 10000 | BN42: =SUM(G42:BM42) -> 10000 | BO42: =BR42 -> 18750 | BQ42: =BO42*(1-BP42) -> 18750 | BR42: 18750 | BS42: =BR42*0.8 -> 15000 | BU42: =SUM(G42:AH42) -> 10000 | BV42: =BQ42*0.8 -> 15000 | BW42: =SUM(AI42:BM42) -> 0 | BX42: 0
C44: ABC NEWS | D44: HOME SUPER BANNER TOPO - 970X250 (FIXO) | E44: DIÁRIO | AG44: 1 | BN44: =SUM(G44:BM44) -> 1 | BO44: 15000 | BP44: 0.16 | BQ44: =BO44*(1-BP44) -> 12600 | BR44: =BQ44 -> 12600 | BS44: =BR44*0.8 -> 10080 | BU44: =SUM(G44:AH44) -> 1 | BV44: =BU44*BQ44*0.8 -> 10080 | BW44: =SUM(AI44:BM44) -> 0 | BX44: =BW44*BQ44*0.8 -> 0
C46: FOLHA DE RIBEIRÃO PIRES | D46: RETÂNGULO FIXO NO TOPO DA PÁGINA - 960x164px | E46: DIÁRIO | AE46: 1 | BN46: =SUM(G46:BM46) -> 1 | BR46: 15000 | BS46: =BR46*0.8 -> 12000
D47: BANNERS - 1024x1024px | AE47: 1 | BO47: 15000 | BQ47: =BO47*(1-BP47) -> 15000 | BU47: =SUM(G47:AH47) -> 1 | BV47: =BS46 -> 12000 | BW47: =SUM(AI47:BM47) -> 0 | BX47: =BU46 -> 0
D48: PUBLIEDITORIAL NA HOME (ENTREGA AGÊNCIA) - DIGITAL | E48: PRODUÇÃO PELA AGENCIA ATÉ 600 CARACTERES + 1 IMAGEM + TÍTULO | AE48: 1
C50: NOVA GENTE | D50: RÁDIO WEB NOVA GENTE - SPOT 30'' | E50: DIÁRIO | AU50: 8 | AV50: 8 | AW50: 8 | AX50: 8 | AY50: 8 | AZ50: 8 | BA50: 8 | BN50: =SUM(G50:BM50) -> 56 | BO50: 17500 | BR50: 17500 | BS50: =BR50*0.8 -> 14000
D51: 1 MENÇÃO ESPECIAL NO PROGRAMA MARCÃO DA GENTE NA RÁDIO - TEXTO 30'' | AR51: 1 | BQ51: =BO50 -> 17500 | BU51: =SUM(G51:AH51) -> 0 | BV51: =BU51*BQ51*0.8 -> 0 | BW51: =SUM(AI51:BM51) -> 1 | BX51: =BW51*BQ51*0.8 -> 14000
D52: ENTREGA NO FACEBOOK - POST (60K IMPRESSÕES) | AK52: 1
C54: JORNAL DIVULGAÇÃO EXATA | D54: SUPERBANNER CONTEÚDO PRINCIPAL - 945x150px | E54: DIÁRIO | AT54: 1 | BN54: =SUM(G54:BM54) -> 1 | BO54: 27900 | BQ54: =BO54*(1-BP54) -> 27900 | BR54: 27900 | BS54: =BR54*0.8 -> 22320 | BU54: =SUM(U54:AH54) -> 0 | BV54: =BU54*BQ54*0.8 -> 0 | BW54: =SUM(AI54:BM54) -> 1 | BX54: =BW54*BQ54*0.8 -> 22320
D55: BANNER ENTRE NOTICIAS - 300x250px | AT55: 1 | BN55: =SUM(G55:BM55) -> 1
C58: VIVA ABC | D58: 6 STORIES COM LINK CLICÁVEL | AY58: 1 | BN58: =SUM(G58:BM58) -> 1 | BO58: =BQ58 -> 3125 | BQ58: =BR58 -> 3125 | BR58: =BS58*1.25 -> 3125 | BS58: 2500 | BU58: =SUM(U58:AH58) -> 0 | BV58: =BU58*BQ58*0.8 -> 0 | BW58: =SUM(AI58:BM58) -> 1 | BX58: =BW58*BQ58*0.8 -> 2500
D59: 7 DIAS COM LINK NA BIO DO VIVA ABC | AY59: 1
D60: 30 DIAS DESTAQUE PARCERIAS | AY60: 1
...

Sheet OPEN TV
B5: CLIENT: SABESP
B6: CAMPAING: ABC RIO GRANDE DA SERRA
DC9: PLANNED
B10: MARKET | C10: CHANNEL | D10: PROGRAMM | E10: START TIME | F10: END TIME | G10: SEC | H10: MARÇO | AM10: ABRIL | BQ10: MAIO | CV10: INS. | CW10: CUSTO TABELA UNITÁRIO (BRUTO) | CX10: DESC. % | CY10: CUSTO NEGOCIADO UNITÁRIO (BRUTO) | CZ10: CUSTO TOTAL NEGOCIADO (BRUTO) | DA10: CUSTO TOTAL DESEMBOLSO SABESP | DC10: AUD. AS ABCDE 25+ | DD10: TRP | DE10: CPP | DG10: RESUMO
H11: S | I11: M | J11: T | K11: W | L11: T | M11: F | N11: S | O11: S | P11: M | Q11: T | R11: W | S11: T | T11: F | U11: S | V11: S | W11: M | X11: T | Y11: W | Z11: T | AA11: F | AB11: S | AC11: S | AD11: M | AE11: T | AF11: W | AG11: T | AH11: F | AI11: S | AJ11: S | AK11: M | AL11: T | AM11: W | AN11: T | AO11: F | AP11: S | AQ11: S | AR11: M | AS11: T | AT11: W | AU11: T | AV11: F | AW11: S | AX11: S | AY11: M | AZ11: T | BA11: W | BB11: T | BC11: F | BD11: S | BE11: S | BF11: M | BG11: T | BH11: W | BI11: T | BJ11: F | BK11: S | BL11: S | BM11: M | BN11: T | BO11: W | BP11: T | BQ11: F | BR11: S | BS11: S | BT11: M | BU11: T | BV11: W | BW11: T | BX11: F | BY11: S | BZ11: S | CA11: M | CB11: T | CC11: W | CD11: T | CE11: F | CF11: S | CG11: S | CH11: M | CI11: T | CJ11: W | CK11: T | CL11: F | CM11: S | CN11: S | CO11: M | CP11: T | CQ11: W | CR11: T | CS11: F | CT11: S | CU11: S
H12: 1 | I12: 2 | J12: 3 | K12: 4 | L12: 5 | M12: 6 | N12: 7 | O12: 8 | P12: 9 | Q12: 10 | R12: 11 | S12: 12 | T12: 13 | U12: 14 | V12: 15 | W12: 16 | X12: 17 | Y12: 18 | Z12: 19 | AA12: 20 | AB12: 21 | AC12: 22 | AD12: 23 | AE12: 24 | AF12: 25 | AG12: 26 | AH12: 27 | AI12: 28 | AJ12: 29 | AK12: 30 | AL12: 31 | AM12: 1 | AN12: 2 | AO12: 3 | AP12: 4 | AQ12: 5 | AR12: 6 | AS12: 7 | AT12: 8 | AU12: 9 | AV12: 10 | AW12: 11 | AX12: 12 | AY12: 13 | AZ12: 14 | BA12: 15 | BB12: 16 | BC12: 17 | BD12: 18 | BE12: 19 | BF12: 20 | BG12: 21 | BH12: 22 | BI12: 23 | BJ12: 24 | BK12: 25 | BL12: 26 | BM12: 27 | BN12: 28 | BO12: 29 | BP12: 30 | BQ12: 1 | BR12: 2 | BS12: 3 | BT12: 4 | BU12: 5 | BV12: 6 | BW12: 7 | BX12: 8 | BY12: 9 | BZ12: 10 | CA12: 11 | CB12: 12 | CC12: 13 | CD12: 14 | CE12: 15 | CF12: 16 | CG12: 17 | CH12: 18 | CI12: 19 | CJ12: 20 | CK12: 21 | CL12: 22 | CM12: 23 | CN12: 24 | CO12: 25 | CP12: 26 | CQ12: 27 | CR12: 28 | CS12: 29 | CT12: 30 | CU12: 31 | DG12: CHANNEL | DH12: DEZEMBRO | DJ12: MARÇO | DL12: ABRIL | DN12: MAIO
G13: PEÇA
DH14: INS | DI14: INVESTIMENTO $ | DJ14: INS | DK14: INVESTIMENTO $ | DL14: INS | DM14: INVESTIMENTO $ | DN14: INS | DO14: INVESTIMENTO $
B15: ABC | C15: CANAL ABC | D15: FAIXA 1 | E15: 0.75 | F15: 0 | G15: 60 | V15: 2 | W15: 2 | X15: 2 | Y15: 2 | Z15: 2 | AA15: 2 | AB15: 2 | AC15: 2 | AD15: 2 | AE15: 2 | AF15: 2 | AG15: 2 | AH15: 2 | AI15: 2 | AJ15: 2 | AK15: 2 | AL15: 2 | AM15: 2 | AN15: 2 | AO15: 2 | AP15: 2 | AQ15: 2 | AR15: 2 | AS15: 2 | AT15: 2 | AU15: 2 | AV15: 2 | AW15: 2 | AX15: 2 | AY15: 2 | AZ15: 2 | BA15: 2 | BB15: 2 | BC15: 2 | BD15: 2 | BE15: 2 | BF15: 2 | BG15: 2 | BH15: 2 | BI15: 2 | BJ15: 2 | BK15: 2 | BL15: 2 | BM15: 2 | BN15: 2 | BO15: 2 | BP15: 2 | BQ15: 2 | BR15: 2 | BS15: 2 | BT15: 2 | BU15: 2 | BV15: 2 | BW15: 2 | BX15: 2 | BY15: 2 | BZ15: 2 | CA15: 2 | CB15: 1 | CC15: 1 | CD15: 1 | CE15: 1 | CF15: 1 | CG15: 1 | CH15: 1 | CI15: 1 | CJ15: 1 | CK15: 1 | CL15: 1 | CM15: 1 | CN15: 1 | CO15: 1 | CP15: 1 | CQ15: 1 | CR15: 1 | CS15: 1 | CT15: 1 | CU15: 1 | CV15: =SUM(H15:CU15) -> 136 | CW15: =777*2 -> 1554 | CX15: 0.6 | CY15: =CW15*(1-CX15) -> 621.6 | CZ15: =CY15*CV15 -> 84537.6 | DA15: =CZ15*0.8 -> 67630.08 | DD15: =DC15*CV15 -> 0 | DE15: =IFERROR(DA15/DD15,0) -> 0 | DG15: CANAL ABC | DH15: =COUNTA(H15:AL15) -> 17 | DI15: =DH15*CY15*0.8 -> 8453.76 | DJ15: =SUM(H15:AL15) -> 34 | DK15: =DJ15*CY15*0.8 -> 16907.52 | DL15: =SUM(AM15:BP15) -> 60 | DM15: =DL15*CY15*0.8 -> 29836.8 | DN15: =SUM(BQ15:CU15) -> 42 | DO15: =DN15*CY15*0.8 -> 20885.76
D16: FAIXA 2 | E16: 0.5 | F16: 0.75 | G16: 60 | V16: 2 | W16: 2 | X16: 2 | Y16: 2 | Z16: 2 | AA16: 2 | AB16: 2 | AC16: 2 | AD16: 2 | AE16: 2 | AF16: 2 | AG16: 2 | AH16: 2 | AI16: 2 | AJ16: 2 | AK16: 2 | AL16: 2 | AM16: 2 | AN16: 2 | AO16: 2 | AP16: 2 | AQ16: 2 | AR16: 2 | AS16: 2 | AT16: 2 | AU16: 2 | AV16: 2 | AW16: 2 | AX16: 1 | AY16: 1 | AZ16: 1 | BA16: 1 | BB16: 1 | BC16: 1 | BD16: 1 | BE16: 1 | BF16: 1 | BG16: 1 | BH16: 1 | BI16: 1 | BJ16: 1 | BK16: 1 | BL16: 1 | BM16: 1 | BN16: 1 | BO16: 1 | BP16: 1 | BQ16: 1 | BR16: 1 | BS16: 1 | BT16: 1 | BU16: 1 | BV16: 1 | BW16: 1 | BX16: 1 | BY16: 1 | BZ16: 1 | CA16: 1 | CB16: 1 | CC16: 1 | CD16: 1 | CE16: 1 | CF16: 1 | CG16: 1 | CH16: 1 | CI16: 1 | CJ16: 1 | CK16: 1 | CL16: 1 | CM16: 1 | CN16: 1 | CO16: 1 | CP16: 1 | CQ16: 1 | CR16: 1 | CS16: 1 | CT16: 1 | CU16: 1 | CV16: =SUM(H16:CU16) -> 106 | CW16: =527*2 -> 1054 | CX16: 0.6 | CY16: =CW16*(1-CX16) -> 421.6 | CZ16: =CY16*CV16 -> 44689.6 | DA16: =CZ16*0.8 -> 35751.68 | DD16: =DC16*CV16 -> 0 | DE16: =IFERROR(DA16/DD16,0) -> 0 | DG16: CANAL ABC | DH16: =COUNTA(H16:AL16) -> 17 | DI16: =DH16*CY16*0.8 -> 5733.76 | DJ16: =SUM(H16:AL16) -> 34 | DK16: =DJ16*CY16*0.8 -> 11467.52 | DL16: =SUM(AM16:BP16) -> 41 | DM16: =DL16*CY16*0.8 -> 13828.48 | DN16: =SUM(BQ16:CU16) -> 31 | DO16: =DN16*CY16*0.8 -> 10455.68
DG17: TT CANAL ABC | DH17: =SUM(#REF!) -> #REF! | DI17: =SUM(#REF!) -> #REF! | DJ17: =SUM(DJ15:DJ16) -> 68 | DK17: =SUM(DK15:DK16) -> 28375.04 | DL17: =SUM(DL15:DL16) -> 101 | DM17: =SUM(DM15:DM16) -> 43665.28 | DN17: =SUM(DN15:DN16) -> 73 | DO17: =SUM(DO15:DO16) -> 31341.44
B19: TT OPEN TV | H19: =SUM(H14:H17) -> 0 | I19: =SUM(I14:I17) -> 0 | J19: =SUM(J14:J17) -> 0 | K19: =SUM(K14:K17) -> 0 | L19: =SUM(L14:L17) -> 0 | M19: =SUM(M14:M17) -> 0 | N19: =SUM(N14:N17) -> 0 | O19: =SUM(O14:O17) -> 0 | ... CV19: =SUM(CV14:CV17) -> 242 | CZ19: =SUM(CZ15:CZ16) -> 129227.2 | DA19: =SUM(DA15:DA16) -> 103381.76 | DD19: =SUM(DD15:DD16) -> 0 | DE19: =DA19/DD19 -> #DIV/0! | DG19: TT GERAL | DH19: =SUM(#REF!,#REF!,#REF!,#REF!,#REF!,#REF!,#REF!,DH17) -> #REF! | DI19: =SUM(#REF!,#REF!,#REF!,#REF!,#REF!,#REF!,#REF!,DI17) -> #REF! | DJ19: =SUM(DJ17) -> 68 | DK19: =SUM(DK17) -> 28375.04 | DL19: =SUM(DL17) -> 101 | DM19: =SUM(DM17) -> 43665.28 | DN19: =SUM(DN17) -> 73 | DO19: =SUM(DO17) -> 31341.44
DN21: TT | DO21: =SUM(DK19,DM19,DO19) -> 103381.76
