Workbook
Name _1: #REF!
Name _1: #REF!
Name _1: #REF!
Name _10: #REF!
Name _10: #REF!
Name _10: #REF!
Name _11: #REF!
Name _11: #REF!
Name _11: #REF!
Name _12: #REF!
Name _12: #REF!
Name _12: #REF!
Name _13: #REF!
Name _13: #REF!
Name _13: #REF!
Name _14: #REF!
Name _14: #REF!
Name _14: #REF!
Name _15: #REF!
Name _15: #REF!
Name _15: #REF!
Name _16: #REF!
Name _16: #REF!
Name _16: #REF!
Name _17: #REF!
Name _17: #REF!
Name _17: #REF!
Name _18: #REF!
Name _18: #REF!
Name _18: #REF!
Name _19: #REF!
Name _19: #REF!
Name _19: #REF!
Name _1Excel_BuiltIn__FilterDatabase_10_9_1: NA()
Name _2: #REF!
Name _2: #REF!
Name _2: #REF!
Name _20: #REF!
Name _20: #REF!
Name _20: #REF!
Name _21: #REF!
Name _21: #REF!
Name _21: #REF!
Name _22: #REF!
Name _22: #REF!
Name _22: #REF!
Name _23: #REF!
Name _23: #REF!
Name _23: #REF!
Name _24: #REF!
Name _24: #REF!
Name _24: #REF!
Name _25: #REF!
Name _25: #REF!
Name _25: #REF!
Name _26: #REF!
Name _26: #REF!
Name _26: #REF!
Name _27: #REF!
Name _27: #REF!

Sheet COVER
B6: Tactical Media Plan | I6: CONFIDENCIAL
B8: CLIENT: | C8: SABESP
B9: CAMPAING | C9: ESCASSEZ HIDRICA PCJ
B10: TARGET: | C10: AS ABCDE 25+
B14: VERSION | C14: UPDATE DATE | D14: UPDATES:
B15: 1 | C15: 46062 | D15: Ajuste do período de veiculação para 15 dias; Redução do investimento de rádio; Ajuste do período de veiculação dos materiais de 60'' e 30'' de TV.
B16: 2 | C16: 46062 | D16: Ajuste do share de investimentos de TV.
B17: 3 | C17: 46078 | D17: Ajuste conforme compensações

Sheet RESUMO DE MEIOS
B5: CLIENT: SABESP
B6: CAMPAING: ESCASSEZ HIDRICA PCJ
B8: RESUMO DE MEIOS - SÃO PAULO CAPITAL
B10: PRAÇA | C10: MEIO | D10: VEÍCULO | F10: FEVEREIRO | G10: TOTAL BRUTO | H10: VALOR DESEMBOLSO TT | I10: PART GERAL %
B13: CAMPINAS | C13: TV ABERTA | D13: GLOBO | F13: ='TV ABERTA'!AX30*1.25 -> 294327.9 | G13: =SUM(F13:F13) -> 294327.9 | H13: =G13*0.8 -> 235462.32 | I13: =H13/$H$27 -> 0.30086699
B14: CAMPINAS | C14: TV ABERTA | D14: BANDEIRANTES | F14: ='TV ABERTA'!AX43*1.25 -> 20698.95 | G14: =SUM(F14:F14) -> 20698.95 | H14: =G14*0.8 -> 16559.16 | I14: =H14/$H$27 -> 0.021158819
B15: CAMPINAS | C15: TV ABERTA | D15: RECORD | F15: ='TV ABERTA'!AX58*1.25 -> 67579.6 | G15: =SUM(F15:F15) -> 67579.6 | H15: =G15*0.8 -> 54063.68 | I15: =H15/$H$27 -> 0.069081017
B16: CAMPINAS/SANTOS | C16: TV ABERTA | D16: SBT | F16: ='TV ABERTA'!AX75*1.25 -> 46601 | G16: =SUM(F16:F16) -> 46601 | H16: =G16*0.8 -> 37280.8 | I16: =H16/$H$27 -> 0.047636335
B17: SOROCABA | C17: TV ABERTA | D17: GLOBO | F17: ='TV ABERTA'!AX93*1.25 -> 119680.2 | G17: =SUM(F17:F17) -> 119680.2 | H17: =G17*0.8 -> 95744.16 | I17: =H17/$H$27 -> 0.12233914
B18: SOROCABA | C18: TV ABERTA | D18: SBT | F18: ='TV ABERTA'!AX108*1.25 -> 20792.75 | G18: =SUM(F18:F18) -> 20792.75 | H18: =G18*0.8 -> 16634.2 | I18: =H18/$H$27 -> 0.021254703
B19: RIBEIRÃO PRETO | C19: TV ABERTA | D19: GLOBO | F19: ='TV ABERTA'!AX126*1.25 -> 160146.9 | G19: =SUM(F19:F19) -> 160146.9 | H19: =G19*0.8 -> 128117.52 | I19: =H19/$H$27 -> 0.16370489
B20: RIBEIRÃO PRETO | C20: TV ABERTA | D20: BANDEIRANTES | F20: ='TV ABERTA'!AX139*1.25 -> 11295.3 | G20: =SUM(F20:F20) -> 11295.3 | H20: =G20*0.8 -> 9036.24 | I20: =H20/$H$27 -> 0.011546248
B21: RIBEIRÃO PRETO | C21: TV ABERTA | D21: SBT | F21: ='TV ABERTA'!AX152*1.25 -> 22686.75 | G21: =SUM(F21:F21) -> 22686.75 | H21: =G21*0.8 -> 18149.4 | I21: =H21/$H$27 -> 0.023190782
B22: SÃO JOSÉ DOS CAMPOS | C22: TV ABERTA | D22: GLOBO | F22: ='TV ABERTA'!AX170*1.25 -> 95413.5 | G22: =SUM(F22:F22) -> 95413.5 | H22: =G22*0.8 -> 76330.8 | I22: =H22/$H$27 -> 0.097533303
B23: SÃO JOSÉ DOS CAMPOS | C23: TV ABERTA | D23: SBT | F23: ='TV ABERTA'!AX185*1.25 -> 17058.5 | G23: =SUM(F23:F23) -> 17058.5 | H23: =G23*0.8 -> 13646.8 | I23: =H23/$H$27 -> 0.017437489
B24: SÃO CARLOS | C24: TV ABERTA | D24: GLOBO | F24: ='TV ABERTA'!AX203*1.25 -> 71724.6 | G24: =SUM(F24:F24) -> 71724.6 | H24: =G24*0.8 -> 57379.68 | I24: =H24/$H$27 -> 0.073318107
B25: FRANCA | C25: TV ABERTA | D25: RECORD | F25: ='TV ABERTA'!AX218*1.25 -> 30259.9 | G25: =SUM(F25:F25) -> 30259.9 | H25: =G25*0.8 -> 24207.92 | I25: =H25/$H$27 -> 0.030932185
B27: TT TV ABERTA | F27: =SUM(F13:F25) -> 978265.85 | G27: =SUM(G13:G25) -> 978265.85 | H27: =SUM(H13:H25) -> 782612.68 | I27: =SUM(I13:I25) -> 1 | J27: =H27/H39 -> 0.87063457 | K27: =H27=SUM('TV ABERTA'!AP220) -> FALSE
B29: BAIXA MOGIANA | C29: RADIO | D29: BAND FM | F29: ='RÁDIO '!BJ16*1.25 -> 6204 | G29: =SUM(F29:F29) -> 6204 | H29: =G29*0.8 -> 4963.2 | I29: =H29/$H$35 -> 0.047046119
B30: CAMPINAS | C30: RADIO | D30: BAND FM | F30: ='RÁDIO '!BJ20*1.25 -> 50301 | G30: =SUM(F30:F30) -> 50301 | H30: =G30*0.8 -> 40240.8 | I30: =H30/$H$35 -> 0.38144211
B31: CAMPINAS | C31: RADIO | D31: NATIVA FM | F31: ='RÁDIO '!BJ24*1.25 -> 56448 | G31: =SUM(F31:F31) -> 56448 | H31: =G31*0.8 -> 45158.4 | I31: =H31/$H$35 -> 0.42805599
B32: CAMPINAS | C32: RADIO | D32: EDUCADORA | F32: ='RÁDIO '!BJ28*1.25 -> 16508.6 | G32: =SUM(F32:F32) -> 16508.6 | H32: =G32*0.8 -> 13206.88 | I32: =H32/$H$35 -> 0.12518787
B33: MOOCA | C33: RADIO | D33: BAND FM | F33: ='RÁDIO '!BJ32*1.25 -> 2409 | G33: =SUM(F33:F33) -> 2409 | H33: =G33*0.8 -> 1927.2 | I33: =H33/$H$35 -> 0.018267908
B35: TT RÁDIO | F35: =SUM(F29:F33) -> 131870.6 | G35: =SUM(G29:G33) -> 131870.6 | H35: =SUM(H29:H33) -> 105496.48 | I35: =SUM(I29:I33) -> 1 | J35: =H35/H39 -> 0.11736186 | K35: =H35='RÁDIO '!BJ33 -> TRUE
B37: TT GERAÇÃO | F37: ='CUSTO GERAÇÃO'!I43*1.25 -> 13487.5 | G37: =SUM(F37:F37) -> 13487.5 | H37: =G37*0.8 -> 10790 | I37: 1 | J37: =H37/H39 -> 0.012003571
B39: TOTAL GERAL | F39: =SUM(F27,F35,F37) -> 1123624 | G39: =SUM(G27,G35,G37) -> 1123624 | H39: =SUM(H27,H35,H37) -> 898899.16 | J39: =SUM(J10:J38) -> 1
F40: =F39/G39 -> 1 | H40: =SUM('TV ABERTA'!AX220,'RÁDIO '!BJ33,'CUSTO GERAÇÃO'!I43)=H39 -> TRUE

Sheet RESUMO DE MEIOS - SPE
B5: CLIENT: SABESP
B6: CAMPAING: ESCASSEZ HIDRICA - CRÍTICO
B8: RESUMO DE MEIOS - SÃO PAULO ESTADO
B10: PRAÇA | C10: MEIO | D10: VEÍCULO | F10: JANEIRO | G10: FEVEREIRO | H10: TOTAL BRUTO | I10: VALOR DESEMBOLSO TT | J10: PART GERAL %
N12: UTILIZAÇÃO DE SALDO DE PACOTES | P12: SALDO PACOTE | Q12: TOTAL A SER FATURADO
B13: SÃO PAULO ESTADO | C13: TV ABERTA | D13: GLOBO | F13: ='TV ABERTA - SPE'!CC32*1.25 -> 3234841.4 | G13: ='TV ABERTA - SPE'!CE32*1.25 -> 1220562 | H13: =SUM(F13:G13) -> 4455403.4 | I13: =H13*0.8 -> 3564322.8 | J13: =I13/$I$23 -> 0.45681236 | N13: SBT | O13: =I16+I21 -> 1109489.6 | P13: 567311.6 | Q13: =O13-P13 -> 542178
B14: SÃO PAULO ESTADO | C14: TV ABERTA | D14: BANDEIRANTES | F14: ='TV ABERTA - SPE'!CC44*1.25 -> 118538.85 | G14: ='TV ABERTA - SPE'!CE44*1.25 -> 77298.6 | H14: =SUM(F14:G14) -> 195837.45 | I14: =H14*0.8 -> 156669.96 | J14: =I14/$I$23 -> 0.020079207
B15: SÃO PAULO ESTADO | C15: TV ABERTA | D15: RECORD | F15: ='TV ABERTA - SPE'!CC57*1.25 -> 602332.6 | G15: ='TV ABERTA - SPE'!CE57*1.25 -> 574113.2 | H15: =SUM(F15:G15) -> 1176445.8 | I15: =H15*0.8 -> 941156.64 | J15: =I15/$I$23 -> 0.12062095
B16: SÃO PAULO ESTADO | C16: TV ABERTA | D16: SBT | F16: ='TV ABERTA - SPE'!CC70*1.25 -> 510641.5 | G16: ='TV ABERTA - SPE'!CE70*1.25 -> 573264 | H16: =SUM(F16:G16) -> 1083905.5 | I16: =H16*0.8 -> 867124.4 | J16: =I16/$I$23 -> 0.11113279
B18: SÃO PAULO ESTADO | C18: TV ABERTA | D18: GLOBO | F18: ='TV ABERTA - COLCHÃO REP - SPE'!CC17*1.25 -> 830408.4 | G18: ='TV ABERTA - COLCHÃO REP - SPE'!CE17*1.25 -> 830408.4 | H18: =SUM(F18:G18) -> 1660816.8 | I18: =H18*0.8 -> 1328653.4 | J18: =I18/$I$23 -> 0.17028349
B19: SÃO PAULO ESTADO | C19: TV ABERTA | D19: BANDEIRANTES | F19: ='TV ABERTA - COLCHÃO REP - SPE'!CC20*1.25 -> 114500.4 | G19: ='TV ABERTA - COLCHÃO REP - SPE'!CE20*1.25 -> 114500.4 | H19: =SUM(F19:G19) -> 229000.8 | I19: =H19*0.8 -> 183200.64 | J19: =I19/$I$23 -> 0.023479444
B20: SÃO PAULO ESTADO | C20: TV ABERTA | D20: RECORD | F20: ='TV ABERTA - COLCHÃO REP - SPE'!CC23*1.25 -> 324440 | G20: ='TV ABERTA - COLCHÃO REP - SPE'!CE23*1.25 -> 324440 | H20: =SUM(F20:G20) -> 648880 | I20: =H20*0.8 -> 519104 | J20: =I20/$I$23 -> 0.066529644
B21: SÃO PAULO ESTADO | C21: TV ABERTA | D21: SBT | F21: ='TV ABERTA - COLCHÃO REP - SPE'!CC25*1.25 -> 100985.5 | G21: ='TV ABERTA - COLCHÃO REP - SPE'!CE25*1.25 -> 201971 | H21: =SUM(F21:G21) -> 302956.5 | I21: =H21*0.8 -> 242365.2 | J21: =I21/$I$23 -> 0.031062119
B23: TT TV ABERTA | F23: =SUM(F13:F21) -> 5836688.7 | G23: =SUM(G13:G21) -> 3916557.6 | H23: =SUM(H13:H21) -> 9753246.3 | I23: =SUM(I13:I21) -> 7802597 | J23: =SUM(J13:J21) -> 1 | K23: =I23/I68 -> #REF! | L23: =I23=SUM('TV ABERTA - SPE'!BU72,'TV ABERTA - COLCHÃO REP - SPE'!BU27) -> TRUE
B25: SÃO PAULO ESTADO | C25: TV PAGA | D25: GLOBONEWS | F25: ='TV PAGA - COLCHÃO REP - SPE'!CC37*1.25 -> 38904 | G25: ='TV PAGA - COLCHÃO REP - SPE'!CE37*1.25 -> 38904 | H25: =SUM(F25:G25) -> 77808 | I25: =H25*0.8 -> 62246.4 | J25: =I25/$I$30 -> 0.41072115
B26: SÃO PAULO ESTADO | C26: TV PAGA | D26: CNN BRASIL | F26: ='TV PAGA - COLCHÃO REP - SPE'!CC40*1.25 -> 22260 | G26: ='TV PAGA - COLCHÃO REP - SPE'!CE40*1.25 -> 22260 | H26: =SUM(F26:G26) -> 44520 | I26: =H26*0.8 -> 35616 | J26: =I26/$I$30 -> 0.23500547
B27: SÃO PAULO ESTADO | C27: TV PAGA | D27: RECORD NEWS | F27: ='TV PAGA - COLCHÃO REP - SPE'!CC43*1.25 -> 22000 | G27: ='TV PAGA - COLCHÃO REP - SPE'!CE43*1.25 -> 22000 | H27: =SUM(F27:G27) -> 44000 | I27: =H27*0.8 -> 35200 | J27: =I27/$I$30 -> 0.23226057
B28: SÃO PAULO ESTADO | C28: TV PAGA | D28: BAND NEWS | F28: ='TV PAGA - COLCHÃO REP - SPE'!CC46*1.25 -> 11557.2 | G28: ='TV PAGA - COLCHÃO REP - SPE'!CE46*1.25 -> 11557.2 | H28: =SUM(F28:G28) -> 23114.4 | I28: =H28*0.8 -> 18491.52 | J28: =I28/$I$30 -> 0.12201281
B30: TT TV PAGA | F30: =SUM(F25:F29) -> 94721.2 | G30: =SUM(G25:G29) -> 94721.2 | H30: =SUM(H25:H29) -> 189442.4 | I30: =SUM(I25:I29) -> 151553.92 | J30: =SUM(J25:J29) -> 1 | K30: =I30/I68 -> #REF! | L30: =I30='TV PAGA - COLCHÃO REP - SPE'!BU48 -> TRUE
B32: SÃO PAULO | C32: JORNAL | D32: =#REF! -> #REF! | F32: =SUM(#REF!)*1.25 -> #REF! | G32: {=SUM(#REF!*1.25)} -> #REF! | H32: =SUM(F32:G32) -> #REF! | I32: =H32*0.8 -> #REF! | J32: =I32/$I$38 -> #REF!
B33: SÃO PAULO | C33: JORNAL | D33: =#REF! -> #REF! | F33: =SUM(#REF!)*1.25 -> #REF! | G33: =SUM(#REF!)*1.25 -> #REF! | H33: =SUM(F33:G33) -> #REF! | I33: =H33*0.8 -> #REF! | J33: =I33/$I$38 -> #REF!
B34: SÃO PAULO | C34: JORNAL | D34: =#REF! -> #REF! | F34: =SUM(#REF!)*1.25 -> #REF! | G34: =SUM(#REF!)*1.25 -> #REF! | H34: =SUM(F34:G34) -> #REF! | I34: =H34*0.8 -> #REF! | J34: =I34/$I$38 -> #REF!
B35: SÃO PAULO | C35: JORNAL | D35: =#REF! -> #REF! | F35: =SUM(#REF!)*1.25 -> #REF! | G35: =SUM(#REF!)*1.25 -> #REF! | H35: =SUM(F35:G35) -> #REF! | I35: =H35*0.8 -> #REF! | J35: =I35/$I$38 -> #REF!
B36: =#REF! -> #REF! | C36: JORNAL | D36: =#REF! -> #REF! | F36: =SUM(#REF!)*1.25 -> #REF! | G36: =SUM(#REF!)*1.25 -> #REF! | H36: =SUM(F36:G36) -> #REF! | I36: =H36*0.8 -> #REF! | J36: =I36/$I$38 -> #REF!
B38: TT JORNAL | F38: =SUM(F32:F36) -> #REF! | G38: =SUM(G32:G36) -> #REF! | H38: =SUM(H32:H36) -> #REF! | I38: =SUM(I32:I36) -> #REF! | J38: =SUM(J32:J36) -> #REF! | K38: =I38/I68 -> #REF! | L38: =I38=#REF! -> #REF!
B40: SÃO PAULO | C40: RADIO | D40: JOVEM PAN FM | F40: =SUM(#REF!)*1.25 -> #REF! | G40: =SUM(#REF!)*1.25 -> #REF! | H40: =SUM(F40:G40) -> #REF! | I40: =H40*0.8 -> #REF! | J40: =I40/$I$60 -> #REF!
B41: SÃO PAULO | C41: RADIO | D41: BAND NEWS FM | F41: =SUM(#REF!)*1.25 -> #REF! | G41: =SUM(#REF!)*1.25 -> #REF! | H41: =SUM(F41:G41) -> #REF! | I41: =H41*0.8 -> #REF! | J41: =I41/$I$60 -> #REF!
B42: SÃO PAULO | C42: RADIO | D42: BANDEIRANTES | F42: =SUM(#REF!)*1.25 -> #REF! | G42: =SUM(#REF!)*1.25 -> #REF! | H42: =SUM(F42:G42) -> #REF! | I42: =H42*0.8 -> #REF! | J42: =I42/$I$60 -> #REF!
B43: SÃO PAULO | C43: RADIO | D43: CBN | F43: =SUM(#REF!)*1.25 -> #REF! | G43: =SUM(#REF!)*1.25 -> #REF! | H43: =SUM(F43:G43) -> #REF! | I43: =H43*0.8 -> #REF! | J43: =I43/$I$60 -> #REF!
B44: SÃO PAULO | C44: RADIO | D44: NATIVA FM | F44: =SUM(#REF!)*1.25 -> #REF! | G44: =SUM(#REF!)*1.25 -> #REF! | H44: =SUM(F44:G44) -> #REF! | I44: =H44*0.8 -> #REF! | J44: =I44/$I$60 -> #REF!
B45: SÃO PAULO | C45: RADIO | D45: BAND FM | F45: =SUM(#REF!)*1.25 -> #REF! | G45: =SUM(#REF!)*1.25 -> #REF! | H45: =SUM(F45:G45) -> #REF! | I45: =H45*0.8 -> #REF! | J45: =I45/$I$60 -> #REF!
B46: SÃO PAULO | C46: RADIO | D46: 89 ROCK FM | F46: =SUM(#REF!)*1.25 -> #REF! | G46: =SUM(#REF!)*1.25 -> #REF! | H46: =SUM(F46:G46) -> #REF! | I46: =H46*0.8 -> #REF! | J46: =I46/$I$60 -> #REF!
B47: SÃO PAULO | C47: RADIO | D47: ALPHA FM | F47: =SUM(#REF!)*1.25 -> #REF! | G47: =SUM(#REF!)*1.25 -> #REF! | H47: =SUM(F47:G47) -> #REF! | I47: =H47*0.8 -> #REF! | J47: =I47/$I$60 -> #REF!
B48: SÃO PAULO | C48: RADIO | D48: DISNEY FM | F48: =SUM(#REF!)*1.25 -> #REF! | G48: =SUM(#REF!)*1.25 -> #REF! | H48: =SUM(F48:G48) -> #REF! | I48: =H48*0.8 -> #REF! | J48: =I48/$I$60 -> #REF!
B49: SÃO PAULO | C49: RADIO | D49: ENERGIA 97 FM | F49: =SUM(#REF!)*1.25 -> #REF! | G49: =SUM(#REF!)*1.25 -> #REF! | H49: =SUM(F49:G49) -> #REF! | I49: =H49*0.8 -> #REF! | J49: =I49/$I$60 -> #REF!
B50: SÃO PAULO | C50: RADIO | D50: KISS FM | F50: =SUM(#REF!)*1.25 -> #REF! | G50: =SUM(#REF!)*1.25 -> #REF! | H50: =SUM(F50:G50) -> #REF! | I50: =H50*0.8 -> #REF! | J50: =I50/$I$60 -> #REF!
B51: SÃO PAULO | C51: RADIO | D51: GAZETA FM | F51: =SUM(#REF!)*1.25 -> #REF! | G51: =SUM(#REF!)*1.25 -> #REF! | H51: =SUM(F51:G51) -> #REF! | I51: =H51*0.8 -> #REF! | J51: =I51/$I$60 -> #REF!
B52: SÃO PAULO | C52: RADIO | D52: 105 FM | F52: =SUM(#REF!)*1.25 -> #REF! | G52: =SUM(#REF!)*1.25 -> #REF! | H52: =SUM(F52:G52) -> #REF! | I52: =H52*0.8 -> #REF! | J52: =I52/$I$60 -> #REF!
B53: SÃO PAULO | C53: RADIO | D53: RÁDIO MIX | F53: =SUM(#REF!+#REF!)*1.25 -> #REF! | G53: =SUM(#REF!+#REF!)*1.25 -> #REF! | H53: =SUM(F53:G53) -> #REF! | I53: =H53*0.8 -> #REF! | J53: =I53/$I$60 -> #REF!
B54: SÃO PAULO | C54: RADIO | D54: TRANSAMÉRICA FM | F54: =SUM(#REF!)*1.25 -> #REF! | G54: =SUM(#REF!)*1.25 -> #REF! | H54: =SUM(F54:G54) -> #REF! | I54: =H54*0.8 -> #REF! | J54: =I54/$I$60 -> #REF!
...

Sheet TV ABERTA
B5: CLIENT: SABESP
B6: CAMPAING: ESCASSEZ HIDRICA PCJ
AR7: PLANNED
B8: MARKET | C8: CHANNEL | D8: PROGRAMM | E8: DAY | F8: START TIME | G8: END TIME | H8: SEC | I8: FEVEREIRO | AK8: INS. | AL8: CUSTO TABELA UNITÁRIO (BRUTO) | AM8: DESC. % | AN8: CUSTO NEGOCIADO UNITÁRIO (BRUTO) | AO8: CUSTO TOTAL NEGOCIADO (BRUTO) | AP8: CUSTO TOTAL DESEMBOLSO SABESP | AR8: AUD. AS ABCDE 25+ | AS8: TRP | AT8: CPP | AV8: RESUMO
I9: S | J9: M | K9: T | L9: W | M9: T | N9: F | O9: S | P9: S | Q9: M | R9: T | S9: W | T9: T | U9: F | V9: S | W9: S | X9: M | Y9: T | Z9: W | AA9: T | AB9: F | AC9: S | AD9: S | AE9: M | AF9: T | AG9: W | AH9: T | AI9: F | AJ9: S
I10: 1 | J10: 2 | K10: 3 | L10: 4 | M10: 5 | N10: 6 | O10: 7 | P10: 8 | Q10: 9 | R10: 10 | S10: 11 | T10: 12 | U10: 13 | V10: 14 | W10: 15 | X10: 16 | Y10: 17 | Z10: =Y10+1 -> 18 | AA10: =Z10+1 -> 19 | AB10: =AA10+1 -> 20 | AC10: =AB10+1 -> 21 | AD10: =AC10+1 -> 22 | AE10: =AD10+1 -> 23 | AF10: =AE10+1 -> 24 | AG10: =AF10+1 -> 25 | ... AJ10: =AI10+1 -> 28 | AV10: CHANNEL | AW10: FEVEREIRO
AW12: INS | AX12: INVESTIMENTO $
B13: CAMPINAS | C13: GLOBO | D13: CALDEIRAO | E13: SÁB | F13: 0.67708333 | G13: 18:40 | H13: 60 | AK13: =SUM(I13:AJ13) -> 0 | AL13: 16272 | AM13: 0.1 | AN13: =AL13*(1-AM13) -> 14644.8 | AO13: =AN13*AK13 -> 0 | AP13: =AO13*0.8 -> 0 | AR13: 5.59 | AS13: =AR13*AK13 -> 0 | AT13: =IFERROR(AP13/AS13,0) -> 0 | AV13: TV GLOBO | AW13: =SUM(I13:AJ13) -> 0 | AX13: =AW13*AN13*0.8 -> 0 | AY13: =SUM(AX13)=AP13 -> TRUE
B14: CAMPINAS | C14: GLOBO | D14: CALDEIRAO | E14: SÁB | F14: 0.67708333 | G14: 18:40 | H14: 30 | V14: 1 | AK14: =SUM(I14:AJ14) -> 1 | AL14: 8136 | AM14: 0.1 | AN14: =AL14*(1-AM14) -> 7322.4 | AO14: =AN14*AK14 -> 7322.4 | AP14: =AO14*0.8 -> 5857.92 | AR14: 5.59 | AS14: =AR14*AK14 -> 5.59 | AT14: =IFERROR(AP14/AS14,0) -> 1047.9284 | AV14: TV GLOBO | AW14: =SUM(I14:AJ14) -> 1 | AX14: =AW14*AN14*0.8 -> 5857.92 | AY14: =SUM(AX14)=AP14 -> TRUE
D15: DOMINGAO COM HUCK | E15: DOM | F15: 0.625 | G15: 17:40 | H15: 60 | AK15: =SUM(I15:AJ15) -> 0 | AL15: 25890 | AM15: 0.1 | AN15: =AL15*(1-AM15) -> 23301 | AO15: =AN15*AK15 -> 0 | AP15: =AO15*0.8 -> 0 | AR15: 8.57 | AS15: =AR15*AK15 -> 0 | AT15: =IFERROR(AP15/AS15,0) -> 0 | AV15: TV GLOBO | AW15: =SUM(I15:AJ15) -> 0 | AX15: =AW15*AN15*0.8 -> 0 | AY15: =SUM(AX15)=AP15 -> TRUE
D16: DOMINGAO COM HUCK | E16: DOM | F16: 0.625 | G16: 17:40 | H16: 30 | W16: 1 | AD16: 1 | AK16: =SUM(I16:AJ16) -> 2 | AL16: 12945 | AM16: 0.1 | AN16: =AL16*(1-AM16) -> 11650.5 | AO16: =AN16*AK16 -> 23301 | AP16: =AO16*0.8 -> 18640.8 | AR16: 8.57 | AS16: =AR16*AK16 -> 17.14 | AT16: =IFERROR(AP16/AS16,0) -> 1087.5613 | AV16: TV GLOBO | AW16: =SUM(I16:AJ16) -> 2 | AX16: =AW16*AN16*0.8 -> 18640.8 | AY16: =SUM(AX16)=AP16 -> TRUE
D17: ENCONTRO | E17: SEG-SEX | F17: 0.39583333 | G17: 10:35 | H17: 30 | Z17: 1 | AF17: 1 | AK17: =SUM(I17:AJ17) -> 2 | AL17: 3137 | AM17: 0.1 | AN17: =AL17*(1-AM17) -> 2823.3 | AO17: =AN17*AK17 -> 5646.6 | AP17: =AO17*0.8 -> 4517.28 | AR17: 3.89 | AS17: =AR17*AK17 -> 7.78 | AT17: =IFERROR(AP17/AS17,0) -> 580.62725 | AV17: TV GLOBO | AW17: =SUM(I17:AJ17) -> 2 | AX17: =AW17*AN17*0.8 -> 4517.28 | AY17: =SUM(AX17)=AP17 -> TRUE
D18: JORNAL HOJE | E18: SEG-SÁB | F18: 0.55902778 | G18: 14:45 | H18: 30 | X18: 1 | AE18: 1 | AK18: =SUM(I18:AJ18) -> 2 | AL18: 7947 | AM18: 0.1 | AN18: =AL18*(1-AM18) -> 7152.3 | AO18: =AN18*AK18 -> 14304.6 | AP18: =AO18*0.8 -> 11443.68 | AR18: 5.92 | AS18: =AR18*AK18 -> 11.84 | AT18: =IFERROR(AP18/AS18,0) -> 966.52703 | AV18: TV GLOBO | AW18: =SUM(I18:AJ18) -> 2 | AX18: =AW18*AN18*0.8 -> 11443.68 | AY18: =SUM(AX18)=AP18 -> TRUE
D19: JORNAL NACIONAL | E19: SEG-SEX | F19: 0.85416667 | G19: 21:20 | H19: 60 | S19: 1 | AK19: =SUM(I19:AJ19) -> 1 | AL19: 72530 | AM19: 0.1 | AN19: =AL19*(1-AM19) -> 65277 | AO19: =AN19*AK19 -> 65277 | AP19: =AO19*0.8 -> 52221.6 | AR19: 13.07 | AS19: =AR19*AK19 -> 13.07 | AT19: =IFERROR(AP19/AS19,0) -> 3995.5318 | AV19: TV GLOBO | AW19: =SUM(I19:AJ19) -> 1 | AX19: =AW19*AN19*0.8 -> 52221.6 | AY19: =SUM(AX19)=AP19 -> TRUE
D20: JORNAL NACIONAL | E20: SEG-SEX | F20: 0.85416667 | G20: 21:20 | H20: 30 | AK20: =SUM(I20:AJ20) -> 0 | AL20: 36265 | AM20: 0.1 | AN20: =AL20*(1-AM20) -> 32638.5 | AO20: =AN20*AK20 -> 0 | AP20: =AO20*0.8 -> 0 | AR20: 13.07 | AS20: =AR20*AK20 -> 0 | AT20: =IFERROR(AP20/AS20,0) -> 0 | AV20: TV GLOBO | AW20: =SUM(I20:AJ20) -> 0 | AX20: =AW20*AN20*0.8 -> 0 | AY20: =SUM(AX20)=AP20 -> TRUE
D21: MAIS VOCE | E21: SEG-SEX | F21: 0.44097222 | G21: 11:45 | H21: 60 | AK21: =SUM(I21:AJ21) -> 0 | AL21: 8322 | AM21: 0.1 | AN21: =AL21*(1-AM21) -> 7489.8 | AO21: =AN21*AK21 -> 0 | AP21: =AO21*0.8 -> 0 | AR21: 3.79 | AS21: =AR21*AK21 -> 0 | AT21: =IFERROR(AP21/AS21,0) -> 0 | AV21: TV GLOBO | AW21: =SUM(I21:AJ21) -> 0 | AX21: =AW21*AN21*0.8 -> 0 | AY21: =SUM(AX21)=AP21 -> TRUE
D22: MAIS VOCE | E22: SEG-SEX | F22: 0.44097222 | G22: 11:45 | H22: 30 | U22: 1 | Y22: 1 | AG22: 1 | AK22: =SUM(I22:AJ22) -> 3 | AL22: 4161 | AM22: 0.1 | AN22: =AL22*(1-AM22) -> 3744.9 | AO22: =AN22*AK22 -> 11234.7 | AP22: =AO22*0.8 -> 8987.76 | AR22: 3.79 | AS22: =AR22*AK22 -> 11.37 | AT22: =IFERROR(AP22/AS22,0) -> 790.48021 | AV22: TV GLOBO | AW22: =SUM(I22:AJ22) -> 3 | AX22: =AW22*AN22*0.8 -> 8987.76 | AY22: =SUM(AX22)=AP22 -> TRUE
D23: NOVELA DA TARDE ED E | E23: SEG-SÁB | F23: 0.61458333 | G23: 15:25 | H23: 30 | Y23: 1 | AK23: =SUM(I23:AJ23) -> 1 | AL23: 5441 | AM23: 0.1 | AN23: =AL23*(1-AM23) -> 4896.9 | AO23: =AN23*AK23 -> 4896.9 | AP23: =AO23*0.8 -> 3917.52 | AR23: 6.47 | AS23: =AR23*AK23 -> 6.47 | AT23: =IFERROR(AP23/AS23,0) -> 605.48995 | AV23: TV GLOBO | AW23: =SUM(I23:AJ23) -> 1 | AX23: =AW23*AN23*0.8 -> 3917.52 | AY23: =SUM(AX23)=AP23 -> TRUE
D24: NOVELA I | E24: SEG-SEX | F24: 0.76736111 | G24: 19:10 | H24: 30 | AA24: 1 | AK24: =SUM(I24:AJ24) -> 1 | AL24: 17217 | AM24: 0.1 | AN24: =AL24*(1-AM24) -> 15495.3 | AO24: =AN24*AK24 -> 15495.3 | AP24: =AO24*0.8 -> 12396.24 | AR24: 8.5 | AS24: =AR24*AK24 -> 8.5 | AT24: =IFERROR(AP24/AS24,0) -> 1458.3812 | AV24: TV GLOBO | AW24: =SUM(I24:AJ24) -> 1 | AX24: =AW24*AN24*0.8 -> 12396.24 | AY24: =SUM(AX24)=AP24 -> TRUE
D25: NOVELA II | E25: SEG-SEX | F25: 0.81944444 | G25: 20:30 | H25: 60 | AK25: =SUM(I25:AJ25) -> 0 | AL25: 46286 | AM25: 0.1 | AN25: =AL25*(1-AM25) -> 41657.4 | AO25: =AN25*AK25 -> 0 | AP25: =AO25*0.8 -> 0 | AR25: 12.33 | AS25: =AR25*AK25 -> 0 | AT25: =IFERROR(AP25/AS25,0) -> 0 | AV25: TV GLOBO | AW25: =SUM(I25:AJ25) -> 0 | AX25: =AW25*AN25*0.8 -> 0 | AY25: =SUM(AX25)=AP25 -> TRUE
D26: NOVELA II | E26: SEG-SEX | F26: 0.81944444 | G26: 20:30 | H26: 30 | U26: 1 | Z26: 1 | AK26: =SUM(I26:AJ26) -> 2 | AL26: 23143 | AM26: 0.1 | AN26: =AL26*(1-AM26) -> 20828.7 | AO26: =AN26*AK26 -> 41657.4 | AP26: =AO26*0.8 -> 33325.92 | AR26: 12.33 | AS26: =AR26*AK26 -> 24.66 | AT26: =IFERROR(AP26/AS26,0) -> 1351.4161 | AV26: TV GLOBO | AW26: =SUM(I26:AJ26) -> 2 | AX26: =AW26*AN26*0.8 -> 33325.92 | AY26: =SUM(AX26)=AP26 -> TRUE
D27: NOVELA III | E27: SEG-SEX | F27: 0.88888889 | G27: 22:25 | H27: 60 | T27: 1 | AK27: =SUM(I27:AJ27) -> 1 | AL27: 67712 | AM27: 0.1 | AN27: =AL27*(1-AM27) -> 60940.8 | AO27: =AN27*AK27 -> 60940.8 | AP27: =AO27*0.8 -> 48752.64 | AR27: 13.4 | AS27: =AR27*AK27 -> 13.4 | AT27: =IFERROR(AP27/AS27,0) -> 3638.2567 | AV27: TV GLOBO | AW27: =SUM(I27:AJ27) -> 1 | AX27: =AW27*AN27*0.8 -> 48752.64 | AY27: =SUM(AX27)=AP27 -> TRUE
D28: NOVELA III | E28: SEG-SEX | F28: 0.88888889 | G28: 22:25 | H28: 30 | AF28: 1 | AK28: =SUM(I28:AJ28) -> 1 | AL28: 33856 | AM28: 0.1 | AN28: =AL28*(1-AM28) -> 30470.4 | AO28: =AN28*AK28 -> 30470.4 | AP28: =AO28*0.8 -> 24376.32 | AR28: 13.4 | AS28: =AR28*AK28 -> 13.4 | AT28: =IFERROR(AP28/AS28,0) -> 1819.1284 | AV28: TV GLOBO | AW28: =SUM(I28:AJ28) -> 1 | AX28: =AW28*AN28*0.8 -> 24376.32 | AY28: =SUM(AX28)=AP28 -> TRUE
D29: VALE A PENA VER DE N | E29: SEG-SEX | F29: 0.71180556 | G29: 18:25 | H29: 30 | X29: 1 | AG29: 1 | AK29: =SUM(I29:AJ29) -> 2 | AL29: 7656 | AM29: 0.1 | AN29: =AL29*(1-AM29) -> 6890.4 | AO29: =AN29*AK29 -> 13780.8 | AP29: =AO29*0.8 -> 11024.64 | AR29: 9.21 | AS29: =AR29*AK29 -> 18.42 | AT29: =IFERROR(AP29/AS29,0) -> 598.51466 | AV29: TV GLOBO | AW29: =SUM(I29:AJ29) -> 2 | AX29: =AW29*AN29*0.8 -> 11024.64 | AY29: =SUM(AX29)=AP29 -> TRUE
AV30: TT | AW30: =SUM(AW13:AW29) -> 19 | AX30: =SUM(AX13:AX29) -> 235462.32 | AY30: =SUM(AP13:AP29)=AX30 -> TRUE
C31: BANDEIRANTES | D31: BORA BRASIL | E31: SEG-SEX | F31: 0.375 | G31: 11:00 | H31: 30 | X31: 1 | AE31: 1 | AK31: =SUM(I31:AJ31) -> 2 | AL31: 2662 | AM31: 0.85 | AN31: =AL31*(1-AM31) -> 399.3 | AO31: =AN31*AK31 -> 798.6 | AP31: =AO31*0.8 -> 638.88 | AR31: 0.24 | AS31: =AR31*AK31 -> 0.48 | AT31: =IFERROR(AP31/AS31,0) -> 1331 | AV31: BANDEIRANTES | AW31: =SUM(I31:AJ31) -> 2 | AX31: =AW31*AN31*0.8 -> 638.88 | AY31: =SUM(AX31)=AP31 -> TRUE
D32: BRASIL URGENTE | E32: SEG-SÁB | F32: 0.66666667 | G32: 17:30 | H32: 60 | T32: 1 | AK32: =SUM(I32:AJ32) -> 1 | AL32: 18856 | AM32: 0.85 | AN32: =AL32*(1-AM32) -> 2828.4 | AO32: =AN32*AK32 -> 2828.4 | AP32: =AO32*0.8 -> 2262.72 | AR32: 1.43 | AS32: =AR32*AK32 -> 1.43 | AT32: =IFERROR(AP32/AS32,0) -> 1582.3217 | AV32: BANDEIRANTES | AW32: =SUM(I32:AJ32) -> 1 | AX32: =AW32*AN32*0.8 -> 2262.72 | AY32: =SUM(AX32)=AP32 -> TRUE
D33: BRASIL URGENTE | E33: SEG-SÁB | F33: 0.66666667 | G33: 17:30 | H33: 30 | Z33: 1 | AK33: =SUM(I33:AJ33) -> 1 | AL33: 9428 | AM33: 0.85 | AN33: =AL33*(1-AM33) -> 1414.2 | AO33: =AN33*AK33 -> 1414.2 | AP33: =AO33*0.8 -> 1131.36 | AR33: 1.43 | AS33: =AR33*AK33 -> 1.43 | AT33: =IFERROR(AP33/AS33,0) -> 791.16084 | AV33: BANDEIRANTES | AW33: =SUM(I33:AJ33) -> 1 | AX33: =AW33*AN33*0.8 -> 1131.36 | AY33: =SUM(AX33)=AP33 -> TRUE
D34: CANAL LIVRE | E34: DOM | F34: 0.95833333 | G34: 00:00 | H34: 60 | AK34: =SUM(I34:AJ34) -> 0 | AL34: 9740 | AM34: 0.85 | AN34: =AL34*(1-AM34) -> 1461 | AO34: =AN34*AK34 -> 0 | AP34: =AO34*0.8 -> 0 | AR34: 0.21 | AS34: =AR34*AK34 -> 0 | AT34: =IFERROR(AP34/AS34,0) -> 0 | AV34: BANDEIRANTES | AW34: =SUM(I34:AJ34) -> 0 | AX34: =AW34*AN34*0.8 -> 0 | AY34: =SUM(AX34)=AP34 -> TRUE
D35: CANAL LIVRE | E35: DOM | F35: 0.95833333 | G35: 00:00 | H35: 30 | AD35: 1 | AK35: =SUM(I35:AJ35) -> 1 | AL35: 4870 | AM35: 0.85 | AN35: =AL35*(1-AM35) -> 730.5 | AO35: =AN35*AK35 -> 730.5 | AP35: =AO35*0.8 -> 584.4 | AR35: 0.21 | AS35: =AR35*AK35 -> 0.21 | AT35: =IFERROR(AP35/AS35,0) -> 2782.8571 | AV35: BANDEIRANTES | AW35: =SUM(I35:AJ35) -> 1 | AX35: =AW35*AN35*0.8 -> 584.4 | AY35: =SUM(AX35)=AP35 -> TRUE
D36: JORNAL DA NOITE | E36: SEG-SEX | F36: 0.010416667 | G36: 01:15 | H36: 60 | T36: 1 | AK36: =SUM(I36:AJ36) -> 1 | AL36: 10226 | AM36: 0.85 | AN36: =AL36*(1-AM36) -> 1533.9 | AO36: =AN36*AK36 -> 1533.9 | AP36: =AO36*0.8 -> 1227.12 | AR36: 0.34 | AS36: =AR36*AK36 -> 0.34 | AT36: =IFERROR(AP36/AS36,0) -> 3609.1765 | AV36: BANDEIRANTES | AW36: =SUM(I36:AJ36) -> 1 | AX36: =AW36*AN36*0.8 -> 1227.12 | AY36: =SUM(AX36)=AP36 -> TRUE
D37: JORNAL DA NOITE | E37: SEG-SEX | F37: 0.010416667 | G37: 01:15 | H37: 30 | Y37: 1 | AF37: 1 | AK37: =SUM(I37:AJ37) -> 2 | AL37: 5113 | AM37: 0.85 | AN37: =AL37*(1-AM37) -> 766.95 | AO37: =AN37*AK37 -> 1533.9 | AP37: =AO37*0.8 -> 1227.12 | AR37: 0.34 | AS37: =AR37*AK37 -> 0.68 | AT37: =IFERROR(AP37/AS37,0) -> 1804.5882 | AV37: BANDEIRANTES | AW37: =SUM(I37:AJ37) -> 2 | AX37: =AW37*AN37*0.8 -> 1227.12 | AY37: =SUM(AX37)=AP37 -> TRUE
D38: NOVELA I | E38: SEG-SEX | F38: 0.29166667 | G38: 08:00 | H38: 30 | AA38: 1 | AG38: 1 | AK38: =SUM(I38:AJ38) -> 2 | AL38: 2662 | AM38: 0.85 | AN38: =AL38*(1-AM38) -> 399.3 | AO38: =AN38*AK38 -> 798.6 | AP38: =AO38*0.8 -> 638.88 | AR38: 0.1 | AS38: =AR38*AK38 -> 0.2 | AT38: =IFERROR(AP38/AS38,0) -> 3194.4 | AV38: BANDEIRANTES | AW38: =SUM(I38:AJ38) -> 2 | AX38: =AW38*AN38*0.8 -> 638.88 | AY38: =SUM(AX38)=AP38 -> TRUE
D39: NOVELA II | E39: SEG-SEX | F39: 0.85416667 | G39: 21:25 | H39: 60 | U39: 1 | AK39: =SUM(I39:AJ39) -> 1 | AL39: 33370 | AM39: 0.85 | AN39: =AL39*(1-AM39) -> 5005.5 | AO39: =AN39*AK39 -> 5005.5 | AP39: =AO39*0.8 -> 4004.4 | AR39: 0.71 | AS39: =AR39*AK39 -> 0.71 | AT39: =IFERROR(AP39/AS39,0) -> 5640 | AV39: BANDEIRANTES | AW39: =SUM(I39:AJ39) -> 1 | AX39: =AW39*AN39*0.8 -> 4004.4 | AY39: =SUM(AX39)=AP39 -> TRUE
D40: NOVELA II | E40: SEG-SEX | F40: 0.85416667 | G40: 21:25 | H40: 30 | AB40: 1 | AK40: =SUM(I40:AJ40) -> 1 | AL40: 16685 | AM40: 0.85 | AN40: =AL40*(1-AM40) -> 2502.75 | AO40: =AN40*AK40 -> 2502.75 | AP40: =AO40*0.8 -> 2002.2 | AR40: 0.71 | AS40: =AR40*AK40 -> 0.71 | AT40: =IFERROR(AP40/AS40,0) -> 2820 | AV40: BANDEIRANTES | AW40: =SUM(I40:AJ40) -> 1 | AX40: =AW40*AN40*0.8 -> 2002.2 | AY40: =SUM(AX40)=AP40 -> TRUE
D41: SABADAO DE TODOS | E41: SÁB | F41: 0.85416667 | G41: 22:30 | H41: 60 | AK41: =SUM(I41:AJ41) -> 0 | AL41: 23684 | AM41: 0.85 | AN41: =AL41*(1-AM41) -> 3552.6 | AO41: =AN41*AK41 -> 0 | AP41: =AO41*0.8 -> 0 | AR41: 0.54 | AS41: =AR41*AK41 -> 0 | AT41: =IFERROR(AP41/AS41,0) -> 0 | AV41: BANDEIRANTES | AW41: =SUM(I41:AJ41) -> 0 | AX41: =AW41*AN41*0.8 -> 0 | AY41: =SUM(AX41)=AP41 -> TRUE
D42: SABADAO DE TODOS | E42: SÁB | F42: 0.85416667 | G42: 22:30 | H42: 30 | V42: 1 | AC42: 1 | AK42: =SUM(I42:AJ42) -> 2 | AL42: 11842 | AM42: 0.85 | AN42: =AL42*(1-AM42) -> 1776.3 | AO42: =AN42*AK42 -> 3552.6 | AP42: =AO42*0.8 -> 2842.08 | AR42: 0.54 | AS42: =AR42*AK42 -> 1.08 | AT42: =IFERROR(AP42/AS42,0) -> 2631.5556 | AV42: BANDEIRANTES | AW42: =SUM(I42:AJ42) -> 2 | AX42: =AW42*AN42*0.8 -> 2842.08 | AY42: =SUM(AX42)=AP42 -> TRUE
AV43: TT | AW43: =SUM(AW31:AW42) -> 14 | AX43: =SUM(AX31:AX42) -> 16559.16 | AY43: =SUM(AP31:AP42)=AX43 -> TRUE
C44: RECORD | D44: CIDADE ALERTA | E44: SEG-SEX | F44: 0.6875 | G44: 19:55 | H44: 60 | U44: 1 | AK44: =SUM(I44:AJ44) -> 1 | AL44: 10374 | AM44: 0.78 | AN44: =AL44*(1-AM44) -> 2282.28 | AO44: =AN44*AK44 -> 2282.28 | AP44: =AO44*0.8 -> 1825.824 | AR44: 2.19 | AS44: =AR44*AK44 -> 2.19 | AT44: =IFERROR(AP44/AS44,0) -> 833.70959 | AV44: RECORD | AW44: =SUM(I44:AJ44) -> 1 | AX44: =AW44*AN44*0.8 -> 1825.824 | AY44: =SUM(AX44)=AP44 -> TRUE
D45: CIDADE ALERTA | E45: SEG-SEX | F45: 0.6875 | G45: 19:55 | H45: 30 | Y45: 1 | AA45: 1 | AF45: 1 | AK45: =SUM(I45:AJ45) -> 3 | AL45: 5187 | AM45: 0.78 | AN45: =AL45*(1-AM45) -> 1141.14 | AO45: =AN45*AK45 -> 3423.42 | AP45: =AO45*0.8 -> 2738.736 | AR45: 2.19 | AS45: =AR45*AK45 -> 6.57 | AT45: =IFERROR(AP45/AS45,0) -> 416.85479 | AV45: RECORD | AW45: =SUM(I45:AJ45) -> 3 | AX45: =AW45*AN45*0.8 -> 2738.736 | AY45: =SUM(AX45)=AP45 -> TRUE
...

Sheet TV ABERTA - SPE
B5: CLIENT: SABESP
B6: CAMPAING: ESCASSEZ HIDRICA - CRÍTICO
BW7: PLANNED
B8: MARKET | C8: CHANNEL | D8: PROGRAMM | E8: DAY | F8: START TIME | G8: END TIME | H8: SEC | I8: JANEIRO | BP8: INS. | BQ8: CUSTO TABELA UNITÁRIO (BRUTO) | BR8: DESC. % | BS8: CUSTO NEGOCIADO UNITÁRIO (BRUTO) | BT8: CUSTO TOTAL NEGOCIADO (BRUTO) | BU8: CUSTO TOTAL DESEMBOLSO SABESP | BW8: AUD. AS ABCDE 25+ | BX8: TRP | BY8: CPP | CA8: RESUMO
I9: T | J9: F | K9: S | L9: S | M9: M | N9: T | O9: W | P9: T | Q9: F | R9: S | S9: S | T9: M | U9: T | V9: W | W9: T | X9: F | Y9: S | Z9: S | AA9: M | AB9: T | AC9: W | AD9: T | AE9: F | AF9: S | AG9: S | AH9: M | AI9: T | AJ9: W | AK9: T | AL9: F | AM9: S | AN9: S | AO9: M | AP9: T | AQ9: W | AR9: T | AS9: F | AT9: S | AU9: S | AV9: M | AW9: T | AX9: W | AY9: T | AZ9: F | BA9: S | BB9: S | BC9: M | BD9: T | BE9: W | BF9: T | BG9: F | BH9: S | BI9: S | BJ9: M | BK9: T | BL9: W | BM9: T | BN9: F | BO9: S
I10: 1 | J10: 2 | K10: 3 | L10: 4 | M10: 5 | N10: 6 | O10: 7 | P10: 8 | Q10: 9 | R10: 10 | S10: 11 | T10: 12 | U10: 13 | V10: 14 | W10: 15 | X10: 16 | Y10: 17 | Z10: =Y10+1 -> 18 | AA10: =Z10+1 -> 19 | AB10: =AA10+1 -> 20 | AC10: =AB10+1 -> 21 | AD10: =AC10+1 -> 22 | AE10: =AD10+1 -> 23 | AF10: =AE10+1 -> 24 | AG10: =AF10+1 -> 25 | ... AM10: =AL10+1 -> 31 | AN10: 1 | AO10: 2 | AP10: 3 | AQ10: 4 | AR10: 5 | AS10: 6 | AT10: 7 | AU10: 8 | AV10: 9 | AW10: 10 | AX10: 11 | AY10: 12 | AZ10: 13 | BA10: 14 | BB10: 15 | BC10: 16 | BD10: 17 | BE10: =BD10+1 -> 18 | BF10: =BE10+1 -> 19 | BG10: =BF10+1 -> 20 | BH10: =BG10+1 -> 21 | BI10: =BH10+1 -> 22 | BJ10: =BI10+1 -> 23 | BK10: =BJ10+1 -> 24 | BL10: =BK10+1 -> 25 | ... BO10: =BN10+1 -> 28 | CA10: CHANNEL | CB10: JANEIRO | CD10: FEVEREIRO
CB12: INS | CC12: INVESTIMENTO $ | CD12: INS | CE12: INVESTIMENTO $
B13: SÃO PAULO ESTADO | C13: TV GLOBO | D13: NOVELA II | E13: SEG-SEX | F13: 0.81944444 | G13: 0.85416667 | H13: 30 | AJ13: 1 | BP13: =SUM(I13:BO13) -> 1 | BQ13: 217403 | BR13: 1 | BS13: =BQ13*(1-BR13) -> 0 | BT13: =BS13*BP13 -> 0 | BU13: =BT13*0.8 -> 0 | BW13: 12.33 | BX13: =BW13*BP13 -> 12.33 | BY13: =IFERROR(BU13/BX13,0) -> 0 | CA13: TV GLOBO | CB13: =COUNTA(I13:AM13) -> 1 | CC13: =CB13*BS13*0.8 -> 0 | CD13: =COUNTA(AN13:BO13) -> 0 | CE13: =CD13*BS13*0.8 -> 0 | CF13: =SUM(CC13,CE13)=BU13 -> TRUE
D14: NOVELA III | E14: SEG-SEX | F14: 0.88888889 | G14: 0.93402778 | H14: 30 | AH14: 1 | AK14: 1 | BP14: =SUM(I14:BO14) -> 2 | BQ14: 318624 | BR14: 0 | BS14: =BQ14*(1-BR14) -> 318624 | BT14: =BS14*BP14 -> 637248 | BU14: =BT14*0.8 -> 509798.4 | BW14: 13.35 | BX14: =BW14*BP14 -> 26.7 | BY14: =IFERROR(BU14/BX14,0) -> 19093.573 | CA14: TV GLOBO | CB14: =COUNTA(I14:AM14) -> 2 | CC14: =CB14*BS14*0.8 -> 509798.4 | CD14: =COUNTA(AN14:BO14) -> 0 | CE14: =CD14*BS14*0.8 -> 0 | CF14: =SUM(CC14,CE14)=BU14 -> TRUE
D16: NOVELA II | E16: SEG-SEX | F16: 0.81944444 | G16: 0.85416667 | H16: 30 | AO16: 1 | AR16: 1 | AW16: 1 | BP16: =SUM(I16:BO16) -> 3 | BQ16: 217403 | BR16: 0 | BS16: =BQ16*(1-BR16) -> 217403 | BT16: =BS16*BP16 -> 652209 | BU16: =BT16*0.8 -> 521767.2 | BW16: 12.33 | BX16: =BW16*BP16 -> 36.99 | BY16: =IFERROR(BU16/BX16,0) -> 14105.629 | CA16: TV GLOBO | CB16: =COUNTA(I16:AM16) -> 0 | CC16: =CB16*BS16*0.8 -> 0 | CD16: =COUNTA(AN16:BO16) -> 3 | CE16: =CD16*BS16*0.8 -> 521767.2 | CF16: =SUM(CC16,CE16)=BU16 -> TRUE
D17: NOVELA I | E17: SEG-SEX | F17: 0.76736111 | G17: 0.79861111 | H17: 30 | AS17: 1 | BP17: =SUM(I17:BO17) -> 1 | BQ17: 163381 | BR17: 1 | BS17: =BQ17*(1-BR17) -> 0 | BT17: =BS17*BP17 -> 0 | BU17: =BT17*0.8 -> 0 | BW17: 8.51 | BX17: =BW17*BP17 -> 8.51 | BY17: =IFERROR(BU17/BX17,0) -> 0 | CA17: TV GLOBO | CB17: =COUNTA(I17:AM17) -> 0 | CC17: =CB17*BS17*0.8 -> 0 | CD17: =COUNTA(AN17:BO17) -> 1 | CE17: =CD17*BS17*0.8 -> 0 | CF17: =SUM(CC17,CE17)=BU17 -> TRUE
D19: JORNAL NACIONAL | E19: SEG-SEX | F19: 0.85416667 | G19: 0.88888889 | H19: 30 | AV19: 1 | BP19: =SUM(I19:BO19) -> 1 | BQ19: 316309 | BR19: 0 | BS19: =BQ19*(1-BR19) -> 316309 | BT19: =BS19*BP19 -> 316309 | BU19: =BT19*0.8 -> 253047.2 | BW19: 13.07 | BX19: =BW19*BP19 -> 13.07 | BY19: =IFERROR(BU19/BX19,0) -> 19360.918 | CA19: TV GLOBO | CB19: =COUNTA(I19:AM19) -> 0 | CC19: =CB19*BS19*0.8 -> 0 | CD19: =COUNTA(AN19:BO19) -> 1 | CE19: =CD19*BS19*0.8 -> 253047.2 | CF19: =SUM(CC19,CE19)=BU19 -> TRUE
D20: FANTASTICO | E20: DOM | F20: 0.85416667 | G20: 0.96527778 | H20: 30 | AU20: 1 | BP20: =SUM(I20:BO20) -> 1 | BQ20: 252044 | BR20: 0 | BS20: =BQ20*(1-BR20) -> 252044 | BT20: =BS20*BP20 -> 252044 | BU20: =BT20*0.8 -> 201635.2 | BW20: 8.8 | BX20: =BW20*BP20 -> 8.8 | BY20: =IFERROR(BU20/BX20,0) -> 22913.091 | CA20: TV GLOBO | CB20: =COUNTA(I20:AM20) -> 0 | CC20: =CB20*BS20*0.8 -> 0 | CD20: =COUNTA(AN20:BO20) -> 1 | CE20: =CD20*BS20*0.8 -> 201635.2 | CF20: =SUM(CC20,CE20)=BU20 -> TRUE
D21: JORNAL DA GLOBO | E21: SEG-SEX | F21: 0.041666667 | G21: 0.076388889 | H21: 30 | AO21: 1 | AQ21: 1 | AW21: 1 | AY21: 1 | BP21: =SUM(I21:BO21) -> 4 | BQ21: 43682 | BR21: 1 | BS21: =BQ21*(1-BR21) -> 0 | BT21: =BS21*BP21 -> 0 | BU21: =BT21*0.8 -> 0 | BW21: 3.7 | BX21: =BW21*BP21 -> 14.8 | BY21: =IFERROR(BU21/BX21,0) -> 0 | CA21: TV GLOBO | CB21: =COUNTA(I21:AM21) -> 0 | CC21: =CB21*BS21*0.8 -> 0 | CD21: =COUNTA(AN21:BO21) -> 4 | CE21: =CD21*BS21*0.8 -> 0 | CF21: =SUM(CC21,CE21)=BU21 -> TRUE
D23: NOVELA I | E23: SEG-SEX | F23: 0.76736111 | G23: 0.79861111 | H23: 30 | AH23: 1 | AK23: 1 | BP23: =SUM(I23:BO23) -> 2 | BQ23: 163381 | BR23: 0 | BS23: =BQ23*(1-BR23) -> 163381 | BT23: =BS23*BP23 -> 326762 | BU23: =BT23*0.8 -> 261409.6 | BW23: 8.51 | BX23: =BW23*BP23 -> 17.02 | BY23: =IFERROR(BU23/BX23,0) -> 15358.966 | CA23: TV GLOBO | CB23: =COUNTA(I23:AM23) -> 2 | CC23: =CB23*BS23*0.8 -> 261409.6 | CD23: =COUNTA(AN23:BO23) -> 0 | CE23: =CD23*BS23*0.8 -> 0 | CF23: =SUM(CC23,CE23)=BU23 -> TRUE
D24: NOVELA II | E24: SEG-SEX | F24: 0.81944444 | G24: 0.85416667 | H24: 30 | AI24: 1 | AL24: 1 | BP24: =SUM(I24:BO24) -> 2 | BQ24: 217403 | BR24: 0 | BS24: =BQ24*(1-BR24) -> 217403 | BT24: =BS24*BP24 -> 434806 | BU24: =BT24*0.8 -> 347844.8 | BW24: 12.33 | BX24: =BW24*BP24 -> 24.66 | BY24: =IFERROR(BU24/BX24,0) -> 14105.629 | CA24: TV GLOBO | CB24: =COUNTA(I24:AM24) -> 2 | CC24: =CB24*BS24*0.8 -> 347844.8 | CD24: =COUNTA(AN24:BO24) -> 0 | CE24: =CD24*BS24*0.8 -> 0 | CF24: =SUM(CC24,CE24)=BU24 -> TRUE
D25: NOVELA I SAB | E25: SÁB | F25: 0.77777778 | G25: 0.80902778 | H25: 30 | AM25: 1 | AT25: 1 | BP25: =SUM(I25:BO25) -> 2 | BQ25: 172884 | BR25: 1 | BS25: =BQ25*(1-BR25) -> 0 | BT25: =BS25*BP25 -> 0 | BU25: =BT25*0.8 -> 0 | BW25: 11.08 | BX25: =BW25*BP25 -> 22.16 | BY25: =IFERROR(BU25/BX25,0) -> 0 | CA25: TV GLOBO | CB25: =COUNTA(I25:AM25) -> 1 | CC25: =CB25*BS25*0.8 -> 0 | CD25: =COUNTA(AN25:BO25) -> 1 | CE25: =CD25*BS25*0.8 -> 0 | CF25: =SUM(CC25,CE25)=BU25 -> TRUE
D27: NOVELA III | E27: SEG-SEX | F27: 0.88888889 | G27: 0.93402778 | H27: 60 | AD27: 1 | BP27: =SUM(I27:BO27) -> 1 | BQ27: =318624*2 -> 637248 | BR27: 0 | BS27: =BQ27*(1-BR27) -> 637248 | BT27: =BS27*BP27 -> 637248 | BU27: =BT27*0.8 -> 509798.4 | BW27: 13.35 | BX27: =BW27*BP27 -> 13.35 | BY27: =IFERROR(BU27/BX27,0) -> 38187.146 | CA27: TV GLOBO | CB27: =COUNTA(I27:AM27) -> 1 | CC27: =CB27*BS27*0.8 -> 509798.4 | CD27: =COUNTA(AN27:BO27) -> 0 | CE27: =CD27*BS27*0.8 -> 0 | CF27: =SUM(CC27,CE27)=BU27 -> TRUE
D28: NOVELA III SAB | E28: SÁB | F28: 0.88888889 | G28: 0.93402778 | H28: 60 | AF28: 1 | BP28: =SUM(I28:BO28) -> 1 | BQ28: =257775*2 -> 515550 | BR28: 0 | BS28: =BQ28*(1-BR28) -> 515550 | BT28: =BS28*BP28 -> 515550 | BU28: =BT28*0.8 -> 412440 | BW28: 11.18 | BX28: =BW28*BP28 -> 11.18 | BY28: =IFERROR(BU28/BX28,0) -> 36890.877 | CA28: TV GLOBO | CB28: =COUNTA(I28:AM28) -> 1 | CC28: =CB28*BS28*0.8 -> 412440 | CD28: =COUNTA(AN28:BO28) -> 0 | CE28: =CD28*BS28*0.8 -> 0 | CF28: =SUM(CC28,CE28)=BU28 -> TRUE
D29: NOVELA II | E29: SEG-SEX | F29: 0.81944444 | G29: 0.85416667 | H29: 60 | AE29: 1 | BP29: =SUM(I29:BO29) -> 1 | BQ29: =217403*2 -> 434806 | BR29: 1 | BS29: =BQ29*(1-BR29) -> 0 | BT29: =BS29*BP29 -> 0 | BU29: =BT29*0.8 -> 0 | BW29: 12.33 | BX29: =BW29*BP29 -> 12.33 | BY29: =IFERROR(BU29/BX29,0) -> 0 | CA29: TV GLOBO | CB29: =COUNTA(I29:AM29) -> 1 | CC29: =CB29*BS29*0.8 -> 0 | CD29: =COUNTA(AN29:BO29) -> 0 | CE29: =CD29*BS29*0.8 -> 0 | CF29: =SUM(CC29,CE29)=BU29 -> TRUE
D31: JORNAL NACIONAL - PRIMEIRISSIMA | E31: SEG-SEX | F31: 0.85416667 | G31: 0.88888889 | H31: 60 | AC31: 1 | BP31: =SUM(I31:BO31) -> 1 | BQ31: =(316309*2)*1.2 -> 759141.6 | BR31: 0.1 | BS31: =BQ31*(1-BR31) -> 683227.44 | BT31: =BS31*BP31 -> 683227.44 | BU31: =BT31*0.8 -> 546581.95 | BW31: 13.07 | BX31: =BW31*BP31 -> 13.07 | BY31: =IFERROR(BU31/BX31,0) -> 41819.583 | CA31: TV GLOBO | CB31: =COUNTA(I31:AM31) -> 1 | CC31: =CB31*BS31*0.8 -> 546581.95 | CD31: =COUNTA(AN31:BO31) -> 0 | CE31: =CD31*BS31*0.8 -> 0 | CF31: =SUM(CC31,CE31)=BU31 -> TRUE
CA32: TT | CB32: =SUM(CB13:CB31) -> 12 | CC32: =SUM(CC13:CC31) -> 2587873.2 | CD32: =SUM(CD13:CD31) -> 11 | CE32: =SUM(CE13:CE31) -> 976449.6
C33: BANDEIRANTES | D33: BORA BRASIL | E33: SEG-SEX | F33: 0.375 | G33: 11:00 | H33: 30 | AK33: 1 | AR33: 1 | AY33: 1 | BP33: =SUM(I33:BO33) -> 3 | BQ33: 18884 | BR33: 0.85 | BS33: =BQ33*(1-BR33) -> 2832.6 | BT33: =BS33*BP33 -> 8497.8 | BU33: =BT33*0.8 -> 6798.24 | BW33: 0.24 | BX33: =BW33*BP33 -> 0.72 | BY33: =IFERROR(BU33/BX33,0) -> 9442 | CA33: BANDEIRANTES | CB33: =COUNTA(I33:AM33) -> 1 | CC33: =CB33*BS33*0.8 -> 2266.08 | CD33: =COUNTA(AN33:BO33) -> 2 | CE33: =CD33*BS33*0.8 -> 4532.16 | CF33: =SUM(CC33,CE33)=BU33 -> TRUE
D34: BORA BRASIL | E34: SEG-SEX | F34: 0.375 | G34: 11:00 | H34: 60 | AD34: 1 | BP34: =SUM(I34:BO34) -> 1 | BQ34: 37768 | BR34: 0.85 | BS34: =BQ34*(1-BR34) -> 5665.2 | BT34: =BS34*BP34 -> 5665.2 | BU34: =BT34*0.8 -> 4532.16 | BW34: 0.24 | BX34: =BW34*BP34 -> 0.24 | BY34: =IFERROR(BU34/BX34,0) -> 18884 | CA34: BANDEIRANTES | CB34: =COUNTA(I34:AM34) -> 1 | CC34: =CB34*BS34*0.8 -> 4532.16 | CD34: =COUNTA(AN34:BO34) -> 0 | CE34: =CD34*BS34*0.8 -> 0 | CF34: =SUM(CC34,CE34)=BU34 -> TRUE
D35: BRASIL URGENTE | E35: SEG-SÁB | F35: 0.66666667 | G35: 17:30 | H35: 30 | AL35: 1 | AS35: 1 | AZ35: 1 | BP35: =SUM(I35:BO35) -> 3 | BQ35: 66878 | BR35: 0.85 | BS35: =BQ35*(1-BR35) -> 10031.7 | BT35: =BS35*BP35 -> 30095.1 | BU35: =BT35*0.8 -> 24076.08 | BW35: 1.43 | BX35: =BW35*BP35 -> 4.29 | BY35: =IFERROR(BU35/BX35,0) -> 5612.1399 | CA35: BANDEIRANTES | CB35: =COUNTA(I35:AM35) -> 1 | CC35: =CB35*BS35*0.8 -> 8025.36 | CD35: =COUNTA(AN35:BO35) -> 2 | CE35: =CD35*BS35*0.8 -> 16050.72 | CF35: =SUM(CC35,CE35)=BU35 -> TRUE
D36: BRASIL URGENTE | E36: SEG-SÁB | F36: 0.66666667 | G36: 17:30 | H36: 60 | AE36: 1 | BP36: =SUM(I36:BO36) -> 1 | BQ36: 133756 | BR36: 0.85 | BS36: =BQ36*(1-BR36) -> 20063.4 | BT36: =BS36*BP36 -> 20063.4 | BU36: =BT36*0.8 -> 16050.72 | BW36: 1.43 | BX36: =BW36*BP36 -> 1.43 | BY36: =IFERROR(BU36/BX36,0) -> 11224.28 | CA36: BANDEIRANTES | CB36: =COUNTA(I36:AM36) -> 1 | CC36: =CB36*BS36*0.8 -> 16050.72 | CD36: =COUNTA(AN36:BO36) -> 0 | CE36: =CD36*BS36*0.8 -> 0 | CF36: =SUM(CC36,CE36)=BU36 -> TRUE
D37: CANAL LIVRE | E37: DOM | F37: 0.95833333 | G37: 00:00 | H37: 30 | AU37: 1 | BP37: =SUM(I37:BO37) -> 1 | BQ37: 34546 | BR37: 0.85 | BS37: =BQ37*(1-BR37) -> 5181.9 | BT37: =BS37*BP37 -> 5181.9 | BU37: =BT37*0.8 -> 4145.52 | BW37: 0.21 | BX37: =BW37*BP37 -> 0.21 | BY37: =IFERROR(BU37/BX37,0) -> 19740.571 | CA37: BANDEIRANTES | CB37: =COUNTA(I37:AM37) -> 0 | CC37: =CB37*BS37*0.8 -> 0 | CD37: =COUNTA(AN37:BO37) -> 1 | CE37: =CD37*BS37*0.8 -> 4145.52 | CF37: =SUM(CC37,CE37)=BU37 -> TRUE
D38: CANAL LIVRE | E38: DOM | F38: 0.95833333 | G38: 00:00 | H38: 60 | AG38: 1 | BP38: =SUM(I38:BO38) -> 1 | BQ38: 69092 | BR38: 0.85 | BS38: =BQ38*(1-BR38) -> 10363.8 | BT38: =BS38*BP38 -> 10363.8 | BU38: =BT38*0.8 -> 8291.04 | BW38: 0.21 | BX38: =BW38*BP38 -> 0.21 | BY38: =IFERROR(BU38/BX38,0) -> 39481.143 | CA38: BANDEIRANTES | CB38: =COUNTA(I38:AM38) -> 1 | CC38: =CB38*BS38*0.8 -> 8291.04 | CD38: =COUNTA(AN38:BO38) -> 0 | CE38: =CD38*BS38*0.8 -> 0 | CF38: =SUM(CC38,CE38)=BU38 -> TRUE
D39: JORNAL DA NOITE | E39: SEG-SEX | F39: 0.010416667 | G39: 01:15 | H39: 30 | AJ39: 1 | AQ39: 1 | AX39: 1 | BP39: =SUM(I39:BO39) -> 3 | BQ39: 36271 | BR39: 0.85 | BS39: =BQ39*(1-BR39) -> 5440.65 | BT39: =BS39*BP39 -> 16321.95 | BU39: =BT39*0.8 -> 13057.56 | BW39: 0.34 | BX39: =BW39*BP39 -> 1.02 | BY39: =IFERROR(BU39/BX39,0) -> 12801.529 | CA39: BANDEIRANTES | CB39: =COUNTA(I39:AM39) -> 1 | CC39: =CB39*BS39*0.8 -> 4352.52 | CD39: =COUNTA(AN39:BO39) -> 2 | CE39: =CD39*BS39*0.8 -> 8705.04 | CF39: =SUM(CC39,CE39)=BU39 -> TRUE
D40: JORNAL DA NOITE | E40: SEG-SEX | F40: 0.010416667 | G40: 01:15 | H40: 60 | AD40: 1 | BP40: =SUM(I40:BO40) -> 1 | BQ40: 72542 | BR40: 0.85 | BS40: =BQ40*(1-BR40) -> 10881.3 | BT40: =BS40*BP40 -> 10881.3 | BU40: =BT40*0.8 -> 8705.04 | BW40: 0.34 | BX40: =BW40*BP40 -> 0.34 | BY40: =IFERROR(BU40/BX40,0) -> 25603.059 | CA40: BANDEIRANTES | CB40: =COUNTA(I40:AM40) -> 1 | CC40: =CB40*BS40*0.8 -> 8705.04 | CD40: =COUNTA(AN40:BO40) -> 0 | CE40: =CD40*BS40*0.8 -> 0 | CF40: =SUM(CC40,CE40)=BU40 -> TRUE
D41: NOVELA I | E41: SEG-SEX | F41: 0.29166667 | G41: 08:00 | H41: 30 | BP41: =SUM(I41:BO41) -> 0 | BQ41: 16564 | BR41: 0.85 | BS41: =BQ41*(1-BR41) -> 2484.6 | BT41: =BS41*BP41 -> 0 | BU41: =BT41*0.8 -> 0 | BW41: 0.1 | BX41: =BW41*BP41 -> 0 | BY41: =IFERROR(BU41/BX41,0) -> 0 | CA41: BANDEIRANTES | CB41: =COUNTA(I41:AM41) -> 0 | CC41: =CB41*BS41*0.8 -> 0 | CD41: =COUNTA(AN41:BO41) -> 0 | CE41: =CD41*BS41*0.8 -> 0 | CF41: =SUM(CC41,CE41)=BU41 -> TRUE
D42: NOVELA II | E42: SEG-SEX | F42: 0.85416667 | G42: 21:25 | H42: 30 | AH42: 1 | AO42: 1 | AV42: 1 | BP42: =SUM(I42:BO42) -> 3 | BQ42: 118356 | BR42: 0.85 | BS42: =BQ42*(1-BR42) -> 17753.4 | BT42: =BS42*BP42 -> 53260.2 | BU42: =BT42*0.8 -> 42608.16 | BW42: 0.71 | BX42: =BW42*BP42 -> 2.13 | BY42: =IFERROR(BU42/BX42,0) -> 20003.831 | CA42: BANDEIRANTES | CB42: =COUNTA(I42:AM42) -> 1 | CC42: =CB42*BS42*0.8 -> 14202.72 | CD42: =COUNTA(AN42:BO42) -> 2 | CE42: =CD42*BS42*0.8 -> 28405.44 | CF42: =SUM(CC42,CE42)=BU42 -> TRUE
D43: NOVELA II | E43: SEG-SEX | F43: 0.85416667 | G43: 21:25 | H43: 60 | AE43: 1 | BP43: =SUM(I43:BO43) -> 1 | BQ43: 236712 | BR43: 0.85 | BS43: =BQ43*(1-BR43) -> 35506.8 | BT43: =BS43*BP43 -> 35506.8 | BU43: =BT43*0.8 -> 28405.44 | BW43: 0.71 | BX43: =BW43*BP43 -> 0.71 | BY43: =IFERROR(BU43/BX43,0) -> 40007.662 | CA43: BANDEIRANTES | CB43: =COUNTA(I43:AM43) -> 1 | CC43: =CB43*BS43*0.8 -> 28405.44 | CD43: =COUNTA(AN43:BO43) -> 0 | CE43: =CD43*BS43*0.8 -> 0 | CF43: =SUM(CC43,CE43)=BU43 -> TRUE
CA44: TT | CB44: =SUM(CB33:CB43) -> 9 | CC44: =SUM(CC33:CC43) -> 94831.08 | CD44: =SUM(CD33:CD43) -> 9 | CE44: =SUM(CE33:CE43) -> 61838.88
C45: RECORD | D45: CIDADE ALERTA 2 SAB | E45: SÁB | F45: 0.875 | G45: 22:30 | H45: 30 | AM45: 1 | AT45: 1 | BA45: 1 | BP45: =SUM(I45:BO45) -> 3 | BQ45: 68258 | BR45: 0.8 | BS45: =BQ45*(1-BR45) -> 13651.6 | BT45: =BS45*BP45 -> 40954.8 | BU45: =BT45*0.8 -> 32763.84 | BW45: 2.19 | BX45: =BW45*BP45 -> 6.57 | BY45: =IFERROR(BU45/BX45,0) -> 4986.8858 | CA45: RECORD | CB45: =COUNTA(I45:AM45) -> 1 | CC45: =CB45*BS45*0.8 -> 10921.28 | CD45: =COUNTA(AN45:BO45) -> 2 | CE45: =CD45*BS45*0.8 -> 21842.56 | CF45: =SUM(CC45,CE45)=BU45 -> TRUE
D46: CIDADE ALERTA 2 SAB | E46: SÁB | F46: 0.875 | G46: 22:30 | H46: 60 | AF46: 1 | BP46: =SUM(I46:BO46) -> 1 | BQ46: 136516 | BR46: 0.8 | BS46: =BQ46*(1-BR46) -> 27303.2 | BT46: =BS46*BP46 -> 27303.2 | BU46: =BT46*0.8 -> 21842.56 | BW46: 2.19 | BX46: =BW46*BP46 -> 2.19 | BY46: =IFERROR(BU46/BX46,0) -> 9973.7717 | CA46: RECORD | CB46: =COUNTA(I46:AM46) -> 1 | CC46: =CB46*BS46*0.8 -> 21842.56 | CD46: =COUNTA(AN46:BO46) -> 0 | CE46: =CD46*BS46*0.8 -> 0 | CF46: =SUM(CC46,CE46)=BU46 -> TRUE
D47: DOMINGO ESPETACULAR | E47: DOM | F47: 0.75 | G47: 20:00 | H47: 30 | AN47: 1 | AU47: 1 | BB47: 1 | BP47: =SUM(I47:BO47) -> 3 | BQ47: 393224 | BR47: 0.8 | BS47: =BQ47*(1-BR47) -> 78644.8 | BT47: =BS47*BP47 -> 235934.4 | BU47: =BT47*0.8 -> 188747.52 | BW47: 3.05 | BX47: =BW47*BP47 -> 9.15 | BY47: =IFERROR(BU47/BX47,0) -> 20628.144 | CA47: RECORD | CB47: =COUNTA(I47:AM47) -> 0 | CC47: =CB47*BS47*0.8 -> 0 | CD47: =COUNTA(AN47:BO47) -> 3 | CE47: =CD47*BS47*0.8 -> 188747.52 | CF47: =SUM(CC47,CE47)=BU47 -> TRUE
D48: DOMINGO ESPETACULAR | E48: DOM | F48: 0.75 | G48: 20:00 | H48: 60 | AG48: 1 | BP48: =SUM(I48:BO48) -> 1 | BQ48: 786448 | BR48: 0.8 | BS48: =BQ48*(1-BR48) -> 157289.6 | BT48: =BS48*BP48 -> 157289.6 | BU48: =BT48*0.8 -> 125831.68 | BW48: 3.05 | BX48: =BW48*BP48 -> 3.05 | BY48: =IFERROR(BU48/BX48,0) -> 41256.289 | CA48: RECORD | CB48: =COUNTA(I48:AM48) -> 1 | CC48: =CB48*BS48*0.8 -> 125831.68 | CD48: =COUNTA(AN48:BO48) -> 0 | CE48: =CD48*BS48*0.8 -> 0 | CF48: =SUM(CC48,CE48)=BU48 -> TRUE
D49: FALA BRASIL | E49: SEG-SEX | F49: 0.35416667 | G49: 09:35 | H49: 30 | AJ49: 1 | AQ49: 1 | AX49: 1 | BP49: =SUM(I49:BO49) -> 3 | BQ49: 88342 | BR49: 0.8 | BS49: =BQ49*(1-BR49) -> 17668.4 | BT49: =BS49*BP49 -> 53005.2 | BU49: =BT49*0.8 -> 42404.16 | BW49: 1.95 | BX49: =BW49*BP49 -> 5.85 | BY49: =IFERROR(BU49/BX49,0) -> 7248.5744 | CA49: RECORD | CB49: =COUNTA(I49:AM49) -> 1 | CC49: =CB49*BS49*0.8 -> 14134.72 | CD49: =COUNTA(AN49:BO49) -> 2 | CE49: =CD49*BS49*0.8 -> 28269.44 | CF49: =SUM(CC49,CE49)=BU49 -> TRUE
D50: FALA BRASIL | E50: SEG-SEX | F50: 0.35416667 | G50: 09:35 | H50: 60 | AE50: 1 | BP50: =SUM(I50:BO50) -> 1 | BQ50: 176684 | BR50: 0.8 | BS50: =BQ50*(1-BR50) -> 35336.8 | BT50: =BS50*BP50 -> 35336.8 | BU50: =BT50*0.8 -> 28269.44 | BW50: 1.95 | BX50: =BW50*BP50 -> 1.95 | BY50: =IFERROR(BU50/BX50,0) -> 14497.149 | CA50: RECORD | CB50: =COUNTA(I50:AM50) -> 1 | CC50: =CB50*BS50*0.8 -> 28269.44 | CD50: =COUNTA(AN50:BO50) -> 0 | CE50: =CD50*BS50*0.8 -> 0 | CF50: =SUM(CC50,CE50)=BU50 -> TRUE
...

Sheet TV ABERTA - COLCHÃO REP - SP1
B5: CLIENT: SABESP
B6: CAMPAING: ESCASSEZ HIDRICA - CRÍTICO
BW7: PLANNED
B8: MARKET | C8: CHANNEL | D8: PROGRAMM | E8: DAY | F8: START TIME | G8: END TIME | H8: SEC | I8: JANEIRO | BP8: INS. | BQ8: CUSTO TABELA UNITÁRIO (BRUTO) | BR8: DESC. % | BS8: CUSTO NEGOCIADO UNITÁRIO (BRUTO) | BT8: CUSTO TOTAL NEGOCIADO (BRUTO) | BU8: CUSTO TOTAL DESEMBOLSO SABESP | BW8: AUD. AS ABCDE 25+ | BX8: TRP | BY8: CPP | CA8: RESUMO
I9: T | J9: F | K9: S | L9: S | M9: M | N9: T | O9: W | P9: T | Q9: F | R9: S | S9: S | T9: M | U9: T | V9: W | W9: T | X9: F | Y9: S | Z9: S | AA9: M | AB9: T | AC9: W | AD9: T | AE9: F | AF9: S | AG9: S | AH9: M | AI9: T | AJ9: W | AK9: T | AL9: F | AM9: S | AN9: S | AO9: M | AP9: T | AQ9: W | AR9: T | AS9: F | AT9: S | AU9: S | AV9: M | AW9: T | AX9: W | AY9: T | AZ9: F | BA9: S | BB9: S | BC9: M | BD9: T | BE9: W | BF9: T | BG9: F | BH9: S | BI9: S | BJ9: M | BK9: T | BL9: W | BM9: T | BN9: F | BO9: S
I10: 1 | J10: 2 | K10: 3 | L10: 4 | M10: 5 | N10: 6 | O10: 7 | P10: 8 | Q10: 9 | R10: 10 | S10: 11 | T10: 12 | U10: 13 | V10: 14 | W10: 15 | X10: 16 | Y10: 17 | Z10: =Y10+1 -> 18 | AA10: =Z10+1 -> 19 | AB10: =AA10+1 -> 20 | AC10: =AB10+1 -> 21 | AD10: =AC10+1 -> 22 | AE10: =AD10+1 -> 23 | AF10: =AE10+1 -> 24 | AG10: =AF10+1 -> 25 | ... AM10: =AL10+1 -> 31 | AN10: 1 | AO10: 2 | AP10: 3 | AQ10: 4 | AR10: 5 | AS10: 6 | AT10: 7 | AU10: 8 | AV10: 9 | AW10: 10 | AX10: 11 | AY10: 12 | AZ10: 13 | BA10: 14 | BB10: 15 | BC10: 16 | BD10: 17 | BE10: =BD10+1 -> 18 | BF10: =BE10+1 -> 19 | BG10: =BF10+1 -> 20 | BH10: =BG10+1 -> 21 | BI10: =BH10+1 -> 22 | BJ10: =BI10+1 -> 23 | BK10: =BJ10+1 -> 24 | BL10: =BK10+1 -> 25 | ... BO10: =BN10+1 -> 28 | CA10: CHANNEL | CB10: JANEIRO | CD10: FEVEREIRO
CB12: INS | CC12: INVESTIMENTO $ | CD12: INS | CE12: INVESTIMENTO $
B13: SÃO PAULO CAPITAL | C13: TV GLOBO | D13: PRACA TV 1 EDICAO | E13: SEG-SEX | F13: 0.48958333 | G13: 13:00 | H13: 30 | AH13: 1 | AJ13: 1 | AL13: 1 | AP13: 1 | AR13: 1 | AV13: 1 | AX13: 1 | AZ13: 1 | BP13: =SUM(I13:BO13) -> 8 | BQ13: 27572 | BR13: 0.1 | BS13: =BQ13*(1-BR13) -> 24814.8 | BT13: =BS13*BP13 -> 198518.4 | BU13: =BT13*0.8 -> 158814.72 | BW13: 5.24 | BX13: =BW13*BP13 -> 41.92 | BY13: =IFERROR(BU13/BX13,0) -> 3788.5191 | CA13: TV GLOBO | CB13: =COUNTA(I13:AM13) -> 3 | CC13: =CB13*BS13*0.8 -> 59555.52 | CD13: =COUNTA(AN13:BO13) -> 5 | CE13: =CD13*BS13*0.8 -> 99259.2 | CF13: =SUM(CC13,CE13)=BU13 -> TRUE
E14: SEG-SEX | F14: 0.48958333 | G14: 13:00 | H14: 60 | AE14: 1 | BP14: =SUM(I14:BO14) -> 1 | BQ14: 55144 | BR14: 0.1 | BS14: =BQ14*(1-BR14) -> 49629.6 | BT14: =BS14*BP14 -> 49629.6 | BU14: =BT14*0.8 -> 39703.68 | BW14: 5.24 | BX14: =BW14*BP14 -> 5.24 | BY14: =IFERROR(BU14/BX14,0) -> 7577.0382 | CA14: TV GLOBO | CB14: =COUNTA(I14:AM14) -> 1 | CC14: =CB14*BS14*0.8 -> 39703.68 | CD14: =COUNTA(AN14:BO14) -> 0 | CE14: =CD14*BS14*0.8 -> 0 | CF14: =SUM(CC14,CE14)=BU14 -> TRUE
D15: PRACA TV 2 EDICAO | E15: SEG-SEX | F15: 0.79861111 | G15: 19:40 | H15: 30 | AK15: 1 | AO15: 1 | AS15: 1 | AY15: 1 | BP15: =SUM(I15:BO15) -> 4 | BQ15: 112324 | BR15: 0.1 | BS15: =BQ15*(1-BR15) -> 101091.6 | BT15: =BS15*BP15 -> 404366.4 | BU15: =BT15*0.8 -> 323493.12 | BW15: 12.39 | BX15: =BW15*BP15 -> 49.56 | BY15: =IFERROR(BU15/BX15,0) -> 6527.3027 | CA15: TV GLOBO | CB15: =COUNTA(I15:AM15) -> 1 | CC15: =CB15*BS15*0.8 -> 80873.28 | CD15: =COUNTA(AN15:BO15) -> 3 | CE15: =CD15*BS15*0.8 -> 242619.84 | CF15: =SUM(CC15,CE15)=BU15 -> TRUE
E16: SEG-SEX | F16: 0.79861111 | G16: 19:40 | H16: 60 | AD16: 1 | BP16: =SUM(I16:BO16) -> 1 | BQ16: 224648 | BR16: 0.1 | BS16: =BQ16*(1-BR16) -> 202183.2 | BT16: =BS16*BP16 -> 202183.2 | BU16: =BT16*0.8 -> 161746.56 | BW16: 12.39 | BX16: =BW16*BP16 -> 12.39 | BY16: =IFERROR(BU16/BX16,0) -> 13054.605 | CA16: TV GLOBO | CB16: =COUNTA(I16:AM16) -> 1 | CC16: =CB16*BS16*0.8 -> 161746.56 | CD16: =COUNTA(AN16:BO16) -> 0 | CE16: =CD16*BS16*0.8 -> 0 | CF16: =SUM(CC16,CE16)=BU16 -> TRUE
CA17: TT | CB17: =SUM(CB13:CB16) -> 6 | CC17: =SUM(CC13:CC16) -> 341879.04 | CD17: =SUM(CD13:CD16) -> 8 | CE17: =SUM(CE13:CE16) -> 341879.04
C18: BANDEIRANTES | D18: JORNAL DA BAND | E18: SEG-SEX | F18: 0.80555556 | G18: 20:30 | H18: 30 | AI18: 1 | AK18: 1 | AP18: 1 | AR18: 1 | AW18: 1 | AY18: 1 | BP18: =SUM(I18:BO18) -> 6 | BQ18: 107608 | BR18: 0.85 | BS18: =BQ18*(1-BR18) -> 16141.2 | BT18: =BS18*BP18 -> 96847.2 | BU18: =BT18*0.8 -> 77477.76 | BW18: 1.59 | BX18: =BW18*BP18 -> 9.54 | BY18: =IFERROR(BU18/BX18,0) -> 8121.3585 | CA18: BANDEIRANTES | CB18: =COUNTA(I18:AM18) -> 2 | CC18: =CB18*BS18*0.8 -> 25825.92 | CD18: =COUNTA(AN18:BO18) -> 4 | CE18: =CD18*BS18*0.8 -> 51651.84 | CF18: =SUM(CC18,CE18)=BU18 -> TRUE
E19: SEG-SEX | F19: 0.80555556 | G19: 20:30 | H19: 60 | AD19: 1 | BP19: =SUM(I19:BO19) -> 1 | BQ19: 215216 | BR19: 0.85 | BS19: =BQ19*(1-BR19) -> 32282.4 | BT19: =BS19*BP19 -> 32282.4 | BU19: =BT19*0.8 -> 25825.92 | BW19: 1.59 | BX19: =BW19*BP19 -> 1.59 | BY19: =IFERROR(BU19/BX19,0) -> 16242.717 | CA19: BANDEIRANTES | CB19: =COUNTA(I19:AM19) -> 1 | CC19: =CB19*BS19*0.8 -> 25825.92 | CD19: =COUNTA(AN19:BO19) -> 0 | CE19: =CD19*BS19*0.8 -> 0 | CF19: =SUM(CC19,CE19)=BU19 -> TRUE
CA20: TT | CB20: =SUM(CB18:CB19) -> 3 | CC20: =SUM(CC18:CC19) -> 51651.84 | CD20: =SUM(CD18:CD19) -> 4 | CE20: =SUM(CE18:CE19) -> 51651.84
C21: RECORD | D21: JORNAL DA RECORD | E21: SEG-SEX | F21: 0.82986111 | G21: 21:00 | H21: 30 | AJ21: 1 | AL21: 1 | AQ21: 1 | AS21: 1 | AX21: 1 | AZ21: 1 | BP21: =SUM(I21:BO21) -> 6 | BQ21: 335107 | BR21: 0.8 | BS21: =BQ21*(1-BR21) -> 67021.4 | BT21: =BS21*BP21 -> 402128.4 | BU21: =BT21*0.8 -> 321702.72 | BW21: 3.53 | BX21: =BW21*BP21 -> 21.18 | BY21: =IFERROR(BU21/BX21,0) -> 15188.986 | CA21: RECORD | CB21: =COUNTA(I21:AM21) -> 2 | CC21: =CB21*BS21*0.8 -> 107234.24 | CD21: =COUNTA(AN21:BO21) -> 4 | CE21: =CD21*BS21*0.8 -> 214468.48 | CF21: =SUM(CC21,CE21)=BU21 -> TRUE
E22: SEG-SEX | F22: 0.82986111 | G22: 21:00 | H22: 60 | AE22: 1 | BP22: =SUM(I22:BO22) -> 1 | BQ22: 670214 | BR22: 0.8 | BS22: =BQ22*(1-BR22) -> 134042.8 | BT22: =BS22*BP22 -> 134042.8 | BU22: =BT22*0.8 -> 107234.24 | BW22: 3.53 | BX22: =BW22*BP22 -> 3.53 | BY22: =IFERROR(BU22/BX22,0) -> 30377.972 | CA22: RECORD | CB22: =COUNTA(I22:AM22) -> 1 | CC22: =CB22*BS22*0.8 -> 107234.24 | CD22: =COUNTA(AN22:BO22) -> 0 | CE22: =CD22*BS22*0.8 -> 0 | CF22: =SUM(CC22,CE22)=BU22 -> TRUE
CA23: TT | CB23: =SUM(CB21:CB22) -> 3 | CC23: =SUM(CC21:CC22) -> 214468.48 | CD23: =SUM(CD21:CD22) -> 4 | CE23: =SUM(CE21:CE22) -> 214468.48
C24: SBT | D24: SBT BRASIL | E24: SEG-SEX | F24: 0.82291667 | G24: 21:00 | H24: 30 | AI24: 1 | AK24: 1 | AP24: 1 | AR24: 1 | AW24: 1 | AY24: 1 | BP24: =SUM(I24:BO24) -> 6 | BQ24: 155300 | BR24: 0.75 | BS24: =BQ24*(1-BR24) -> 38825 | BT24: =BS24*BP24 -> 232950 | BU24: =BT24*0.8 -> 186360 | BW24: 1.91 | BX24: =BW24*BP24 -> 11.46 | BY24: =IFERROR(BU24/BX24,0) -> 16261.78 | CA24: SBT | CB24: =COUNTA(I24:AM24) -> 2 | CC24: =CB24*BS24*0.8 -> 62120 | CD24: =COUNTA(AN24:BO24) -> 4 | CE24: =CD24*BS24*0.8 -> 124240 | CF24: =SUM(CC24,CE24)=BU24 -> TRUE
CA25: TT | CB25: =SUM(CB24) -> 2 | CC25: =SUM(CC24) -> 62120 | CD25: =SUM(CD24) -> 4 | CE25: =SUM(CE24) -> 124240
C26: REDE TV | D26: REDETV! NEWS | E26: SEG-SEX | F26: 0.82986111 | G26: 20:30 | H26: 30 | AI26: 1 | AL26: 1 | AP26: 1 | AS26: 1 | AW26: 1 | AZ26: 1 | BP26: =SUM(I26:BO26) -> 6 | BQ26: 83652 | BR26: 0.85 | BS26: =BQ26*(1-BR26) -> 12547.8 | BT26: =BS26*BP26 -> 75286.8 | BU26: =BT26*0.8 -> 60229.44 | BW26: 0.14 | BX26: =BW26*BP26 -> 0.84 | BY26: =IFERROR(BU26/BX26,0) -> 71701.714 | CA26: REDE TV | CB26: =COUNTA(I26:AM26) -> 2 | CC26: =CB26*BS26*0.8 -> 20076.48 | CD26: =COUNTA(AN26:BO26) -> 4 | CE26: =CD26*BS26*0.8 -> 40152.96 | CF26: =SUM(CC26,CE26)=BU26 -> TRUE
E27: SEG-SEX | F27: 0.82986111 | G27: 20:30 | H27: 60 | AE27: 1 | BP27: =SUM(I27:BO27) -> 1 | BQ27: 167304 | BR27: 0.85 | BS27: =BQ27*(1-BR27) -> 25095.6 | BT27: =BS27*BP27 -> 25095.6 | BU27: =BT27*0.8 -> 20076.48 | BW27: 0.14 | BX27: =BW27*BP27 -> 0.14 | BY27: =IFERROR(BU27/BX27,0) -> 143403.43 | CA27: REDE TV | CB27: =COUNTA(I27:AM27) -> 1 | CC27: =CB27*BS27*0.8 -> 20076.48 | CD27: =COUNTA(AN27:BO27) -> 0 | CE27: =CD27*BS27*0.8 -> 0 | CF27: =SUM(CC27,CE27)=BU27 -> TRUE
CA28: TT | CB28: =SUM(CB26:CB27) -> 3 | CC28: =SUM(CC26:CC27) -> 40152.96 | CD28: =SUM(CD26:CD27) -> 4 | CE28: =SUM(CE26:CE27) -> 40152.96
B30: TT OPEN TV | I30: =COUNTA(I12:I16) -> 0 | J30: =COUNTA(J12:J16) -> 0 | K30: =COUNTA(K12:K16) -> 0 | L30: =COUNTA(L12:L16) -> 0 | M30: =COUNTA(M12:M16) -> 0 | N30: =SUM(N12:N16) -> 0 | O30: =SUM(O12:O16) -> 0 | P30: =SUM(P12:P16) -> 0 | Q30: =SUM(Q12:Q28) -> 0 | R30: =SUM(R12:R28) -> 0 | S30: =SUM(S12:S28) -> 0 | T30: =SUM(T12:T28) -> 0 | U30: =SUM(U12:U28) -> 0 | V30: =SUM(V12:V28) -> 0 | W30: =SUM(W12:W28) -> 0 | X30: =SUM(X12:X28) -> 0 | ... BJ30: =SUM(BJ12:BJ28) -> 0 | BK30: =SUM(BK13:BK29) -> 0 | BL30: =SUM(BL13:BL29) -> 0 | BM30: =SUM(BM12:BM16) -> 0 | BN30: =SUM(BN12:BN16) -> 0 | BO30: =SUM(BO12:BO16) -> 0 | BP30: =SUM(BP13:BP28) -> 41 | BT30: =SUM(BT13:BT28) -> 1853330.8 | BU30: =SUM(BU13:BU28) -> 1482664.6 | BX30: =SUM(BX13:BX27) -> 157.39 | BY30: =BU30/BX30 -> 9420.323 | CA30: TT GERAL | CB30: =CB17+CB20+CB23+CB28+CB25 -> 17 | CC30: =CC17+CC20+CC23+CC28+CC25 -> 710272.32 | CD30: =CD17+CD20+CD23+CD28+CD25 -> 24 | CE30: =CE17+CE20+CE23+CE28+CE25 -> 772392.32
BT31: UTILIZAÇÃO DE PACOTE | BU31: =SUM(BU24:BU27) -> 266665.92
BT32: TOTAL FATURÁVEL | BU32: =BU30-BU31 -> 1215998.7 | CD32: TT | CE32: =CC30+CE30 -> 1482664.6
CE33: =CE32=BU30 -> TRUE

Sheet TV ABERTA - COLCHÃO REP - SPE
B5: CLIENT: SABESP
B6: CAMPAING: ESCASSEZ HIDRICA - CRÍTICO
BW7: PLANNED
B8: MARKET | C8: CHANNEL | D8: PROGRAMM | E8: DAY | F8: START TIME | G8: END TIME | H8: SEC | I8: JANEIRO | BP8: INS. | BQ8: CUSTO TABELA UNITÁRIO (BRUTO) | BR8: DESC. % | BS8: CUSTO NEGOCIADO UNITÁRIO (BRUTO) | BT8: CUSTO TOTAL NEGOCIADO (BRUTO) | BU8: CUSTO TOTAL DESEMBOLSO SABESP | BW8: AUD. AS ABCDE 25+ | BX8: TRP | BY8: CPP | CA8: RESUMO
I9: T | J9: F | K9: S | L9: S | M9: M | N9: T | O9: W | P9: T | Q9: F | R9: S | S9: S | T9: M | U9: T | V9: W | W9: T | X9: F | Y9: S | Z9: S | AA9: M | AB9: T | AC9: W | AD9: T | AE9: F | AF9: S | AG9: S | AH9: M | AI9: T | AJ9: W | AK9: T | AL9: F | AM9: S | AN9: S | AO9: M | AP9: T | AQ9: W | AR9: T | AS9: F | AT9: S | AU9: S | AV9: M | AW9: T | AX9: W | AY9: T | AZ9: F | BA9: S | BB9: S | BC9: M | BD9: T | BE9: W | BF9: T | BG9: F | BH9: S | BI9: S | BJ9: M | BK9: T | BL9: W | BM9: T | BN9: F | BO9: S
I10: 1 | J10: 2 | K10: 3 | L10: 4 | M10: 5 | N10: 6 | O10: 7 | P10: 8 | Q10: 9 | R10: 10 | S10: 11 | T10: 12 | U10: 13 | V10: 14 | W10: 15 | X10: 16 | Y10: 17 | Z10: =Y10+1 -> 18 | AA10: =Z10+1 -> 19 | AB10: =AA10+1 -> 20 | AC10: =AB10+1 -> 21 | AD10: =AC10+1 -> 22 | AE10: =AD10+1 -> 23 | AF10: =AE10+1 -> 24 | AG10: =AF10+1 -> 25 | ... AM10: =AL10+1 -> 31 | AN10: 1 | AO10: 2 | AP10: 3 | AQ10: 4 | AR10: 5 | AS10: 6 | AT10: 7 | AU10: 8 | AV10: 9 | AW10: 10 | AX10: 11 | AY10: 12 | AZ10: 13 | BA10: 14 | BB10: 15 | BC10: 16 | BD10: 17 | BE10: =BD10+1 -> 18 | BF10: =BE10+1 -> 19 | BG10: =BF10+1 -> 20 | BH10: =BG10+1 -> 21 | BI10: =BH10+1 -> 22 | BJ10: =BI10+1 -> 23 | BK10: =BJ10+1 -> 24 | BL10: =BK10+1 -> 25 | ... BO10: =BN10+1 -> 28 | CA10: CHANNEL | CB10: JANEIRO | CD10: FEVEREIRO
CB12: INS | CC12: INVESTIMENTO $ | CD12: INS | CE12: INVESTIMENTO $
B13: SÃO PAULO ESTADO | C13: TV GLOBO | D13: PRACA TV 1 EDICAO | E13: SEG-SEX | F13: 0.48958333 | G13: 13:00 | H13: 30 | AH13: 1 | AJ13: 1 | AL13: 1 | AP13: 1 | AR13: 1 | AV13: 1 | AX13: 1 | AZ13: 1 | BP13: =SUM(I13:BO13) -> 8 | BQ13: 64054 | BR13: 0.1 | BS13: =BQ13*(1-BR13) -> 57648.6 | BT13: =BS13*BP13 -> 461188.8 | BU13: =BT13*0.8 -> 368951.04 | BW13: 5.24 | BX13: =BW13*BP13 -> 41.92 | BY13: =IFERROR(BU13/BX13,0) -> 8801.313 | CA13: TV GLOBO | CB13: =COUNTA(I13:AM13) -> 3 | CC13: =CB13*BS13*0.8 -> 138356.64 | CD13: =COUNTA(AN13:BO13) -> 5 | CE13: =CD13*BS13*0.8 -> 230594.4 | CF13: =SUM(CC13,CE13)=BU13 -> TRUE
E14: SEG-SEX | F14: 0.48958333 | G14: 13:00 | H14: 60 | AE14: 1 | BP14: =SUM(I14:BO14) -> 1 | BQ14: 128108 | BR14: 0.1 | BS14: =BQ14*(1-BR14) -> 115297.2 | BT14: =BS14*BP14 -> 115297.2 | BU14: =BT14*0.8 -> 92237.76 | BW14: 5.24 | BX14: =BW14*BP14 -> 5.24 | BY14: =IFERROR(BU14/BX14,0) -> 17602.626 | CA14: TV GLOBO | CB14: =COUNTA(I14:AM14) -> 1 | CC14: =CB14*BS14*0.8 -> 92237.76 | CD14: =COUNTA(AN14:BO14) -> 0 | CE14: =CD14*BS14*0.8 -> 0 | CF14: =SUM(CC14,CE14)=BU14 -> TRUE
D15: PRACA TV 2 EDICAO | E15: SEG-SEX | F15: 0.79861111 | G15: 19:40 | H15: 30 | AK15: 1 | AO15: 1 | AS15: 1 | AY15: 1 | BP15: =SUM(I15:BO15) -> 4 | BQ15: 200802 | BR15: 0.1 | BS15: =BQ15*(1-BR15) -> 180721.8 | BT15: =BS15*BP15 -> 722887.2 | BU15: =BT15*0.8 -> 578309.76 | BW15: 12.39 | BX15: =BW15*BP15 -> 49.56 | BY15: =IFERROR(BU15/BX15,0) -> 11668.881 | CA15: TV GLOBO | CB15: =COUNTA(I15:AM15) -> 1 | CC15: =CB15*BS15*0.8 -> 144577.44 | CD15: =COUNTA(AN15:BO15) -> 3 | CE15: =CD15*BS15*0.8 -> 433732.32 | CF15: =SUM(CC15,CE15)=BU15 -> TRUE
E16: SEG-SEX | F16: 0.79861111 | G16: 19:40 | H16: 60 | AD16: 1 | BP16: =SUM(I16:BO16) -> 1 | BQ16: 401604 | BR16: 0.1 | BS16: =BQ16*(1-BR16) -> 361443.6 | BT16: =BS16*BP16 -> 361443.6 | BU16: =BT16*0.8 -> 289154.88 | BW16: 12.39 | BX16: =BW16*BP16 -> 12.39 | BY16: =IFERROR(BU16/BX16,0) -> 23337.763 | CA16: TV GLOBO | CB16: =COUNTA(I16:AM16) -> 1 | CC16: =CB16*BS16*0.8 -> 289154.88 | CD16: =COUNTA(AN16:BO16) -> 0 | CE16: =CD16*BS16*0.8 -> 0 | CF16: =SUM(CC16,CE16)=BU16 -> TRUE
CA17: TT | CB17: =SUM(CB13:CB16) -> 6 | CC17: =SUM(CC13:CC16) -> 664326.72 | CD17: =SUM(CD13:CD16) -> 8 | CE17: =SUM(CE13:CE16) -> 664326.72
