Workbook
Name _1: #REF!
Name _10: #REF!
Name _11: #REF!
Name _12: #REF!
Name _13: #REF!
Name _14: #REF!
Name _15: #REF!
Name _16: #REF!
Name _17: #REF!
Name _18: #REF!
Name _19: #REF!
Name _1Excel_BuiltIn__FilterDatabase_10_9_1: NA()
Name _2: #REF!
Name _20: #REF!
Name _21: #REF!
Name _22: #REF!
Name _23: #REF!
Name _24: #REF!
Name _25: #REF!
Name _26: #REF!
Name _27: #REF!
Name _28: #REF!
Name _29: #REF!
Name _3: #REF!
Name _30: #REF!
Name _31: #REF!
Name _4: #REF!
Name _5: #REF!
Name _6: #REF!
Name _7: #REF!
Name _8: #REF!
Name _9: #REF!
Name _M: #REF!
Name _O: #REF!
Name C_: #REF!
Name CACHE: '[4]Conversão-Mercha'!$A$57:$I$112
Name CACHESEL1: '[4]Conversão-Mercha'!$M$59:$M$72
Name CACHESEL10: '[4]Conversão-Mercha'!$V$59:$V$72
Name CACHESEL2: '[4]Conversão-Mercha'!$N$59:$N$72
Name CACHESEL3: '[4]Conversão-Mercha'!$O$59:$O$72
Name CACHESEL4: '[4]Conversão-Mercha'!$P$59:$P$72
Name CACHESEL5: '[4]Conversão-Mercha'!$Q$59:$Q$72
Name CACHESEL6: '[4]Conversão-Mercha'!$R$59:$R$72
Name CACHESEL7: '[4]Conversão-Mercha'!$S$59:$S$72
Name CACHESEL8: '[4]Conversão-Mercha'!$T$59:$T$72
Name CACHESEL9: '[4]Conversão-Mercha'!$U$59:$U$72
Name CALENDARIO: '[4]Conversão-Mercha'!$B$119:$B$132
Name CAMP: #REF!
Name CAX: '[4]base TV'!#REF!
Name CLIENTE: #REF!
Name DocumentDate: #N/A
Name DocumentYear: #N/A
Name DocumentYear: #N/A
Name DocumentYear: #N/A
Name DocumentYear: #N/A
Name DocumentYear: #N/A
Name DONO: '[4]Conversão-Mercha'!#REF!
Name Excel_BuiltIn__FilterDatabase_10: [5]GERAÇÃO!#REF!
Name Excel_BuiltIn__FilterDatabase_10_1: NA()
Name Excel_BuiltIn__FilterDatabase_10_10: #REF!

Sheet COVER
B6: Tactical Media Plan | I6: CONFIDENCIAL
B8: CLIENT: | C8: SABESP
B9: CAMPAING | C9: CARAVANAS
B10: TARGET: | C10: AS ABCDE 25+
B14: VERSION | C14: UPDATE DATE | D14: UPDATES:
B15: 1 | C15: 46084 | D15: Atualizações de custos de Paulínia.
B16: 2 | C16: 0503/26 | D16: Inlclusão do jornal Agora Paulínia.

Sheet RESUMO DE MEIOS
B5: CLIENT: SABESP
B6: CAMPAING: CARAVANAS
B8: RESUMO DE MEIOS
B10: PRAÇA | C10: MEIO | D10: VEÍCULO | F10: MARÇO | G10: ABRIL | H10: MAIO | I10: TOTAL BRUTO | J10: VALOR DESEMBOLSO TT | K10: PART GERAL %
B13: PAULÍNIA | C13: JORNAL | D13: JORNAL TRIBUNA | F13: ='JORNAL - PAULINIA'!AT14*1.25 -> 9360 | G13: 0 | H13: 0 | I13: =SUM(F13:H13) -> 9360 | J13: =I13*0.8 -> 7488 | K13: =J13/$J$17 -> 0.31904015
B14: PAULÍNIA | C14: JORNAL | D14: JORNAL DE PAULÍNIA | F14: ='JORNAL - PAULINIA'!AT16*1.25 -> 13728 | G14: 0 | H14: 0 | I14: =SUM(F14:H14) -> 13728 | J14: =I14*0.8 -> 10982.4 | K14: =J14/$J$17 -> 0.46792556
B15: PAULÍNIA | C15: JORNAL | D15: AGORA PAULÍNIA | F15: ='JORNAL - PAULINIA'!AT18*1.25 -> 6250 | G15: 0 | H15: 0 | I15: =SUM(F15:H15) -> 6250 | J15: =I15*0.8 -> 5000 | K15: =J15/$J$17 -> 0.21303429
B17: TT JORNAL | F17: =SUM(F13:F15) -> 29338 | G17: =SUM(G13:G15) -> 0 | H17: =SUM(H13:H15) -> 0 | I17: =SUM(I13:I15) -> 29338 | J17: =SUM(J13:J15) -> 23470.4 | K17: =SUM(K13:K15) -> 1 | L17: =J17/J26 -> 0.24446143 | M17: =J17='JORNAL - PAULINIA'!AT22 -> TRUE
B19: PAULÍNIA | C19: RADIO | D19: BAND FM | F19: ='RÁDIO - PAULINIA'!AU14*1.25 -> 29342.25 | G19: 0 | H19: 0 | I19: =SUM(F19:H19) -> 29342.25 | J19: =I19*0.8 -> 23473.8 | K19: =J19/$J$24 -> 0.32360604
B20: PAULÍNIA | C20: RADIO | D20: NATIVA FM | F20: ='RÁDIO - PAULINIA'!AU17*1.25 -> 24696 | G20: 0 | H20: 0 | I20: =SUM(F20:H20) -> 24696 | J20: =I20*0.8 -> 19756.8 | K20: =J20/$J$24 -> 0.27236408
B21: PAULÍNIA | C21: RADIO | D21: EDUCADORA | F21: ='RÁDIO - PAULINIA'!AU20*1.25 -> 26397 | G21: 0 | H21: 0 | I21: =SUM(F21:H21) -> 26397 | J21: =I21*0.8 -> 21117.6 | K21: =J21/$J$24 -> 0.29112385
B22: PAULÍNIA | C22: RADIO | D22: JOVEM PAN | F22: ='RÁDIO - PAULINIA'!AU23*1.25 -> 10237.5 | G22: 0 | H22: 0 | I22: =SUM(F22:H22) -> 10237.5 | J22: =I22*0.8 -> 8190 | K22: =J22/$J$24 -> 0.11290603
B24: TT RÁDIO | F24: =SUM(F19:F22) -> 90672.75 | G24: =SUM(G19:G22) -> 0 | H24: =SUM(H19:H22) -> 0 | I24: =SUM(I19:I22) -> 90672.75 | J24: =SUM(J19:J22) -> 72538.2 | K24: =SUM(K19:K22) -> 1 | L24: =J24/J26 -> 0.75553857 | M24: =J24='RÁDIO - PAULINIA'!AU24 -> TRUE
B26: TOTAL PAULINIA | F26: =SUM(F17,F24) -> 120010.75 | G26: =SUM(G17,G24) -> 0 | H26: =SUM(H17,H24) -> 0 | I26: =SUM(I17,I24,) -> 120010.75 | J26: =SUM(J17,J24,) -> 96008.6 | L26: =SUM(L10:L25) -> 1
F27: =F26/I26 -> 1 | G27: =G26/I26 -> 0 | H27: =H26/I26 -> 0 | J27: ='RESUMO DE MEIOS'!J26='JORNAL - PAULINIA'!AQ22+'RÁDIO - PAULINIA'!AR24 -> TRUE
B29: PRAÇA | C29: MEIO | D29: VEÍCULO | F29: MARÇO | G29: ABRIL | H29: MAIO | I29: TOTAL BRUTO | J29: VALOR DESEMBOLSO TT | K29: PART GERAL %
B32: FRANCA | C32: PORTAL | D32: COMERCIO DA FRANCA | F32: ='PORTAL - FRANCA'!AT14*1.25 -> 28800 | G32: 0 | H32: 0 | I32: =SUM(F32:H32) -> 28800 | J32: =I32*0.8 -> 23040 | K32: =J32/$J$34 -> 1
B34: TT PORTAL | F34: =SUM(F32:F32) -> 28800 | G34: =SUM(G32:G32) -> 0 | H34: =SUM(H32:H32) -> 0 | I34: =SUM(I32:I32) -> 28800 | J34: =SUM(J32:J32) -> 23040 | K34: =SUM(K32:K32) -> 1 | L34: =J34/J44 -> 0.50469427 | M34: =J34=SUM('PORTAL - FRANCA'!AT17) -> TRUE
B36: FRANCA | C36: RADIO | D36: HERTZ FM | F36: ='RÁDIO - FRANCA'!AU14*1.25 -> 9625 | G36: 0 | H36: 0 | I36: =SUM(F36:H36) -> 9625 | J36: =I36*0.8 -> 7700 | K36: =J36/$J$24 -> 0.10615097
B37: FRANCA | C37: RADIO | D37: ESTUDIO 1 FM | F37: ='RÁDIO - FRANCA'!AU17*1.25 -> 8085 | G37: 0 | H37: 0 | I37: =SUM(F37:H37) -> 8085 | J37: =I37*0.8 -> 6468 | K37: =J37/$J$24 -> 0.089166811
B38: FRANCA | C38: RADIO | D38: 101.7 FM | F38: ='RÁDIO - FRANCA'!AU20*1.25 -> 7122.5 | G38: 0 | H38: 0 | I38: =SUM(F38:H38) -> 7122.5 | J38: =I38*0.8 -> 5698 | K38: =J38/$J$24 -> 0.078551715
B39: FRANCA | C39: RADIO | D39: 3 COLINAS FM | F39: ='RÁDIO - FRANCA'!AU23*1.25 -> 918.75 | G39: 0 | H39: 0 | I39: =SUM(F39:H39) -> 918.75 | J39: =I39*0.8 -> 735 | K39: =J39/$J$24 -> 0.010132592
B40: FRANCA | C40: RADIO | D40: MAIS FM | F40: ='RÁDIO - FRANCA'!AU26*1.25 -> 2513 | G40: 0 | H40: 0 | I40: =SUM(F40:H40) -> 2513 | J40: =I40*0.8 -> 2010.4 | K40: =J40/$J$24 -> 0.027715052
B42: TT RÁDIO | F42: =SUM(F36:F40) -> 28264.25 | G42: =SUM(G36:G40) -> 0 | H42: =SUM(H36:H40) -> 0 | I42: =SUM(I36:I40) -> 28264.25 | J42: =SUM(J36:J40) -> 22611.4 | K42: =SUM(K36:K40) -> 0.31171714 | L42: =J42/J44 -> 0.49530573 | M42: =J42='RÁDIO - FRANCA'!AU27 -> TRUE
B44: TOTAL FRANCA | F44: =SUM(F34,F42) -> 57064.25 | G44: =SUM(G34,G42) -> 0 | H44: =SUM(H34,H42) -> 0 | I44: =SUM(I34,I42,) -> 57064.25 | J44: =SUM(J34,J42,) -> 45651.4 | L44: =SUM(L29:L43) -> 1
F45: =F44/I44 -> 1 | G45: =G44/I44 -> 0 | H45: =H44/I44 -> 0 | J45: ='RESUMO DE MEIOS'!J44='RÁDIO - FRANCA'!AU27+'PORTAL - FRANCA'!AT17 -> TRUE
B47: PRAÇA | C47: MEIO | D47: VEÍCULO | F47: MARÇO | G47: ABRIL | H47: MAIO | I47: TOTAL BRUTO | J47: VALOR DESEMBOLSO TT | K47: PART GERAL %
B50: PRESIDENTE PRUDENTE | C50: JORNAL | D50: O IMPARCIAL | F50: =SUM('JORNAL - PRESIDENTE PRUDENTE'!AT14:AT15)*1.25 -> 5375 | G50: 0 | H50: 0 | I50: =SUM(F50:H50) -> 5375 | J50: =I50*0.8 -> 4300 | K50: =J50/$J$34 -> 0.18663194
B52: TT JORNAL | F52: =SUM(F50:F50) -> 5375 | G52: =SUM(G50:G50) -> 0 | H52: =SUM(H50:H50) -> 0 | I52: =SUM(I50:I50) -> 5375 | J52: =SUM(J50:J50) -> 4300 | K52: =SUM(K50:K50) -> 0.18663194 | L52: =J52/J62 -> 0.18026478 | M52: =J52='JORNAL - PRESIDENTE PRUDENTE'!AT18 -> TRUE
B54: PRESIDENTE PRUDENTE | C54: RADIO | D54: 101 FM | F54: ='RÁDIO - PRESIDENTE PRUDENTE'!AU14*1.25 -> 8720.25 | G54: 0 | H54: 0 | I54: =SUM(F54:H54) -> 8720.25 | J54: =I54*0.8 -> 6976.2 | K54: =J54/$J$24 -> 0.096172775
B55: PRESIDENTE PRUDENTE | C55: RADIO | D55: BAND FM | F55: ='RÁDIO - PRESIDENTE PRUDENTE'!AU17*1.25 -> 2724.75 | G55: 0 | H55: 0 | I55: =SUM(F55:H55) -> 2724.75 | J55: =I55*0.8 -> 2179.8 | K55: =J55/$J$24 -> 0.030050373
B56: PRESIDENTE PRUDENTE | C56: RADIO | D56: FRONTEIRA FM | F56: ='RÁDIO - PRESIDENTE PRUDENTE'!AU20*1.25 -> 3657.5 | G56: 0 | H56: 0 | I56: =SUM(F56:H56) -> 3657.5 | J56: =I56*0.8 -> 2926 | K56: =J56/$J$24 -> 0.040337367
B57: PRESIDENTE PRUDENTE | C57: RADIO | D57: 98 FM | F57: ='RÁDIO - PRESIDENTE PRUDENTE'!AU23*1.25 -> 6048 | G57: 0 | H57: 0 | I57: =SUM(F57:H57) -> 6048 | J57: =I57*0.8 -> 4838.4 | K57: =J57/$J$24 -> 0.066701407
B58: PRESIDENTE PRUDENTE | C58: RADIO | D58: NATIVA FM | F58: ='RÁDIO - PRESIDENTE PRUDENTE'!AU26*1.25 -> 3291.75 | G58: 0 | H58: 0 | I58: =SUM(F58:H58) -> 3291.75 | J58: =I58*0.8 -> 2633.4 | K58: =J58/$J$24 -> 0.03630363
B60: TT RÁDIO | F60: =SUM(F54:F58) -> 24442.25 | G60: =SUM(G54:G58) -> 0 | H60: =SUM(H54:H58) -> 0 | I60: =SUM(I54:I58) -> 24442.25 | J60: =SUM(J54:J58) -> 19553.8 | K60: =SUM(K54:K58) -> 0.26956555 | L60: =J60/J62 -> 0.81973522 | M60: =J60='RÁDIO - PRESIDENTE PRUDENTE'!AU27 -> TRUE
B62: TOTAL PRESIDENTE PRUDENTE | F62: =SUM(F52,F60) -> 29817.25 | G62: =SUM(G52,G60) -> 0 | H62: =SUM(H52,H60) -> 0 | I62: =SUM(I52,I60,) -> 29817.25 | J62: =SUM(J52,J60,) -> 23853.8 | L62: =SUM(L47:L61) -> 1
F63: =F62/I62 -> 1 | G63: =G62/I62 -> 0 | H63: =H62/I62 -> 0 | J63: ='RESUMO DE MEIOS'!J62='RÁDIO - PRESIDENTE PRUDENTE'!AU27+'JORNAL - PRESIDENTE PRUDENTE'!AT18 -> TRUE
B65: PRAÇA | C65: MEIO | D65: VEÍCULO | F65: MARÇO | G65: ABRIL | H65: MAIO | I65: TOTAL BRUTO | J65: VALOR DESEMBOLSO TT | K65: PART GERAL %
B68: JALES | C68: JORNAL | D68: A TRIBUNA | F68: =SUM('JORNAL - JALES'!BX14:BX15)*1.25 -> 20188.35 | G68: 0 | H68: 0 | I68: =SUM(F68:H68) -> 20188.35 | J68: =I68*0.8 -> 16150.68 | K68: =J68/$J$34 -> 0.70098438
B70: TT JORNAL | F70: =SUM(F68:F68) -> 20188.35 | G70: =SUM(G68:G68) -> 0 | H70: =SUM(H68:H68) -> 0 | I70: =SUM(I68:I68) -> 20188.35 | J70: =SUM(J68:J68) -> 16150.68 | K70: =SUM(K68:K68) -> 0.70098438 | L70: =J70/J79 -> 0.72480869 | M70: =J70='JORNAL - JALES'!BU18 -> TRUE
...

Sheet RÁDIO - PAULINIA
B5: CLIENT: SABESP
B6: CAMPAING: CARAVANAS - PAULÍNIA
N7: DIA D
B9: MARKET | C9: CHANNEL | D9: PROGRAM | E9: PROPERTY | F9: ASSET | G9: FORMAT: SPOT | H9: MARÇO | AM9: INS. | AN9: CUSTO TABELA UNITÁRIO (BRUTO) | AO9: DESC. % | AP9: CUSTO NEGOCIADO UNITÁRIO (BRUTO) | AQ9: CUSTO TOTAL NEGOCIADO (BRUTO) | AR9: CUSTO TOTAL DESEMBOLSO CLIENTE | AT9: MARÇO
H10: S | I10: M | J10: T | K10: W | L10: T | M10: F | N10: S | O10: S | P10: M | Q10: T | R10: W | S10: T | T10: F | U10: S | V10: S | W10: M | X10: T | Y10: W | Z10: T | AA10: F | AB10: S | AC10: S | AD10: M | AE10: T | AF10: W | AG10: T | AH10: F | AI10: S | AJ10: S | AK10: M | AL10: T
H11: 1 | I11: =H11+1 -> 2 | J11: =I11+1 -> 3 | K11: =J11+1 -> 4 | L11: =K11+1 -> 5 | M11: =L11+1 -> 6 | N11: =M11+1 -> 7 | O11: =N11+1 -> 8 | P11: =O11+1 -> 9 | ... U11: =T11+1 -> 14 | V11: 15 | W11: =V11+1 -> 16 | X11: =W11+1 -> 17 | Y11: =X11+1 -> 18 | Z11: =Y11+1 -> 19 | AA11: =Z11+1 -> 20 | AB11: =AA11+1 -> 21 | AC11: =AB11+1 -> 22 | AD11: =AC11+1 -> 23 | ... AL11: =AK11+1 -> 31 | AT11: INS. | AU11: INV LIQUIDO
B13: PAULÍNIA (COBERTURA VIA CAMPINAS) | C13: BAND FM | D13: ROTATIVO | E13: 07h00 as 19h00 | F13: COMERCIAL | G13: 30" | N13: 5 | O13: 5 | P13: 5 | Q13: 5 | R13: 5 | S13: 5 | T13: 5 | AM13: =SUM(H13:AL13) -> 35 | AN13: 1863 | AO13: 0.55 | AP13: =AN13*(1-AO13) -> 838.35 | AQ13: =AP13*AM13 -> 29342.25 | AR13: =AQ13*0.8 -> 23473.8 | AT13: =SUM(H13:AL13 ) -> 35 | AU13: =AT13*AP13*0.8 -> 23473.8
AT14: =SUM(AT13:AT13) -> 35 | AU14: =SUM(AU13:AU13) -> 23473.8
C16: NATIVA | D16: ROTATIVO | E16: 07h00 as 19h00 | F16: COMERCIAL | G16: 30" | N16: 5 | O16: 5 | P16: 5 | Q16: 5 | R16: 5 | S16: 5 | T16: 5 | AM16: =SUM(H16:AL16) -> 35 | AN16: 1568 | AO16: 0.55 | AP16: =AN16*(1-AO16) -> 705.6 | AQ16: =AP16*AM16 -> 24696 | AR16: =AQ16*0.8 -> 19756.8 | AT16: =SUM(H16:AL16 ) -> 35 | AU16: =AT16*AP16*0.8 -> 19756.8
AT17: =SUM(AT16:AT16) -> 35 | AU17: =SUM(AU16:AU16) -> 19756.8
C19: EDUCADORA | D19: ROTATIVO | E19: 07h00 as 19h00 | F19: COMERCIAL | G19: 30" | N19: 5 | O19: 5 | P19: 5 | Q19: 5 | R19: 5 | S19: 5 | T19: 5 | AM19: =SUM(H19:AL19) -> 35 | AN19: 1676 | AO19: 0.55 | AP19: =AN19*(1-AO19) -> 754.2 | AQ19: =AP19*AM19 -> 26397 | AR19: =AQ19*0.8 -> 21117.6 | AT19: =SUM(H19:AL19 ) -> 35 | AU19: =AT19*AP19*0.8 -> 21117.6
AT20: =SUM(AT19:AT19) -> 35 | AU20: =SUM(AU19:AU19) -> 21117.6
C22: JOVEM PAN | D22: ROTATIVO | E22: 07h00 as 19h00 | F22: COMERCIAL | G22: 30" | N22: 5 | O22: 5 | P22: 5 | Q22: 5 | R22: 5 | S22: 5 | T22: 5 | AM22: =SUM(H22:AL22) -> 35 | AN22: 585 | AO22: 0.5 | AP22: =AN22*(1-AO22) -> 292.5 | AQ22: =AP22*AM22 -> 10237.5 | AR22: =AQ22*0.8 -> 8190 | AT22: =SUM(H22:AL22 ) -> 35 | AU22: =AT22*AP22*0.8 -> 8190
AT23: =SUM(AT22:AT22) -> 35 | AU23: =SUM(AU22:AU22) -> 8190
B24: TOTAL RÁDIO | H24: =SUM(H12:H23) -> 0 | I24: =SUM(I12:I23) -> 0 | J24: =SUM(J12:J23) -> 0 | K24: =SUM(K12:K23) -> 0 | L24: =SUM(L12:L23) -> 0 | M24: =SUM(M12:M23) -> 0 | N24: =SUM(N12:N23) -> 20 | O24: =SUM(O12:O23) -> 20 | ... AL24: =SUM(AL12:AL23) -> 0 | AM24: =SUM(AM13:AM23) -> 140 | AQ24: =SUM(AQ13:AQ23) -> 90672.75 | AR24: =SUM(AR13:AR23) -> 72538.2 | AT24: =SUM(AT14,AT17,AT20,AT23) -> 140 | AU24: =SUM(AU14,AU17,AU20,AU23) -> 72538.2 | AW24: =AU24=AR24 -> TRUE

Sheet COBERTURA
B1: COBERTURA DAS EMISSORAS
B2: MUNICIPIOS
C3: GLOBO | D3: RECORD | E3: SBT | F3: BANDEIRANTES | G3: RÁDIO
B4: PAULÍNIA | G4: BAND - NATIVA - EDUCADORA - JOVEM PAN

Sheet JORNAL - PAULINIA
B5: CLIENT: SABESP
B6: CAMPAING: CARAVANAS - PAULÍNIA
M8: DIA D
B9: MARKET | C9: CHANNEL | D9: FORMATO | E9: INFORMAÇÕES | F9: CIRCULAÇÃO / IMPRESSÕES | G9: MARÇO | AL9: INS. | AM9: CUSTO TABELA UNITÁRIO (BRUTO) | AN9: DESC. % | AO9: CUSTO NEGOCIADO UNITÁRIO (BRUTO) | AP9: CUSTO TOTAL NEGOCIADO (BRUTO) | AQ9: CUSTO TOTAL DESEMBOLSO
G10: S | H10: M | I10: T | J10: W | K10: T | L10: F | M10: S | N10: S | O10: M | P10: T | Q10: W | R10: T | S10: F | T10: S | U10: S | V10: M | W10: T | X10: W | Y10: T | Z10: F | AA10: S | AB10: S | AC10: M | AD10: T | AE10: W | AF10: T | AG10: F | AH10: S | AI10: S | AJ10: M | AK10: T | AS10: MARÇO
G11: 1 | H11: =G11+1 -> 2 | I11: =H11+1 -> 3 | J11: =I11+1 -> 4 | K11: =J11+1 -> 5 | L11: =K11+1 -> 6 | M11: =L11+1 -> 7 | N11: =M11+1 -> 8 | O11: =N11+1 -> 9 | ... T11: =S11+1 -> 14 | U11: 15 | V11: =U11+1 -> 16 | W11: =V11+1 -> 17 | X11: =W11+1 -> 18 | Y11: =X11+1 -> 19 | Z11: =Y11+1 -> 20 | AA11: =Z11+1 -> 21 | AB11: =AA11+1 -> 22 | AC11: =AB11+1 -> 23 | ... AK11: =AJ11+1 -> 31
AS12: INS. | AT12: INV. LIQUIDO
B14: PAULÍNIA (COBERTURA VIA CAMPINAS) | C14: JORNAL TRIBUNA | D14: PÁGINA SIMPLES - IMPRESSO - 29,7x52cm | E14: SEMANAL - SÁBADO | F14: 8000 | M14: 1 | AL14: =SUM(G14:AK14) -> 1 | AM14: 10400 | AN14: 0.1 | AO14: =AM14*(1-AN14) -> 9360 | AP14: =AO14*AL14 -> 9360 | AQ14: =AP14*0.8 -> 7488 | AS14: =SUM(G14:AK14) -> 1 | AT14: =AS14*$AO14*0.8 -> 7488
C16: JORNAL DE PAULÍNIA | D16: PÁGINA SIMPLES - IMPRESSO - 29,7x52cm | E16: SEMANAL - SEXTA | F16: 5000 | S16: 1 | AL16: =SUM(G16:AK16) -> 1 | AM16: 24960 | AN16: 0.45 | AO16: =AM16*(1-AN16) -> 13728 | AP16: =AO16*AL16 -> 13728 | AQ16: =AP16*0.8 -> 10982.4 | AS16: =SUM(G16:AK16) -> 1 | AT16: =AS16*$AO16*0.8 -> 10982.4
C18: AGORA PAULÍNIA | D18: TABLÓIDE - IMPRESSO - 25,5 x 29,7cm | E18: SEMANAL - SEXTA | F18: 10000 | S18: 1 | AL18: =SUM(G18:AK18) -> 1 | AM18: 6250 | AN18: 0 | AO18: =AM18*(1-AN18) -> 6250 | AP18: =AO18*AL18 -> 6250 | AQ18: =AP18*0.8 -> 5000 | AS18: =SUM(G18:AK18) -> 1 | AT18: =AS18*$AO18*0.8 -> 5000
D19: 1 PUBLIPOST REDES SOCIAIS + 2 SEQUÊNCIA STORIES | F19: - | S19: 1 | AL19: =SUM(G19:AK19) -> 1 | AM19: BONIFICAÇÃO | AN19: 1 | AO19: =IFERROR(AM19*(1-AN19),0) -> 0 | AP19: =AO19*AL19 -> 0 | AQ19: =AP19*0.8 -> 0 | AS19: =SUM(G19:AK19) -> 1 | AT19: =AS19*$AO19*0.8 -> 0
B22: TT JORNAL | G22: =SUM(G13:G20) -> 0 | H22: =SUM(H13:H20) -> 0 | I22: =SUM(I13:I20) -> 0 | J22: =SUM(J13:J20) -> 0 | K22: =SUM(K13:K20) -> 0 | L22: =SUM(L13:L20) -> 0 | M22: =SUM(M13:M20) -> 1 | N22: =SUM(N13:N20) -> 0 | ... T22: =SUM(T13:T20) -> 0 | U22: =SUM(U13:U16) -> 0 | V22: =SUM(V13:V16) -> 0 | W22: =SUM(W13:W16) -> 0 | X22: =SUM(X13:X16) -> 0 | Y22: =SUM(Y13:Y16) -> 0 | Z22: =SUM(Z13:Z16) -> 0 | AA22: =SUM(AA13:AA16) -> 0 | AB22: =SUM(AB13:AB16) -> 0 | ... AK22: =SUM(AK13:AK16) -> 0 | AL22: =SUM(AL13:AL20) -> 4 | AP22: =SUM(AP13:AP20) -> 29338 | AQ22: =SUM(AQ13:AQ20) -> 23470.4 | AS22: =SUM(AS13:AS20) -> 4 | AT22: =SUM(AT14:AT20) -> 23470.4 | AU22: =AT22=AQ22 -> TRUE

Sheet RÁDIO - FRANCA
B5: CLIENT: SABESP
B6: CAMPAING: CARAVANAS - FRANCA
T7: DIA D
B9: MARKET | C9: CHANNEL | D9: PROGRAM | E9: PROPERTY | F9: ASSET | G9: FORMAT: SPOT | H9: MARÇO | AM9: INS. | AN9: CUSTO TABELA UNITÁRIO (BRUTO) | AO9: DESC. % | AP9: CUSTO NEGOCIADO UNITÁRIO (BRUTO) | AQ9: CUSTO TOTAL NEGOCIADO (BRUTO) | AR9: CUSTO TOTAL DESEMBOLSO CLIENTE | AT9: MARÇO
H10: S | I10: M | J10: T | K10: W | L10: T | M10: F | N10: S | O10: S | P10: M | Q10: T | R10: W | S10: T | T10: F | U10: S | V10: S | W10: M | X10: T | Y10: W | Z10: T | AA10: F | AB10: S | AC10: S | AD10: M | AE10: T | AF10: W | AG10: T | AH10: F | AI10: S | AJ10: S | AK10: M | AL10: T
H11: 1 | I11: =H11+1 -> 2 | J11: =I11+1 -> 3 | K11: =J11+1 -> 4 | L11: =K11+1 -> 5 | M11: =L11+1 -> 6 | N11: =M11+1 -> 7 | O11: =N11+1 -> 8 | P11: =O11+1 -> 9 | ... U11: =T11+1 -> 14 | V11: 15 | W11: =V11+1 -> 16 | X11: =W11+1 -> 17 | Y11: =X11+1 -> 18 | Z11: =Y11+1 -> 19 | AA11: =Z11+1 -> 20 | AB11: =AA11+1 -> 21 | AC11: =AB11+1 -> 22 | AD11: =AC11+1 -> 23 | ... AL11: =AK11+1 -> 31 | AT11: INS. | AU11: INV LIQUIDO
B13: FRANCA | C13: HERTZ FM | D13: ROTATIVO | E13: 07h00 as 19h00 | F13: COMERCIAL | G13: 30" | T13: 5 | U13: 5 | V13: 5 | W13: 5 | X13: 5 | Y13: 5 | Z13: 5 | AM13: =SUM(H13:AL13) -> 35 | AN13: 500 | AO13: 0.45 | AP13: =AN13*(1-AO13) -> 275 | AQ13: =AP13*AM13 -> 9625 | AR13: =AQ13*0.8 -> 7700 | AT13: =SUM(H13:AL13 ) -> 35 | AU13: =AT13*AP13*0.8 -> 7700
AT14: =SUM(AT13:AT13) -> 35 | AU14: =SUM(AU13:AU13) -> 7700
C16: ESTÚDIO 1 FM | D16: ROTATIVO | E16: 07h00 as 19h00 | F16: COMERCIAL | G16: 30" | T16: 5 | U16: 5 | V16: 5 | W16: 5 | X16: 5 | Y16: 5 | Z16: 5 | AM16: =SUM(H16:AL16) -> 35 | AN16: 420 | AO16: 0.45 | AP16: =AN16*(1-AO16) -> 231 | AQ16: =AP16*AM16 -> 8085 | AR16: =AQ16*0.8 -> 6468 | AT16: =SUM(H16:AL16 ) -> 35 | AU16: =AT16*AP16*0.8 -> 6468
AT17: =SUM(AT16:AT16) -> 35 | AU17: =SUM(AU16:AU16) -> 6468
C19: 101.7 FM | D19: ROTATIVO | E19: 07h00 as 19h00 | F19: COMERCIAL | G19: 30" | T19: 5 | U19: 5 | V19: 5 | W19: 5 | X19: 5 | Y19: 5 | Z19: 5 | AM19: =SUM(H19:AL19) -> 35 | AN19: 370 | AO19: 0.45 | AP19: =AN19*(1-AO19) -> 203.5 | AQ19: =AP19*AM19 -> 7122.5 | AR19: =AQ19*0.8 -> 5698 | AT19: =SUM(H19:AL19 ) -> 35 | AU19: =AT19*AP19*0.8 -> 5698
AT20: =SUM(AT19:AT19) -> 35 | AU20: =SUM(AU19:AU19) -> 5698
C22: 3 COLINAS FM | D22: ROTATIVO | E22: 07h00 as 19h00 | F22: COMERCIAL | G22: 30" | T22: 5 | U22: 5 | V22: 5 | W22: 5 | X22: 5 | Y22: 5 | Z22: 5 | AM22: =SUM(H22:AL22) -> 35 | AN22: 35 | AO22: 0.25 | AP22: =AN22*(1-AO22) -> 26.25 | AQ22: =AP22*AM22 -> 918.75 | AR22: =AQ22*0.8 -> 735 | AT22: =SUM(H22:AL22 ) -> 35 | AU22: =AT22*AP22*0.8 -> 735
AT23: =SUM(AT22:AT22) -> 35 | AU23: =SUM(AU22:AU22) -> 735
C25: MAIS FM | D25: ROTATIVO | E25: 07h00 as 19h00 | F25: COMERCIAL | G25: 30" | T25: 5 | U25: 5 | V25: 5 | W25: 5 | X25: 5 | Y25: 5 | Z25: 5 | AM25: =SUM(H25:AL25) -> 35 | AN25: 359 | AO25: 0.8 | AP25: =AN25*(1-AO25) -> 71.8 | AQ25: =AP25*AM25 -> 2513 | AR25: =AQ25*0.8 -> 2010.4 | AT25: =SUM(H25:AL25 ) -> 35 | AU25: =AT25*AP25*0.8 -> 2010.4
AT26: =SUM(AT25:AT25) -> 35 | AU26: =SUM(AU25:AU25) -> 2010.4
B27: TOTAL RÁDIO | H27: =SUM(H12:H26) -> 0 | I27: =SUM(I12:I26) -> 0 | J27: =SUM(J12:J26) -> 0 | K27: =SUM(K12:K26) -> 0 | L27: =SUM(L12:L26) -> 0 | M27: =SUM(M12:M26) -> 0 | N27: =SUM(N12:N26) -> 0 | O27: =SUM(O12:O26) -> 0 | ... AL27: =SUM(AL12:AL26) -> 0 | AM27: =SUM(AM13:AM25) -> 175 | AQ27: =SUM(AQ13:AQ25) -> 28264.25 | AR27: =SUM(AR13:AR25) -> 22611.4 | AT27: =SUM(AT14,AT17,AT20,AT23,AT26) -> 175 | AU27: =SUM(AU14,AU17,AU20,AU23,AU26) -> 22611.4 | AW27: =AU27=AR27 -> TRUE

Sheet PORTAL - FRANCA
B5: CLIENT: SABESP
B6: CAMPAING: CARAVANAS - FRANCA
S8: DIA D
B9: MARKET | C9: CHANNEL | D9: FORMATO | E9: INFORMAÇÕES | F9: CIRCULAÇÃO / IMPRESSÕES | G9: MARÇO | AL9: INS. | AM9: CUSTO TABELA UNITÁRIO (BRUTO) | AN9: DESC. % | AO9: CUSTO NEGOCIADO UNITÁRIO (BRUTO) | AP9: CUSTO TOTAL NEGOCIADO (BRUTO) | AQ9: CUSTO TOTAL DESEMBOLSO | AV9: IMPACTO | AW9: CPM
G10: S | H10: M | I10: T | J10: W | K10: T | L10: F | M10: S | N10: S | O10: M | P10: T | Q10: W | R10: T | S10: F | T10: S | U10: S | V10: M | W10: T | X10: W | Y10: T | Z10: F | AA10: S | AB10: S | AC10: M | AD10: T | AE10: W | AF10: T | AG10: F | AH10: S | AI10: S | AJ10: M | AK10: T | AS10: MARÇO
G11: 1 | H11: =G11+1 -> 2 | I11: =H11+1 -> 3 | J11: =I11+1 -> 4 | K11: =J11+1 -> 5 | L11: =K11+1 -> 6 | M11: =L11+1 -> 7 | N11: =M11+1 -> 8 | O11: =N11+1 -> 9 | ... T11: =S11+1 -> 14 | U11: 15 | V11: =U11+1 -> 16 | W11: =V11+1 -> 17 | X11: =W11+1 -> 18 | Y11: =X11+1 -> 19 | Z11: =Y11+1 -> 20 | AA11: =Z11+1 -> 21 | AB11: =AA11+1 -> 22 | AC11: =AB11+1 -> 23 | ... AK11: =AJ11+1 -> 31
AS12: INS. | AT12: INV. LIQUIDO
B14: FRANCA | C14: COMERCIO DA FRANCA | D14: SUPER BANNER (HOME + INTERNAS) | E14: 728x90px | F14: 200000 | S14: =F14 -> 200000 | AL14: =SUM(G14:AK14) -> 200000 | AM14: 180 | AN14: 0.2 | AO14: =AM14*(1-AN14) -> 144 | AP14: =(AL14/1000)*AO14 -> 28800 | AQ14: =AP14*0.8 -> 23040 | AS14: =SUM(G14:AK14) -> 200000 | AT14: =(AS14*$AO14/1000)*0.8 -> 23040 | AV14: =F14*AL14 -> 40000000000 | AW14: =AQ14/AV14*1000 -> 0.000576
B17: TT JORNAL | G17: =SUM(G13:G15) -> 0 | H17: =SUM(H13:H15) -> 0 | I17: =SUM(I13:I15) -> 0 | J17: =SUM(J13:J15) -> 0 | K17: =SUM(K13:K15) -> 0 | L17: =SUM(L13:L15) -> 0 | M17: =SUM(M13:M15) -> 0 | N17: =SUM(N13:N15) -> 0 | ... AL17: =SUM(AL13:AL15) -> 200000 | AP17: =SUM(AP13:AP15) -> 28800 | AQ17: =SUM(AQ13:AQ15) -> 23040 | AS17: =SUM(AS13:AS15) -> 200000 | AT17: =SUM(AT13:AT15) -> 23040 | AV17: 7895033

Sheet RÁDIO - PRESIDENTE PRUDENTE
B5: CLIENT: SABESP
B6: CAMPAING: CARAVANAS - PRESIDENTE PRUDENTE
AA7: DIA D
B9: MARKET | C9: CHANNEL | D9: PROGRAM | E9: PROPERTY | F9: ASSET | G9: FORMAT: SPOT | H9: MARÇO | AM9: INS. | AN9: CUSTO TABELA UNITÁRIO (BRUTO) | AO9: DESC. % | AP9: CUSTO NEGOCIADO UNITÁRIO (BRUTO) | AQ9: CUSTO TOTAL NEGOCIADO (BRUTO) | AR9: CUSTO TOTAL DESEMBOLSO CLIENTE | AT9: MARÇO
H10: S | I10: M | J10: T | K10: W | L10: T | M10: F | N10: S | O10: S | P10: M | Q10: T | R10: W | S10: T | T10: F | U10: S | V10: S | W10: M | X10: T | Y10: W | Z10: T | AA10: F | AB10: S | AC10: S | AD10: M | AE10: T | AF10: W | AG10: T | AH10: F | AI10: S | AJ10: S | AK10: M | AL10: T
H11: 1 | I11: =H11+1 -> 2 | J11: =I11+1 -> 3 | K11: =J11+1 -> 4 | L11: =K11+1 -> 5 | M11: =L11+1 -> 6 | N11: =M11+1 -> 7 | O11: =N11+1 -> 8 | P11: =O11+1 -> 9 | ... U11: =T11+1 -> 14 | V11: 15 | W11: =V11+1 -> 16 | X11: =W11+1 -> 17 | Y11: =X11+1 -> 18 | Z11: =Y11+1 -> 19 | AA11: =Z11+1 -> 20 | AB11: =AA11+1 -> 21 | AC11: =AB11+1 -> 22 | AD11: =AC11+1 -> 23 | ... AL11: =AK11+1 -> 31 | AT11: INS. | AU11: INV LIQUIDO
B13: PRESIDENTE PRUDENTE | C13: 101 FM | D13: ROTATIVO | E13: 07h00 as 19h00 | F13: COMERCIAL | G13: 30" | AA13: 5 | AB13: 5 | AC13: 5 | AD13: 5 | AE13: 5 | AF13: 5 | AG13: 5 | AM13: =SUM(H13:AL13) -> 35 | AN13: 453 | AO13: 0.45 | AP13: =AN13*(1-AO13) -> 249.15 | AQ13: =AP13*AM13 -> 8720.25 | AR13: =AQ13*0.8 -> 6976.2 | AT13: =SUM(H13:AL13 ) -> 35 | AU13: =AT13*AP13*0.8 -> 6976.2
AT14: =SUM(AT13:AT13) -> 35 | AU14: =SUM(AU13:AU13) -> 6976.2
C16: BAND FM | D16: ROTATIVO | E16: 07h00 as 19h00 | F16: COMERCIAL | G16: 30" | AA16: 5 | AB16: 5 | AC16: 5 | AD16: 5 | AE16: 5 | AF16: 5 | AG16: 5 | AM16: =SUM(H16:AL16) -> 35 | AN16: 173 | AO16: 0.55 | AP16: =AN16*(1-AO16) -> 77.85 | AQ16: =AP16*AM16 -> 2724.75 | AR16: =AQ16*0.8 -> 2179.8 | AT16: =SUM(H16:AL16 ) -> 35 | AU16: =AT16*AP16*0.8 -> 2179.8
AT17: =SUM(AT16:AT16) -> 35 | AU17: =SUM(AU16:AU16) -> 2179.8
C19: FRONTEIRA FM | D19: ROTATIVO | E19: 07h00 as 19h00 | F19: COMERCIAL | G19: 30" | AA19: 5 | AB19: 5 | AC19: 5 | AD19: 5 | AE19: 5 | AF19: 5 | AG19: 5 | AM19: =SUM(H19:AL19) -> 35 | AN19: 209 | AO19: 0.5 | AP19: =AN19*(1-AO19) -> 104.5 | AQ19: =AP19*AM19 -> 3657.5 | AR19: =AQ19*0.8 -> 2926 | AT19: =SUM(H19:AL19 ) -> 35 | AU19: =AT19*AP19*0.8 -> 2926
AT20: =SUM(AT19:AT19) -> 35 | AU20: =SUM(AU19:AU19) -> 2926
C22: 98 FM | D22: ROTATIVO | E22: 07h00 as 19h00 | F22: COMERCIAL | G22: 30" | AA22: 5 | AB22: 5 | AC22: 5 | AD22: 5 | AE22: 5 | AF22: 5 | AG22: 5 | AM22: =SUM(H22:AL22) -> 35 | AN22: 240 | AO22: 0.28 | AP22: =AN22*(1-AO22) -> 172.8 | AQ22: =AP22*AM22 -> 6048 | AR22: =AQ22*0.8 -> 4838.4 | AT22: =SUM(H22:AL22 ) -> 35 | AU22: =AT22*AP22*0.8 -> 4838.4
AT23: =SUM(AT22:AT22) -> 35 | AU23: =SUM(AU22:AU22) -> 4838.4
C25: NATIVA FM | D25: ROTATIVO | E25: 07h00 as 19h00 | F25: COMERCIAL | G25: 30" | AA25: 5 | AB25: 5 | AC25: 5 | AD25: 5 | AE25: 5 | AF25: 5 | AG25: 5 | AM25: =SUM(H25:AL25) -> 35 | AN25: 209 | AO25: 0.55 | AP25: =AN25*(1-AO25) -> 94.05 | AQ25: =AP25*AM25 -> 3291.75 | AR25: =AQ25*0.8 -> 2633.4 | AT25: =SUM(H25:AL25 ) -> 35 | AU25: =AT25*AP25*0.8 -> 2633.4
AT26: =SUM(AT25:AT25) -> 35 | AU26: =SUM(AU25:AU25) -> 2633.4
B27: TOTAL RÁDIO | H27: =SUM(H12:H23) -> 0 | I27: =SUM(I12:I23) -> 0 | J27: =SUM(J12:J23) -> 0 | K27: =SUM(K12:K23) -> 0 | L27: =SUM(L12:L23) -> 0 | M27: =SUM(M12:M23) -> 0 | N27: =SUM(N12:N23) -> 0 | O27: =SUM(O12:O23) -> 0 | ... U27: =SUM(U12:U23) -> 0 | V27: =SUM(V12:V26) -> 0 | W27: =SUM(W12:W26) -> 0 | X27: =SUM(X12:X26) -> 0 | Y27: =SUM(Y12:Y26) -> 0 | Z27: =SUM(Z12:Z26) -> 0 | AA27: =SUM(AA12:AA26) -> 25 | AB27: =SUM(AB12:AB26) -> 25 | AC27: =SUM(AC12:AC26) -> 25 | ... AI27: =SUM(AI12:AI26) -> 0 | AJ27: =SUM(AJ12:AJ23) -> 0 | AK27: =SUM(AK12:AK23) -> 0 | AL27: =SUM(AL12:AL23) -> 0 | AM27: =SUM(AM13:AM26) -> 175 | AQ27: =SUM(AQ13:AQ26) -> 24442.25 | AR27: =SUM(AR13:AR26) -> 19553.8 | AT27: =SUM(AT14,AT17,AT20,AT23,AT26) -> 175 | AU27: =SUM(AU14,AU17,AU20,AU23,AU26) -> 19553.8 | AW27: =AU27=AR27 -> TRUE

Sheet JORNAL - PRESIDENTE PRUDENTE
B5: CLIENT: SABESP
B6: CAMPAING: CARAVANAS - PRESIDENTE PRUDENTE
Z8: DIA D
B9: MARKET | C9: CHANNEL | D9: FORMATO | E9: INFORMAÇÕES | F9: CIRCULAÇÃO / IMPRESSÕES | G9: MARÇO | AL9: INS. | AM9: CUSTO TABELA UNITÁRIO (BRUTO) | AN9: DESC. % | AO9: CUSTO NEGOCIADO UNITÁRIO (BRUTO) | AP9: CUSTO TOTAL NEGOCIADO (BRUTO) | AQ9: CUSTO TOTAL DESEMBOLSO | AV9: IMPACTO | AW9: CPM
G10: S | H10: M | I10: T | J10: W | K10: T | L10: F | M10: S | N10: S | O10: M | P10: T | Q10: W | R10: T | S10: F | T10: S | U10: S | V10: M | W10: T | X10: W | Y10: T | Z10: F | AA10: S | AB10: S | AC10: M | AD10: T | AE10: W | AF10: T | AG10: F | AH10: S | AI10: S | AJ10: M | AK10: T | AS10: MARÇO
G11: 1 | H11: =G11+1 -> 2 | I11: =H11+1 -> 3 | J11: =I11+1 -> 4 | K11: =J11+1 -> 5 | L11: =K11+1 -> 6 | M11: =L11+1 -> 7 | N11: =M11+1 -> 8 | O11: =N11+1 -> 9 | ... T11: =S11+1 -> 14 | U11: 15 | V11: =U11+1 -> 16 | W11: =V11+1 -> 17 | X11: =W11+1 -> 18 | Y11: =X11+1 -> 19 | Z11: =Y11+1 -> 20 | AA11: =Z11+1 -> 21 | AB11: =AA11+1 -> 22 | AC11: =AB11+1 -> 23 | ... AK11: =AJ11+1 -> 31
AS12: INS. | AT12: INV. LIQUIDO
B14: PRESIDENTE PRUDENTE | C14: O IMPARCIAL | D14: PÁGINA SIMPLES - DIGITAL | E14: TER À DOM | F14: - | Z14: 1 | AL14: =SUM(G14:AK14) -> 1 | AM14: 3500 | AN14: 0 | AO14: =AM14*(1-AN14) -> 3500 | AP14: =AL14*AO14 -> 3500 | AQ14: =AP14*0.8 -> 2800 | AS14: =SUM(G14:AK14) -> 1 | AT14: =(AS14*$AO14)*0.8 -> 2800 | AV14: =F14*AL14 -> #VALUE! | AW14: =AQ14/AV14*1000 -> #VALUE!
D15: MEIA PÁGINA - DIGITAL | E15: TER À DOM | F15: - | AB15: 1 | AL15: =SUM(G15:AK15) -> 1 | AM15: 1875 | AN15: 0 | AO15: =AM15*(1-AN15) -> 1875 | AP15: =AL15*AO15 -> 1875 | AQ15: =AP15*0.8 -> 1500 | AS15: =SUM(G15:AK15) -> 1 | AT15: =(AS15*$AO15)*0.8 -> 1500 | AV15: =F15*AL15 -> #VALUE! | AW15: =AQ15/AV15*1000 -> #VALUE!
B18: TT JORNAL | G18: =SUM(G13:G16) -> 0 | H18: =SUM(H13:H16) -> 0 | I18: =SUM(I13:I16) -> 0 | J18: =SUM(J13:J16) -> 0 | K18: =SUM(K13:K16) -> 0 | L18: =SUM(L13:L16) -> 0 | M18: =SUM(M13:M16) -> 0 | N18: =SUM(N13:N16) -> 0 | ... AL18: =SUM(AL13:AL16) -> 2 | AP18: =SUM(AP13:AP16) -> 5375 | AQ18: =SUM(AQ13:AQ16) -> 4300 | AS18: =SUM(AS13:AS16) -> 2 | AT18: =SUM(AT13:AT16) -> 4300 | AV18: 7895033

Sheet RÁDIO - JALES
B5: CLIENT: SABESP
B6: CAMPAING: CARAVANAS - JALES
AH7: DIA D
B9: MARKET | C9: CHANNEL | D9: PROGRAM | E9: PROPERTY | F9: ASSET | G9: FORMAT: SPOT | H9: MARÇO | AM9: ABRIL | BQ9: INS. | BR9: CUSTO TABELA UNITÁRIO (BRUTO) | BS9: DESC. % | BT9: CUSTO NEGOCIADO UNITÁRIO (BRUTO) | BU9: CUSTO TOTAL NEGOCIADO (BRUTO) | BV9: CUSTO TOTAL DESEMBOLSO CLIENTE | BX9: MARÇO | BZ9: ABRIL
H10: S | I10: M | J10: T | K10: W | L10: T | M10: F | N10: S | O10: S | P10: M | Q10: T | R10: W | S10: T | T10: F | U10: S | V10: S | W10: M | X10: T | Y10: W | Z10: T | AA10: F | AB10: S | AC10: S | AD10: M | AE10: T | AF10: W | AG10: T | AH10: F | AI10: S | AJ10: S | AK10: M | AL10: T | AM10: W | AN10: T | AO10: F | AP10: S | AQ10: S | AR10: M | AS10: T | AT10: W | AU10: T | AV10: F | AW10: S | AX10: S | AY10: M | AZ10: T | BA10: W | BB10: T | BC10: F | BD10: S | BE10: S | BF10: M | BG10: T | BH10: W | BI10: T | BJ10: F | BK10: S | BL10: S | BM10: M | BN10: T | BO10: W | BP10: T
H11: 1 | I11: =H11+1 -> 2 | J11: =I11+1 -> 3 | K11: =J11+1 -> 4 | L11: =K11+1 -> 5 | M11: =L11+1 -> 6 | N11: =M11+1 -> 7 | O11: =N11+1 -> 8 | P11: =O11+1 -> 9 | ... U11: =T11+1 -> 14 | V11: 15 | W11: =V11+1 -> 16 | X11: =W11+1 -> 17 | Y11: =X11+1 -> 18 | Z11: =Y11+1 -> 19 | AA11: =Z11+1 -> 20 | AB11: =AA11+1 -> 21 | AC11: =AB11+1 -> 22 | AD11: =AC11+1 -> 23 | ... AL11: =AK11+1 -> 31 | AM11: 1 | AN11: =AM11+1 -> 2 | AO11: =AN11+1 -> 3 | AP11: =AO11+1 -> 4 | AQ11: =AP11+1 -> 5 | AR11: =AQ11+1 -> 6 | AS11: =AR11+1 -> 7 | AT11: =AS11+1 -> 8 | AU11: =AT11+1 -> 9 | ... AZ11: =AY11+1 -> 14 | BA11: 15 | BB11: =BA11+1 -> 16 | BC11: =BB11+1 -> 17 | BD11: =BC11+1 -> 18 | BE11: =BD11+1 -> 19 | BF11: =BE11+1 -> 20 | BG11: =BF11+1 -> 21 | BH11: =BG11+1 -> 22 | BI11: =BH11+1 -> 23 | ... BP11: =BO11+1 -> 30 | BX11: INS. | BY11: INV LIQUIDO | BZ11: INS. | CA11: INV LIQUIDO
B13: JALES | C13: ANTENA FM | D13: ROTATIVO | E13: 07h00 as 19h00 | F13: COMERCIAL | G13: 30" | AH13: 5 | AI13: 5 | AJ13: 5 | AK13: 5 | AL13: 5 | AM13: 5 | AN13: 5 | BQ13: =SUM(H13:BP13) -> 35 | BR13: 91.5 | BS13: 0.5 | BT13: =BR13*(1-BS13) -> 45.75 | BU13: =BT13*BQ13 -> 1601.25 | BV13: =BU13*0.8 -> 1281 | BX13: =SUM(H13:AL13 ) -> 25 | BY13: =BX13*BT13*0.8 -> 915 | BZ13: =SUM(AM13:BP13 ) -> 10 | CA13: =BZ13*BT13*0.8 -> 366
BX14: =SUM(BX13:BX13) -> 25 | BY14: =SUM(BY13:BY13) -> 915 | BZ14: =SUM(BZ13:BZ13) -> 10 | CA14: =SUM(CA13:CA13) -> 366
C16: REGIONAL FM | D16: ROTATIVO | E16: 07h00 as 19h00 | F16: COMERCIAL | G16: 30" | AH16: 5 | AI16: 5 | AJ16: 5 | AK16: 5 | AL16: 5 | AM16: 5 | AN16: 5 | BQ16: =SUM(H16:BP16) -> 35 | BR16: 78.75 | BS16: 0.2 | BT16: =BR16*(1-BS16) -> 63 | BU16: =BT16*BQ16 -> 2205 | BV16: =BU16*0.8 -> 1764 | BX16: =SUM(H16:AL16 ) -> 25 | BY16: =BX16*BT16*0.8 -> 1260 | BZ16: =SUM(AM16:BP16 ) -> 10 | CA16: =BZ16*BT16*0.8 -> 504
BX17: =SUM(BX16:BX16) -> 25 | BY17: =SUM(BY16:BY16) -> 1260 | BZ17: =SUM(BZ16:BZ16) -> 10 | CA17: =SUM(CA16:CA16) -> 504
C19: BAND FM | D19: ROTATIVO | E19: 07h00 as 19h00 | F19: COMERCIAL | G19: 30" | AH19: 5 | AI19: 5 | AJ19: 5 | AK19: 5 | AL19: 5 | AM19: 5 | AN19: 5 | BQ19: =SUM(H19:BP19) -> 35 | BR19: 171 | BS19: 0.55 | BT19: =BR19*(1-BS19) -> 76.95 | BU19: =BT19*BQ19 -> 2693.25 | BV19: =BU19*0.8 -> 2154.6 | BX19: =SUM(H19:AL19 ) -> 25 | BY19: =BX19*BT19*0.8 -> 1539 | BZ19: =SUM(AM19:BP19 ) -> 10 | CA19: =BZ19*BT19*0.8 -> 615.6
BX20: =SUM(BX19:BX19) -> 25 | BY20: =SUM(BY19:BY19) -> 1539 | BZ20: =SUM(BZ19:BZ19) -> 10 | CA20: =SUM(CA19:CA19) -> 615.6
C22: NATIVA FM | D22: ROTATIVO | E22: 07h00 as 19h00 | F22: COMERCIAL | G22: 30" | AH22: 5 | AI22: 5 | AJ22: 5 | AK22: 5 | AL22: 5 | AM22: 5 | AN22: 5 | BQ22: =SUM(H22:BP22) -> 35 | BR22: 74 | BS22: 0.55 | BT22: =BR22*(1-BS22) -> 33.3 | BU22: =BT22*BQ22 -> 1165.5 | BV22: =BU22*0.8 -> 932.4 | BX22: =SUM(H22:AL22 ) -> 25 | BY22: =BX22*BT22*0.8 -> 666 | BZ22: =SUM(AM22:BP22 ) -> 10 | CA22: =BZ22*BT22*0.8 -> 266.4
BX23: =SUM(BX22:BX22) -> 25 | BY23: =SUM(BY22:BY22) -> 666 | BZ23: =SUM(BZ22:BZ22) -> 10 | CA23: =SUM(CA22:CA22) -> 266.4
B24: TOTAL RÁDIO | H24: =SUM(H12:H23) -> 0 | I24: =SUM(I12:I23) -> 0 | J24: =SUM(J12:J23) -> 0 | K24: =SUM(K12:K23) -> 0 | L24: =SUM(L12:L23) -> 0 | M24: =SUM(M12:M23) -> 0 | N24: =SUM(N12:N23) -> 0 | O24: =SUM(O12:O23) -> 0 | ... BP24: =SUM(BP12:BP23) -> 0 | BQ24: =SUM(BQ13:BQ23) -> 140 | BU24: =SUM(BU13:BU23) -> 7665 | BV24: =SUM(BV13:BV23) -> 6132 | BX24: =SUM(BX14,BX17,BX20,BX23) -> 100 | BY24: =SUM(BY14,BY17,BY20,BY23) -> 4380 | BZ24: =SUM(BZ14,BZ17,BZ20,BZ23) -> 40 | CA24: =SUM(CA14,CA17,CA20,CA23) -> 1752 | CB24: =SUM(BY24,CA24)=BV24 -> TRUE

Sheet JORNAL - JALES
B5: CLIENT: SABESP
B6: CAMPAING: CARAVANAS - JALES
AG8: DIA D
B9: MARKET | C9: CHANNEL | D9: FORMATO | E9: INFORMAÇÕES | F9: CIRCULAÇÃO / IMPRESSÕES | G9: MARÇO | AL9: ABRIL | BP9: INS. | BQ9: CUSTO TABELA UNITÁRIO (BRUTO) | BR9: DESC. % | BS9: CUSTO NEGOCIADO UNITÁRIO (BRUTO) | BT9: CUSTO TOTAL NEGOCIADO (BRUTO) | BU9: CUSTO TOTAL DESEMBOLSO | BW9: RESUMO MENSAL
G10: S | H10: M | I10: T | J10: W | K10: T | L10: F | M10: S | N10: S | O10: M | P10: T | Q10: W | R10: T | S10: F | T10: S | U10: S | V10: M | W10: T | X10: W | Y10: T | Z10: F | AA10: S | AB10: S | AC10: M | AD10: T | AE10: W | AF10: T | AG10: F | AH10: S | AI10: S | AJ10: M | AK10: T | AL10: W | AM10: T | AN10: F | AO10: S | AP10: S | AQ10: M | AR10: T | AS10: W | AT10: T | AU10: F | AV10: S | AW10: S | AX10: M | AY10: T | AZ10: W | BA10: T | BB10: F | BC10: S | BD10: S | BE10: M | BF10: T | BG10: W | BH10: T | BI10: F | BJ10: S | BK10: S | BL10: M | BM10: T | BN10: W | BO10: T | BW10: MARÇO | BY10: ABRIL
G11: 1 | H11: =G11+1 -> 2 | I11: =H11+1 -> 3 | J11: =I11+1 -> 4 | K11: =J11+1 -> 5 | L11: =K11+1 -> 6 | M11: =L11+1 -> 7 | N11: =M11+1 -> 8 | O11: =N11+1 -> 9 | ... T11: =S11+1 -> 14 | U11: 15 | V11: =U11+1 -> 16 | W11: =V11+1 -> 17 | X11: =W11+1 -> 18 | Y11: =X11+1 -> 19 | Z11: =Y11+1 -> 20 | AA11: =Z11+1 -> 21 | AB11: =AA11+1 -> 22 | AC11: =AB11+1 -> 23 | ... AK11: =AJ11+1 -> 31 | AL11: 1 | AM11: =AL11+1 -> 2 | AN11: =AM11+1 -> 3 | AO11: =AN11+1 -> 4 | AP11: =AO11+1 -> 5 | AQ11: =AP11+1 -> 6 | AR11: =AQ11+1 -> 7 | AS11: =AR11+1 -> 8 | AT11: =AS11+1 -> 9 | ... AY11: =AX11+1 -> 14 | AZ11: 15 | BA11: =AZ11+1 -> 16 | BB11: =BA11+1 -> 17 | BC11: =BB11+1 -> 18 | BD11: =BC11+1 -> 19 | BE11: =BD11+1 -> 20 | BF11: =BE11+1 -> 21 | BG11: =BF11+1 -> 22 | BH11: =BG11+1 -> 23 | ... BO11: =BN11+1 -> 30
BW12: INS. | BX12: INV. LIQUIDO | BY12: INS. | BZ12: INV. LIQUIDO
B14: JALES | C14: A TRIBUNA | D14: PÁGINA SIMPLES | E14: SEMANAL - DOMINGO | F14: 10000 | AI14: 1 | BP14: =SUM(G14:BO14) -> 1 | BQ14: 31059 | BR14: 0.35 | BS14: =BQ14*(1-BR14) -> 20188.35 | BT14: =BP14*BS14 -> 20188.35 | BU14: =BT14*0.8 -> 16150.68 | BW14: =SUM(G14:AK14) -> 1 | BX14: =(BW14*$BS14)*0.8 -> 16150.68 | BY14: =SUM(AL14:BO14) -> 0 | BZ14: =(BY14*$BS14)*0.8 -> 0
D15: MEIA PÁGINA | BP15: =SUM(G15:BO15) -> 0 | BQ15: 15435 | BR15: 0.35 | BS15: =BQ15*(1-BR15) -> 10032.75 | BT15: =BP15*BS15 -> 0 | BU15: =BT15*0.8 -> 0 | BW15: =SUM(G15:AK15) -> 0 | BX15: =(BW15*$BS15)*0.8 -> 0 | BY15: =SUM(AL15:BO15) -> 0 | BZ15: =(BY15*$BS15)*0.8 -> 0
B18: TT JORNAL | G18: =SUM(G13:G16) -> 0 | H18: =SUM(H13:H16) -> 0 | I18: =SUM(I13:I16) -> 0 | J18: =SUM(J13:J16) -> 0 | K18: =SUM(K13:K16) -> 0 | L18: =SUM(L13:L16) -> 0 | M18: =SUM(M13:M16) -> 0 | N18: =SUM(N13:N16) -> 0 | ... BP18: =SUM(BP13:BP16) -> 1 | BT18: =SUM(BT13:BT16) -> 20188.35 | BU18: =SUM(BU13:BU16) -> 16150.68 | BW18: =SUM(BW13:BW16) -> 1 | BX18: =SUM(BX13:BX16) -> 16150.68 | BY18: =SUM(BY13:BY16) -> 0 | BZ18: =SUM(BZ13:BZ16) -> 0 | CA18: =SUM(BX18,BZ18)=BU18 -> TRUE

Sheet COBERTURA RÁDIOS
B2: BAND FM
B27: JOVEM PAN
B47: EDUCADORA FM | C47: 7338397
B49: ÁGUAS DE LINDÓIA | C49: 17266
B50: ÁGUAS DE SÃO PEDRO | C50: 2707
B51: AMERICANA | C51: 210638
B52: AMPARO | C52: 65829
B53: ARARAS | C53: 118843
B54: ARTUR NOGUEIRA | C54: 44177
B55: ATIBAIA | C55: 126603
B56: BOITUVA | C56: 48314
B57: BRAGANÇA PAULISTA | C57: 146744
B58: CAIEIRAS | C58: 86529
B59: CAMPINAS | C59: 1080113
... B123: VOTORANTIM | C123: 108809
